Workbook

Sheet Input Data
A1: FUZZY AHP - INPUT DATA
A2: Masukkan data di sel berwarna KUNING
A4: DATA KEGIATAN
A5: Nama Kegiatan: | B5: Kegiatan itu sudah
A6: Kuota: | B6: 5
A8: INPUT BOBOT KRITERIA (Skala 1-9)
A9: Kode | B9: Kriteria | C9: Bobot (1-9)
A10: K1 | B10: Status Keaktifan | C10: 1
A11: K2 | B11: Pencapaian SKU | C11: 2
A12: K3 | B12: Pencapaian SPG | C12: 2
A13: K4 | B13: Kesehatan Jasmani | C13: 3
A14: K5 | B14: Tes Wawancara | C14: 4
A15: K6 | B15: Tes Pilihan Ganda | C15: 5
A18: DAFTAR PESERTA
A19: No | B19: Nama Peserta | C19: Asal
A20: 1 | B20: Gading Martin | C20: Merauke
A21: 2 | B21: Taufik Iriansyah | C21: Jayapura
A22: 3
A23: 4
A24: 5
A25: 6
A26: 7
A27: 8
A28: 9
A29: 10

Sheet 1-3. Crisp & Konsistensi
A1: LANGKAH 1-3: MATRIKS CRISP, EIGENVECTOR & UJI KONSISTENSI
A3: LANGKAH 1: PENYUSUNAN MATRIKS PERBANDINGAN BERPASANGAN (CRISP)
A4: Matriks di-generate otomatis berdasarkan rasio bobot kriteria dari Sheet Input
A5: Kriteria | B5: K1 | C5: K2 | D5: K3 | E5: K4 | F5: K5 | G5: K6
A6: K1 | B6: 1 | C6: =IF('Input Data'!C10>='Input Data'!C11,MAX(1,MIN(9,ROUND('Input Data'!C10/'Input Data'!C11,0))),1/MAX(1,MIN(9,ROUND('Input Data'!C11/'Input Data'!C10,0)))) -> 0.5 | D6: =IF('Input Data'!C10>='Input Data'!C12,MAX(1,MIN(9,ROUND('Input Data'!C10/'Input Data'!C12,0))),1/MAX(1,MIN(9,ROUND('Input Data'!C12/'Input Data'!C10,0)))) -> 0.5 | E6: =IF('Input Data'!C10>='Input Data'!C13,MAX(1,MIN(9,ROUND('Input Data'!C10/'Input Data'!C13,0))),1/MAX(1,MIN(9,ROUND('Input Data'!C13/'Input Data'!C10,0)))) -> 0.33333333 | F6: =IF('Input Data'!C10>='Input Data'!C14,MAX(1,MIN(9,ROUND('Input Data'!C10/'Input Data'!C14,0))),1/MAX(1,MIN(9,ROUND('Input Data'!C14/'Input Data'!C10,0)))) -> 0.25 | G6: =IF('Input Data'!C10>='Input Data'!C15,MAX(1,MIN(9,ROUND('Input Data'!C10/'Input Data'!C15,0))),1/MAX(1,MIN(9,ROUND('Input Data'!C15/'Input Data'!C10,0)))) -> 0.2
A7: K2 | B7: =IF('Input Data'!C11>='Input Data'!C10,MAX(1,MIN(9,ROUND('Input Data'!C11/'Input Data'!C10,0))),1/MAX(1,MIN(9,ROUND('Input Data'!C10/'Input Data'!C11,0)))) -> 2 | C7: 1 | D7: =IF('Input Data'!C11>='Input Data'!C12,MAX(1,MIN(9,ROUND('Input Data'!C11/'Input Data'!C12,0))),1/MAX(1,MIN(9,ROUND('Input Data'!C12/'Input Data'!C11,0)))) -> 1 | E7: =IF('Input Data'!C11>='Input Data'!C13,MAX(1,MIN(9,ROUND('Input Data'!C11/'Input Data'!C13,0))),1/MAX(1,MIN(9,ROUND('Input Data'!C13/'Input Data'!C11,0)))) -> 0.5 | F7: =IF('Input Data'!C11>='Input Data'!C14,MAX(1,MIN(9,ROUND('Input Data'!C11/'Input Data'!C14,0))),1/MAX(1,MIN(9,ROUND('Input Data'!C14/'Input Data'!C11,0)))) -> 0.5 | G7: =IF('Input Data'!C11>='Input Data'!C15,MAX(1,MIN(9,ROUND('Input Data'!C11/'Input Data'!C15,0))),1/MAX(1,MIN(9,ROUND('Input Data'!C15/'Input Data'!C11,0)))) -> 0.33333333
A8: K3 | B8: =IF('Input Data'!C12>='Input Data'!C10,MAX(1,MIN(9,ROUND('Input Data'!C12/'Input Data'!C10,0))),1/MAX(1,MIN(9,ROUND('Input Data'!C10/'Input Data'!C12,0)))) -> 2 | C8: =IF('Input Data'!C12>='Input Data'!C11,MAX(1,MIN(9,ROUND('Input Data'!C12/'Input Data'!C11,0))),1/MAX(1,MIN(9,ROUND('Input Data'!C11/'Input Data'!C12,0)))) -> 1 | D8: 1 | E8: =IF('Input Data'!C12>='Input Data'!C13,MAX(1,MIN(9,ROUND('Input Data'!C12/'Input Data'!C13,0))),1/MAX(1,MIN(9,ROUND('Input Data'!C13/'Input Data'!C12,0)))) -> 0.5 | F8: =IF('Input Data'!C12>='Input Data'!C14,MAX(1,MIN(9,ROUND('Input Data'!C12/'Input Data'!C14,0))),1/MAX(1,MIN(9,ROUND('Input Data'!C14/'Input Data'!C12,0)))) -> 0.5 | G8: =IF('Input Data'!C12>='Input Data'!C15,MAX(1,MIN(9,ROUND('Input Data'!C12/'Input Data'!C15,0))),1/MAX(1,MIN(9,ROUND('Input Data'!C15/'Input Data'!C12,0)))) -> 0.33333333
A9: K4 | B9: =IF('Input Data'!C13>='Input Data'!C10,MAX(1,MIN(9,ROUND('Input Data'!C13/'Input Data'!C10,0))),1/MAX(1,MIN(9,ROUND('Input Data'!C10/'Input Data'!C13,0)))) -> 3 | C9: =IF('Input Data'!C13>='Input Data'!C11,MAX(1,MIN(9,ROUND('Input Data'!C13/'Input Data'!C11,0))),1/MAX(1,MIN(9,ROUND('Input Data'!C11/'Input Data'!C13,0)))) -> 2 | D9: =IF('Input Data'!C13>='Input Data'!C12,MAX(1,MIN(9,ROUND('Input Data'!C13/'Input Data'!C12,0))),1/MAX(1,MIN(9,ROUND('Input Data'!C12/'Input Data'!C13,0)))) -> 2 | E9: 1 | F9: =IF('Input Data'!C13>='Input Data'!C14,MAX(1,MIN(9,ROUND('Input Data'!C13/'Input Data'!C14,0))),1/MAX(1,MIN(9,ROUND('Input Data'!C14/'Input Data'!C13,0)))) -> 1 | G9: =IF('Input Data'!C13>='Input Data'!C15,MAX(1,MIN(9,ROUND('Input Data'!C13/'Input Data'!C15,0))),1/MAX(1,MIN(9,ROUND('Input Data'!C15/'Input Data'!C13,0)))) -> 0.5
A10: K5 | B10: =IF('Input Data'!C14>='Input Data'!C10,MAX(1,MIN(9,ROUND('Input Data'!C14/'Input Data'!C10,0))),1/MAX(1,MIN(9,ROUND('Input Data'!C10/'Input Data'!C14,0)))) -> 4 | C10: =IF('Input Data'!C14>='Input Data'!C11,MAX(1,MIN(9,ROUND('Input Data'!C14/'Input Data'!C11,0))),1/MAX(1,MIN(9,ROUND('Input Data'!C11/'Input Data'!C14,0)))) -> 2 | D10: =IF('Input Data'!C14>='Input Data'!C12,MAX(1,MIN(9,ROUND('Input Data'!C14/'Input Data'!C12,0))),1/MAX(1,MIN(9,ROUND('Input Data'!C12/'Input Data'!C14,0)))) -> 2 | E10: =IF('Input Data'!C14>='Input Data'!C13,MAX(1,MIN(9,ROUND('Input Data'!C14/'Input Data'!C13,0))),1/MAX(1,MIN(9,ROUND('Input Data'!C13/'Input Data'!C14,0)))) -> 1 | F10: 1 | G10: =IF('Input Data'!C14>='Input Data'!C15,MAX(1,MIN(9,ROUND('Input Data'!C14/'Input Data'!C15,0))),1/MAX(1,MIN(9,ROUND('Input Data'!C15/'Input Data'!C14,0)))) -> 1
A11: K6 | B11: =IF('Input Data'!C15>='Input Data'!C10,MAX(1,MIN(9,ROUND('Input Data'!C15/'Input Data'!C10,0))),1/MAX(1,MIN(9,ROUND('Input Data'!C10/'Input Data'!C15,0)))) -> 5 | C11: =IF('Input Data'!C15>='Input Data'!C11,MAX(1,MIN(9,ROUND('Input Data'!C15/'Input Data'!C11,0))),1/MAX(1,MIN(9,ROUND('Input Data'!C11/'Input Data'!C15,0)))) -> 3 | D11: =IF('Input Data'!C15>='Input Data'!C12,MAX(1,MIN(9,ROUND('Input Data'!C15/'Input Data'!C12,0))),1/MAX(1,MIN(9,ROUND('Input Data'!C12/'Input Data'!C15,0)))) -> 3 | E11: =IF('Input Data'!C15>='Input Data'!C13,MAX(1,MIN(9,ROUND('Input Data'!C15/'Input Data'!C13,0))),1/MAX(1,MIN(9,ROUND('Input Data'!C13/'Input Data'!C15,0)))) -> 2 | F11: =IF('Input Data'!C15>='Input Data'!C14,MAX(1,MIN(9,ROUND('Input Data'!C15/'Input Data'!C14,0))),1/MAX(1,MIN(9,ROUND('Input Data'!C14/'Input Data'!C15,0)))) -> 1 | G11: 1
A14: LANGKAH 2: PERHITUNGAN VECTOR EIGEN (GEOMETRIC MEAN METHOD)
A15: GMi = (Πaij)^(1/n), Wi = GMi / ΣGMi
A16: Kriteria | B16: Geometric Mean (GM) | C16: Eigenvector (Wi)
A17: Status Keaktifan | B17: =(B6*C6*D6*E6*F6*G6)^(1/6) -> 0.40114199 | C17: =B17/$B$23 -> 0.057825146
A18: Pencapaian SKU | B18: =(B7*C7*D7*E7*F7*G7)^(1/6) -> 0.74183638 | C18: =B18/$B$23 -> 0.10693669
A19: Pencapaian SPG | B19: =(B8*C8*D8*E8*F8*G8)^(1/6) -> 0.74183638 | C19: =B19/$B$23 -> 0.10693669
A20: Kesehatan Jasmani | B20: =(B9*C9*D9*E9*F9*G9)^(1/6) -> 1.3480062 | C20: =B20/$B$23 -> 0.19431686
A21: Tes Wawancara | B21: =(B10*C10*D10*E10*F10*G10)^(1/6) -> 1.5874011 | C21: =B21/$B$23 -> 0.22882595
A22: Tes Pilihan Ganda | B22: =(B11*C11*D11*E11*F11*G11)^(1/6) -> 2.1169329 | C22: =B22/$B$23 -> 0.30515866
A23: Total | B23: =SUM(B17:B22) -> 6.9371548 | C23: =SUM(C17:C22) -> 1
A25: LANGKAH 3: UJI KONSISTENSI MATRIKS PERBANDINGAN
A26: CI = (λmax - n) / (n - 1), CR = CI / RI
A27: Kriteria | B27: A*w | C27: (A*w)/w
A28: Status Keaktifan | B28: =B6*$C$17+C6*$C$18+D6*$C$19+E6*$C$20+F6*$C$21+G6*$C$22 -> 0.34777234 | C28: =B28/$C$17 -> 6.014206
A29: Pencapaian SKU | B29: =B7*$C$17+C7*$C$18+D7*$C$19+E7*$C$20+F7*$C$21+G7*$C$22 -> 0.64281463 | C29: =B29/$C$18 -> 6.0111701
A30: Pencapaian SPG | B30: =B8*$C$17+C8*$C$18+D8*$C$19+E8*$C$20+F8*$C$21+G8*$C$22 -> 0.64281463 | C30: =B30/$C$19 -> 6.0111701
A31: Kesehatan Jasmani | B31: =B9*$C$17+C9*$C$18+D9*$C$19+E9*$C$20+F9*$C$21+G9*$C$22 -> 1.1769443 | C31: =B31/$C$20 -> 6.0568307
A32: Tes Wawancara | B32: =B10*$C$17+C10*$C$18+D10*$C$19+E10*$C$20+F10*$C$21+G10*$C$22 -> 1.3873488 | C32: =B32/$C$21 -> 6.0628998
A33: Tes Pilihan Ganda | B33: =B11*$C$17+C11*$C$18+D11*$C$19+E11*$C$20+F11*$C$21+G11*$C$22 -> 1.8533642 | C33: =B33/$C$22 -> 6.0734446
A35: Lambda Max (λmax): | B35: =AVERAGE(C28:C33) -> 6.0382869
A36: Consistency Index (CI): | B36: =(B35-6)/(6-1) -> 0.0076573778
A37: Random Index (RI) n=6: | B37: 1.24
A38: Consistency Ratio (CR): | B38: =B36/B37 -> 0.0061753047
A39: Status: | B39: =IF(B38<=0.1,"KONSISTEN (CR <= 0.1)","TIDAK KONSISTEN") -> KONSISTEN (CR <= 0.1)

Sheet 4-6. Fuzzy & Bobot
A1: LANGKAH 4-6: FUZZIFIKASI, SYNTHETIC EXTENT & BOBOT GLOBAL
A3: TABEL SKALA FUZZY (TFN)
A4: Intensitas | B4: l | C4: m | D4: u | E4: Kebalikan (1/u, 1/m, 1/l)
A5: 1 | B5: 1 | C5: 1 | D5: 1 | E5: (1/1, 1/1, 1/1)
A6: 2 | B6: 0.5 | C6: 1 | D6: 1.5 | E6: (1/1.5, 1/1, 1/0.5)
A7: 3 | B7: 1 | C7: 1.5 | D7: 2 | E7: (1/2, 1/1.5, 1/1)
A8: 4 | B8: 1.5 | C8: 2 | D8: 2.5 | E8: (1/2.5, 1/2, 1/1.5)
A9: 5 | B9: 2 | C9: 2.5 | D9: 3 | E9: (1/3, 1/2.5, 1/2)
A10: 6 | B10: 2.5 | C10: 3 | D10: 3.5 | E10: (1/3.5, 1/3, 1/2.5)
A11: 7 | B11: 3 | C11: 3.5 | D11: 4 | E11: (1/4, 1/3.5, 1/3)
A12: 8 | B12: 3.5 | C12: 4 | D12: 4.5 | E12: (1/4.5, 1/4, 1/3.5)
A13: 9 | B13: 4 | C13: 4.5 | D13: 4.5 | E13: (1/4.5, 1/4.5, 1/4)
A15: LANGKAH 4: FUZZIFIKASI MATRIKS PERBANDINGAN BERPASANGAN
A16: Konversi nilai crisp ke Triangular Fuzzy Number (TFN)
B17: K1 | E17: K2 | H17: K3 | K17: K4 | N17: K5 | Q17: K6
A18: Kriteria | B18: l | C18: m | D18: u | E18: l | F18: m | G18: u | H18: l | I18: m | J18: u | K18: l | L18: m | M18: u | N18: l | O18: m | P18: u | Q18: l | R18: m | S18: u
A19: K1 | B19: 1 | C19: 1 | D19: 1 | E19: =IF(ROUND('1-3. Crisp & Konsistensi'!C6,0)>=1,INDEX($B$5:$B$13,ROUND('1-3. Crisp & Konsistensi'!C6,0)),1/INDEX($D$5:$D$13,ROUND(1/'1-3. Crisp & Konsistensi'!C6,0))) -> 1 | F19: =IF(ROUND('1-3. Crisp & Konsistensi'!C6,0)>=1,INDEX($C$5:$C$13,ROUND('1-3. Crisp & Konsistensi'!C6,0)),1/INDEX($C$5:$C$13,ROUND(1/'1-3. Crisp & Konsistensi'!C6,0))) -> 1 | G19: =IF(ROUND('1-3. Crisp & Konsistensi'!C6,0)>=1,INDEX($D$5:$D$13,ROUND('1-3. Crisp & Konsistensi'!C6,0)),1/INDEX($B$5:$B$13,ROUND(1/'1-3. Crisp & Konsistensi'!C6,0))) -> 1 | H19: =IF(ROUND('1-3. Crisp & Konsistensi'!D6,0)>=1,INDEX($B$5:$B$13,ROUND('1-3. Crisp & Konsistensi'!D6,0)),1/INDEX($D$5:$D$13,ROUND(1/'1-3. Crisp & Konsistensi'!D6,0))) -> 1 | I19: =IF(ROUND('1-3. Crisp & Konsistensi'!D6,0)>=1,INDEX($C$5:$C$13,ROUND('1-3. Crisp & Konsistensi'!D6,0)),1/INDEX($C$5:$C$13,ROUND(1/'1-3. Crisp & Konsistensi'!D6,0))) -> 1 | J19: =IF(ROUND('1-3. Crisp & Konsistensi'!D6,0)>=1,INDEX($D$5:$D$13,ROUND('1-3. Crisp & Konsistensi'!D6,0)),1/INDEX($B$5:$B$13,ROUND(1/'1-3. Crisp & Konsistensi'!D6,0))) -> 1 | K19: =IF(ROUND('1-3. Crisp & Konsistensi'!E6,0)>=1,INDEX($B$5:$B$13,ROUND('1-3. Crisp & Konsistensi'!E6,0)),1/INDEX($D$5:$D$13,ROUND(1/'1-3. Crisp & Konsistensi'!E6,0))) -> 0.5 | L19: =IF(ROUND('1-3. Crisp & Konsistensi'!E6,0)>=1,INDEX($C$5:$C$13,ROUND('1-3. Crisp & Konsistensi'!E6,0)),1/INDEX($C$5:$C$13,ROUND(1/'1-3. Crisp & Konsistensi'!E6,0))) -> 0.66666667 | M19: =IF(ROUND('1-3. Crisp & Konsistensi'!E6,0)>=1,INDEX($D$5:$D$13,ROUND('1-3. Crisp & Konsistensi'!E6,0)),1/INDEX($B$5:$B$13,ROUND(1/'1-3. Crisp & Konsistensi'!E6,0))) -> 1 | N19: =IF(ROUND('1-3. Crisp & Konsistensi'!F6,0)>=1,INDEX($B$5:$B$13,ROUND('1-3. Crisp & Konsistensi'!F6,0)),1/INDEX($D$5:$D$13,ROUND(1/'1-3. Crisp & Konsistensi'!F6,0))) -> 0.4 | O19: =IF(ROUND('1-3. Crisp & Konsistensi'!F6,0)>=1,INDEX($C$5:$C$13,ROUND('1-3. Crisp & Konsistensi'!F6,0)),1/INDEX($C$5:$C$13,ROUND(1/'1-3. Crisp & Konsistensi'!F6,0))) -> 0.5 | P19: =IF(ROUND('1-3. Crisp & Konsistensi'!F6,0)>=1,INDEX($D$5:$D$13,ROUND('1-3. Crisp & Konsistensi'!F6,0)),1/INDEX($B$5:$B$13,ROUND(1/'1-3. Crisp & Konsistensi'!F6,0))) -> 0.66666667 | Q19: =IF(ROUND('1-3. Crisp & Konsistensi'!G6,0)>=1,INDEX($B$5:$B$13,ROUND('1-3. Crisp & Konsistensi'!G6,0)),1/INDEX($D$5:$D$13,ROUND(1/'1-3. Crisp & Konsistensi'!G6,0))) -> 0.33333333 | R19: =IF(ROUND('1-3. Crisp & Konsistensi'!G6,0)>=1,INDEX($C$5:$C$13,ROUND('1-3. Crisp & Konsistensi'!G6,0)),1/INDEX($C$5:$C$13,ROUND(1/'1-3. Crisp & Konsistensi'!G6,0))) -> 0.4 | S19: =IF(ROUND('1-3. Crisp & Konsistensi'!G6,0)>=1,INDEX($D$5:$D$13,ROUND('1-3. Crisp & Konsistensi'!G6,0)),1/INDEX($B$5:$B$13,ROUND(1/'1-3. Crisp & Konsistensi'!G6,0))) -> 0.5
A20: K2 | B20: =1/IF(ROUND('1-3. Crisp & Konsistensi'!C6,0)>=1,INDEX($D$5:$D$13,ROUND('1-3. Crisp & Konsistensi'!C6,0)),1/INDEX($B$5:$B$13,ROUND(1/'1-3. Crisp & Konsistensi'!C6,0))) -> 1 | C20: =1/IF(ROUND('1-3. Crisp & Konsistensi'!C6,0)>=1,INDEX($C$5:$C$13,ROUND('1-3. Crisp & Konsistensi'!C6,0)),1/INDEX($C$5:$C$13,ROUND(1/'1-3. Crisp & Konsistensi'!C6,0))) -> 1 | D20: =1/IF(ROUND('1-3. Crisp & Konsistensi'!C6,0)>=1,INDEX($B$5:$B$13,ROUND('1-3. Crisp & Konsistensi'!C6,0)),1/INDEX($D$5:$D$13,ROUND(1/'1-3. Crisp & Konsistensi'!C6,0))) -> 1 | E20: 1 | F20: 1 | G20: 1 | H20: =IF(ROUND('1-3. Crisp & Konsistensi'!D7,0)>=1,INDEX($B$5:$B$13,ROUND('1-3. Crisp & Konsistensi'!D7,0)),1/INDEX($D$5:$D$13,ROUND(1/'1-3. Crisp & Konsistensi'!D7,0))) -> 1 | I20: =IF(ROUND('1-3. Crisp & Konsistensi'!D7,0)>=1,INDEX($C$5:$C$13,ROUND('1-3. Crisp & Konsistensi'!D7,0)),1/INDEX($C$5:$C$13,ROUND(1/'1-3. Crisp & Konsistensi'!D7,0))) -> 1 | J20: =IF(ROUND('1-3. Crisp & Konsistensi'!D7,0)>=1,INDEX($D$5:$D$13,ROUND('1-3. Crisp & Konsistensi'!D7,0)),1/INDEX($B$5:$B$13,ROUND(1/'1-3. Crisp & Konsistensi'!D7,0))) -> 1 | K20: =IF(ROUND('1-3. Crisp & Konsistensi'!E7,0)>=1,INDEX($B$5:$B$13,ROUND('1-3. Crisp & Konsistensi'!E7,0)),1/INDEX($D$5:$D$13,ROUND(1/'1-3. Crisp & Konsistensi'!E7,0))) -> 1 | L20: =IF(ROUND('1-3. Crisp & Konsistensi'!E7,0)>=1,INDEX($C$5:$C$13,ROUND('1-3. Crisp & Konsistensi'!E7,0)),1/INDEX($C$5:$C$13,ROUND(1/'1-3. Crisp & Konsistensi'!E7,0))) -> 1 | M20: =IF(ROUND('1-3. Crisp & Konsistensi'!E7,0)>=1,INDEX($D$5:$D$13,ROUND('1-3. Crisp & Konsistensi'!E7,0)),1/INDEX($B$5:$B$13,ROUND(1/'1-3. Crisp & Konsistensi'!E7,0))) -> 1 | N20: =IF(ROUND('1-3. Crisp & Konsistensi'!F7,0)>=1,INDEX($B$5:$B$13,ROUND('1-3. Crisp & Konsistensi'!F7,0)),1/INDEX($D$5:$D$13,ROUND(1/'1-3. Crisp & Konsistensi'!F7,0))) -> 1 | O20: =IF(ROUND('1-3. Crisp & Konsistensi'!F7,0)>=1,INDEX($C$5:$C$13,ROUND('1-3. Crisp & Konsistensi'!F7,0)),1/INDEX($C$5:$C$13,ROUND(1/'1-3. Crisp & Konsistensi'!F7,0))) -> 1 | P20: =IF(ROUND('1-3. Crisp & Konsistensi'!F7,0)>=1,INDEX($D$5:$D$13,ROUND('1-3. Crisp & Konsistensi'!F7,0)),1/INDEX($B$5:$B$13,ROUND(1/'1-3. Crisp & Konsistensi'!F7,0))) -> 1 | Q20: =IF(ROUND('1-3. Crisp & Konsistensi'!G7,0)>=1,INDEX($B$5:$B$13,ROUND('1-3. Crisp & Konsistensi'!G7,0)),1/INDEX($D$5:$D$13,ROUND(1/'1-3. Crisp & Konsistensi'!G7,0))) -> 0.5 | R20: =IF(ROUND('1-3. Crisp & Konsistensi'!G7,0)>=1,INDEX($C$5:$C$13,ROUND('1-3. Crisp & Konsistensi'!G7,0)),1/INDEX($C$5:$C$13,ROUND(1/'1-3. Crisp & Konsistensi'!G7,0))) -> 0.66666667 | S20: =IF(ROUND('1-3. Crisp & Konsistensi'!G7,0)>=1,INDEX($D$5:$D$13,ROUND('1-3. Crisp & Konsistensi'!G7,0)),1/INDEX($B$5:$B$13,ROUND(1/'1-3. Crisp & Konsistensi'!G7,0))) -> 1
A21: K3 | B21: =1/IF(ROUND('1-3. Crisp & Konsistensi'!D6,0)>=1,INDEX($D$5:$D$13,ROUND('1-3. Crisp & Konsistensi'!D6,0)),1/INDEX($B$5:$B$13,ROUND(1/'1-3. Crisp & Konsistensi'!D6,0))) -> 1 | C21: =1/IF(ROUND('1-3. Crisp & Konsistensi'!D6,0)>=1,INDEX($C$5:$C$13,ROUND('1-3. Crisp & Konsistensi'!D6,0)),1/INDEX($C$5:$C$13,ROUND(1/'1-3. Crisp & Konsistensi'!D6,0))) -> 1 | D21: =1/IF(ROUND('1-3. Crisp & Konsistensi'!D6,0)>=1,INDEX($B$5:$B$13,ROUND('1-3. Crisp & Konsistensi'!D6,0)),1/INDEX($D$5:$D$13,ROUND(1/'1-3. Crisp & Konsistensi'!D6,0))) -> 1 | E21: =1/IF(ROUND('1-3. Crisp & Konsistensi'!D7,0)>=1,INDEX($D$5:$D$13,ROUND('1-3. Crisp & Konsistensi'!D7,0)),1/INDEX($B$5:$B$13,ROUND(1/'1-3. Crisp & Konsistensi'!D7,0))) -> 1 | F21: =1/IF(ROUND('1-3. Crisp & Konsistensi'!D7,0)>=1,INDEX($C$5:$C$13,ROUND('1-3. Crisp & Konsistensi'!D7,0)),1/INDEX($C$5:$C$13,ROUND(1/'1-3. Crisp & Konsistensi'!D7,0))) -> 1 | G21: =1/IF(ROUND('1-3. Crisp & Konsistensi'!D7,0)>=1,INDEX($B$5:$B$13,ROUND('1-3. Crisp & Konsistensi'!D7,0)),1/INDEX($D$5:$D$13,ROUND(1/'1-3. Crisp & Konsistensi'!D7,0))) -> 1 | H21: 1 | I21: 1 | J21: 1 | K21: =IF(ROUND('1-3. Crisp & Konsistensi'!E8,0)>=1,INDEX($B$5:$B$13,ROUND('1-3. Crisp & Konsistensi'!E8,0)),1/INDEX($D$5:$D$13,ROUND(1/'1-3. Crisp & Konsistensi'!E8,0))) -> 1 | L21: =IF(ROUND('1-3. Crisp & Konsistensi'!E8,0)>=1,INDEX($C$5:$C$13,ROUND('1-3. Crisp & Konsistensi'!E8,0)),1/INDEX($C$5:$C$13,ROUND(1/'1-3. Crisp & Konsistensi'!E8,0))) -> 1 | M21: =IF(ROUND('1-3. Crisp & Konsistensi'!E8,0)>=1,INDEX($D$5:$D$13,ROUND('1-3. Crisp & Konsistensi'!E8,0)),1/INDEX($B$5:$B$13,ROUND(1/'1-3. Crisp & Konsistensi'!E8,0))) -> 1 | N21: =IF(ROUND('1-3. Crisp & Konsistensi'!F8,0)>=1,INDEX($B$5:$B$13,ROUND('1-3. Crisp & Konsistensi'!F8,0)),1/INDEX($D$5:$D$13,ROUND(1/'1-3. Crisp & Konsistensi'!F8,0))) -> 1 | O21: =IF(ROUND('1-3. Crisp & Konsistensi'!F8,0)>=1,INDEX($C$5:$C$13,ROUND('1-3. Crisp & Konsistensi'!F8,0)),1/INDEX($C$5:$C$13,ROUND(1/'1-3. Crisp & Konsistensi'!F8,0))) -> 1 | P21: =IF(ROUND('1-3. Crisp & Konsistensi'!F8,0)>=1,INDEX($D$5:$D$13,ROUND('1-3. Crisp & Konsistensi'!F8,0)),1/INDEX($B$5:$B$13,ROUND(1/'1-3. Crisp & Konsistensi'!F8,0))) -> 1 | Q21: =IF(ROUND('1-3. Crisp & Konsistensi'!G8,0)>=1,INDEX($B$5:$B$13,ROUND('1-3. Crisp & Konsistensi'!G8,0)),1/INDEX($D$5:$D$13,ROUND(1/'1-3. Crisp & Konsistensi'!G8,0))) -> 0.5 | R21: =IF(ROUND('1-3. Crisp & Konsistensi'!G8,0)>=1,INDEX($C$5:$C$13,ROUND('1-3. Crisp & Konsistensi'!G8,0)),1/INDEX($C$5:$C$13,ROUND(1/'1-3. Crisp & Konsistensi'!G8,0))) -> 0.66666667 | S21: =IF(ROUND('1-3. Crisp & Konsistensi'!G8,0)>=1,INDEX($D$5:$D$13,ROUND('1-3. Crisp & Konsistensi'!G8,0)),1/INDEX($B$5:$B$13,ROUND(1/'1-3. Crisp & Konsistensi'!G8,0))) -> 1
A22: K4 | B22: =1/IF(ROUND('1-3. Crisp & Konsistensi'!E6,0)>=1,INDEX($D$5:$D$13,ROUND('1-3. Crisp & Konsistensi'!E6,0)),1/INDEX($B$5:$B$13,ROUND(1/'1-3. Crisp & Konsistensi'!E6,0))) -> 1 | C22: =1/IF(ROUND('1-3. Crisp & Konsistensi'!E6,0)>=1,INDEX($C$5:$C$13,ROUND('1-3. Crisp & Konsistensi'!E6,0)),1/INDEX($C$5:$C$13,ROUND(1/'1-3. Crisp & Konsistensi'!E6,0))) -> 1.5 | D22: =1/IF(ROUND('1-3. Crisp & Konsistensi'!E6,0)>=1,INDEX($B$5:$B$13,ROUND('1-3. Crisp & Konsistensi'!E6,0)),1/INDEX($D$5:$D$13,ROUND(1/'1-3. Crisp & Konsistensi'!E6,0))) -> 2 | E22: =1/IF(ROUND('1-3. Crisp & Konsistensi'!E7,0)>=1,INDEX($D$5:$D$13,ROUND('1-3. Crisp & Konsistensi'!E7,0)),1/INDEX($B$5:$B$13,ROUND(1/'1-3. Crisp & Konsistensi'!E7,0))) -> 1 | F22: =1/IF(ROUND('1-3. Crisp & Konsistensi'!E7,0)>=1,INDEX($C$5:$C$13,ROUND('1-3. Crisp & Konsistensi'!E7,0)),1/INDEX($C$5:$C$13,ROUND(1/'1-3. Crisp & Konsistensi'!E7,0))) -> 1 | G22: =1/IF(ROUND('1-3. Crisp & Konsistensi'!E7,0)>=1,INDEX($B$5:$B$13,ROUND('1-3. Crisp & Konsistensi'!E7,0)),1/INDEX($D$5:$D$13,ROUND(1/'1-3. Crisp & Konsistensi'!E7,0))) -> 1 | H22: =1/IF(ROUND('1-3. Crisp & Konsistensi'!E8,0)>=1,INDEX($D$5:$D$13,ROUND('1-3. Crisp & Konsistensi'!E8,0)),1/INDEX($B$5:$B$13,ROUND(1/'1-3. Crisp & Konsistensi'!E8,0))) -> 1 | I22: =1/IF(ROUND('1-3. Crisp & Konsistensi'!E8,0)>=1,INDEX($C$5:$C$13,ROUND('1-3. Crisp & Konsistensi'!E8,0)),1/INDEX($C$5:$C$13,ROUND(1/'1-3. Crisp & Konsistensi'!E8,0))) -> 1 | J22: =1/IF(ROUND('1-3. Crisp & Konsistensi'!E8,0)>=1,INDEX($B$5:$B$13,ROUND('1-3. Crisp & Konsistensi'!E8,0)),1/INDEX($D$5:$D$13,ROUND(1/'1-3. Crisp & Konsistensi'!E8,0))) -> 1 | K22: 1 | L22: 1 | M22: 1 | N22: =IF(ROUND('1-3. Crisp & Konsistensi'!F9,0)>=1,INDEX($B$5:$B$13,ROUND('1-3. Crisp & Konsistensi'!F9,0)),1/INDEX($D$5:$D$13,ROUND(1/'1-3. Crisp & Konsistensi'!F9,0))) -> 1 | O22: =IF(ROUND('1-3. Crisp & Konsistensi'!F9,0)>=1,INDEX($C$5:$C$13,ROUND('1-3. Crisp & Konsistensi'!F9,0)),1/INDEX($C$5:$C$13,ROUND(1/'1-3. Crisp & Konsistensi'!F9,0))) -> 1 | P22: =IF(ROUND('1-3. Crisp & Konsistensi'!F9,0)>=1,INDEX($D$5:$D$13,ROUND('1-3. Crisp & Konsistensi'!F9,0)),1/INDEX($B$5:$B$13,ROUND(1/'1-3. Crisp & Konsistensi'!F9,0))) -> 1 | Q22: =IF(ROUND('1-3. Crisp & Konsistensi'!G9,0)>=1,INDEX($B$5:$B$13,ROUND('1-3. Crisp & Konsistensi'!G9,0)),1/INDEX($D$5:$D$13,ROUND(1/'1-3. Crisp & Konsistensi'!G9,0))) -> 1 | R22: =IF(ROUND('1-3. Crisp & Konsistensi'!G9,0)>=1,INDEX($C$5:$C$13,ROUND('1-3. Crisp & Konsistensi'!G9,0)),1/INDEX($C$5:$C$13,ROUND(1/'1-3. Crisp & Konsistensi'!G9,0))) -> 1 | S22: =IF(ROUND('1-3. Crisp & Konsistensi'!G9,0)>=1,INDEX($D$5:$D$13,ROUND('1-3. Crisp & Konsistensi'!G9,0)),1/INDEX($B$5:$B$13,ROUND(1/'1-3. Crisp & Konsistensi'!G9,0))) -> 1
A23: K5 | B23: =1/IF(ROUND('1-3. Crisp & Konsistensi'!F6,0)>=1,INDEX($D$5:$D$13,ROUND('1-3. Crisp & Konsistensi'!F6,0)),1/INDEX($B$5:$B$13,ROUND(1/'1-3. Crisp & Konsistensi'!F6,0))) -> 1.5 | C23: =1/IF(ROUND('1-3. Crisp & Konsistensi'!F6,0)>=1,INDEX($C$5:$C$13,ROUND('1-3. Crisp & Konsistensi'!F6,0)),1/INDEX($C$5:$C$13,ROUND(1/'1-3. Crisp & Konsistensi'!F6,0))) -> 2 | D23: =1/IF(ROUND('1-3. Crisp & Konsistensi'!F6,0)>=1,INDEX($B$5:$B$13,ROUND('1-3. Crisp & Konsistensi'!F6,0)),1/INDEX($D$5:$D$13,ROUND(1/'1-3. Crisp & Konsistensi'!F6,0))) -> 2.5 | E23: =1/IF(ROUND('1-3. Crisp & Konsistensi'!F7,0)>=1,INDEX($D$5:$D$13,ROUND('1-3. Crisp & Konsistensi'!F7,0)),1/INDEX($B$5:$B$13,ROUND(1/'1-3. Crisp & Konsistensi'!F7,0))) -> 1 | F23: =1/IF(ROUND('1-3. Crisp & Konsistensi'!F7,0)>=1,INDEX($C$5:$C$13,ROUND('1-3. Crisp & Konsistensi'!F7,0)),1/INDEX($C$5:$C$13,ROUND(1/'1-3. Crisp & Konsistensi'!F7,0))) -> 1 | G23: =1/IF(ROUND('1-3. Crisp & Konsistensi'!F7,0)>=1,INDEX($B$5:$B$13,ROUND('1-3. Crisp & Konsistensi'!F7,0)),1/INDEX($D$5:$D$13,ROUND(1/'1-3. Crisp & Konsistensi'!F7,0))) -> 1 | H23: =1/IF(ROUND('1-3. Crisp & Konsistensi'!F8,0)>=1,INDEX($D$5:$D$13,ROUND('1-3. Crisp & Konsistensi'!F8,0)),1/INDEX($B$5:$B$13,ROUND(1/'1-3. Crisp & Konsistensi'!F8,0))) -> 1 | I23: =1/IF(ROUND('1-3. Crisp & Konsistensi'!F8,0)>=1,INDEX($C$5:$C$13,ROUND('1-3. Crisp & Konsistensi'!F8,0)),1/INDEX($C$5:$C$13,ROUND(1/'1-3. Crisp & Konsistensi'!F8,0))) -> 1 | J23: =1/IF(ROUND('1-3. Crisp & Konsistensi'!F8,0)>=1,INDEX($B$5:$B$13,ROUND('1-3. Crisp & Konsistensi'!F8,0)),1/INDEX($D$5:$D$13,ROUND(1/'1-3. Crisp & Konsistensi'!F8,0))) -> 1 | K23: =1/IF(ROUND('1-3. Crisp & Konsistensi'!F9,0)>=1,INDEX($D$5:$D$13,ROUND('1-3. Crisp & Konsistensi'!F9,0)),1/INDEX($B$5:$B$13,ROUND(1/'1-3. Crisp & Konsistensi'!F9,0))) -> 1 | L23: =1/IF(ROUND('1-3. Crisp & Konsistensi'!F9,0)>=1,INDEX($C$5:$C$13,ROUND('1-3. Crisp & Konsistensi'!F9,0)),1/INDEX($C$5:$C$13,ROUND(1/'1-3. Crisp & Konsistensi'!F9,0))) -> 1 | M23: =1/IF(ROUND('1-3. Crisp & Konsistensi'!F9,0)>=1,INDEX($B$5:$B$13,ROUND('1-3. Crisp & Konsistensi'!F9,0)),1/INDEX($D$5:$D$13,ROUND(1/'1-3. Crisp & Konsistensi'!F9,0))) -> 1 | N23: 1 | O23: 1 | P23: 1 | Q23: =IF(ROUND('1-3. Crisp & Konsistensi'!G10,0)>=1,INDEX($B$5:$B$13,ROUND('1-3. Crisp & Konsistensi'!G10,0)),1/INDEX($D$5:$D$13,ROUND(1/'1-3. Crisp & Konsistensi'!G10,0))) -> 1 | R23: =IF(ROUND('1-3. Crisp & Konsistensi'!G10,0)>=1,INDEX($C$5:$C$13,ROUND('1-3. Crisp & Konsistensi'!G10,0)),1/INDEX($C$5:$C$13,ROUND(1/'1-3. Crisp & Konsistensi'!G10,0))) -> 1 | S23: =IF(ROUND('1-3. Crisp & Konsistensi'!G10,0)>=1,INDEX($D$5:$D$13,ROUND('1-3. Crisp & Konsistensi'!G10,0)),1/INDEX($B$5:$B$13,ROUND(1/'1-3. Crisp & Konsistensi'!G10,0))) -> 1
A24: K6 | B24: =1/IF(ROUND('1-3. Crisp & Konsistensi'!G6,0)>=1,INDEX($D$5:$D$13,ROUND('1-3. Crisp & Konsistensi'!G6,0)),1/INDEX($B$5:$B$13,ROUND(1/'1-3. Crisp & Konsistensi'!G6,0))) -> 2 | C24: =1/IF(ROUND('1-3. Crisp & Konsistensi'!G6,0)>=1,INDEX($C$5:$C$13,ROUND('1-3. Crisp & Konsistensi'!G6,0)),1/INDEX($C$5:$C$13,ROUND(1/'1-3. Crisp & Konsistensi'!G6,0))) -> 2.5 | D24: =1/IF(ROUND('1-3. Crisp & Konsistensi'!G6,0)>=1,INDEX($B$5:$B$13,ROUND('1-3. Crisp & Konsistensi'!G6,0)),1/INDEX($D$5:$D$13,ROUND(1/'1-3. Crisp & Konsistensi'!G6,0))) -> 3 | E24: =1/IF(ROUND('1-3. Crisp & Konsistensi'!G7,0)>=1,INDEX($D$5:$D$13,ROUND('1-3. Crisp & Konsistensi'!G7,0)),1/INDEX($B$5:$B$13,ROUND(1/'1-3. Crisp & Konsistensi'!G7,0))) -> 1 | F24: =1/IF(ROUND('1-3. Crisp & Konsistensi'!G7,0)>=1,INDEX($C$5:$C$13,ROUND('1-3. Crisp & Konsistensi'!G7,0)),1/INDEX($C$5:$C$13,ROUND(1/'1-3. Crisp & Konsistensi'!G7,0))) -> 1.5 | G24: =1/IF(ROUND('1-3. Crisp & Konsistensi'!G7,0)>=1,INDEX($B$5:$B$13,ROUND('1-3. Crisp & Konsistensi'!G7,0)),1/INDEX($D$5:$D$13,ROUND(1/'1-3. Crisp & Konsistensi'!G7,0))) -> 2 | H24: =1/IF(ROUND('1-3. Crisp & Konsistensi'!G8,0)>=1,INDEX($D$5:$D$13,ROUND('1-3. Crisp & Konsistensi'!G8,0)),1/INDEX($B$5:$B$13,ROUND(1/'1-3. Crisp & Konsistensi'!G8,0))) -> 1 | I24: =1/IF(ROUND('1-3. Crisp & Konsistensi'!G8,0)>=1,INDEX($C$5:$C$13,ROUND('1-3. Crisp & Konsistensi'!G8,0)),1/INDEX($C$5:$C$13,ROUND(1/'1-3. Crisp & Konsistensi'!G8,0))) -> 1.5 | J24: =1/IF(ROUND('1-3. Crisp & Konsistensi'!G8,0)>=1,INDEX($B$5:$B$13,ROUND('1-3. Crisp & Konsistensi'!G8,0)),1/INDEX($D$5:$D$13,ROUND(1/'1-3. Crisp & Konsistensi'!G8,0))) -> 2 | K24: =1/IF(ROUND('1-3. Crisp & Konsistensi'!G9,0)>=1,INDEX($D$5:$D$13,ROUND('1-3. Crisp & Konsistensi'!G9,0)),1/INDEX($B$5:$B$13,ROUND(1/'1-3. Crisp & Konsistensi'!G9,0))) -> 1 | L24: =1/IF(ROUND('1-3. Crisp & Konsistensi'!G9,0)>=1,INDEX($C$5:$C$13,ROUND('1-3. Crisp & Konsistensi'!G9,0)),1/INDEX($C$5:$C$13,ROUND(1/'1-3. Crisp & Konsistensi'!G9,0))) -> 1 | M24: =1/IF(ROUND('1-3. Crisp & Konsistensi'!G9,0)>=1,INDEX($B$5:$B$13,ROUND('1-3. Crisp & Konsistensi'!G9,0)),1/INDEX($D$5:$D$13,ROUND(1/'1-3. Crisp & Konsistensi'!G9,0))) -> 1 | N24: =1/IF(ROUND('1-3. Crisp & Konsistensi'!G10,0)>=1,INDEX($D$5:$D$13,ROUND('1-3. Crisp & Konsistensi'!G10,0)),1/INDEX($B$5:$B$13,ROUND(1/'1-3. Crisp & Konsistensi'!G10,0))) -> 1 | O24: =1/IF(ROUND('1-3. Crisp & Konsistensi'!G10,0)>=1,INDEX($C$5:$C$13,ROUND('1-3. Crisp & Konsistensi'!G10,0)),1/INDEX($C$5:$C$13,ROUND(1/'1-3. Crisp & Konsistensi'!G10,0))) -> 1 | P24: =1/IF(ROUND('1-3. Crisp & Konsistensi'!G10,0)>=1,INDEX($B$5:$B$13,ROUND('1-3. Crisp & Konsistensi'!G10,0)),1/INDEX($D$5:$D$13,ROUND(1/'1-3. Crisp & Konsistensi'!G10,0))) -> 1 | Q24: 1 | R24: 1 | S24: 1
A27: LANGKAH 5: PERHITUNGAN FUZZY SYNTHETIC EXTENT
A28: Si = (ΣMij) ⊗ (ΣΣMij)^-1
A29: Kriteria | B29: Σl | C29: Σm | D29: Σu
A30: Status Keaktifan | B30: =B19+E19+H19+K19+N19+Q19 -> 4.2333333 | C30: =C19+F19+I19+L19+O19+R19 -> 4.5666667 | D30: =D19+G19+J19+M19+P19+S19 -> 5.1666667
A31: Pencapaian SKU | B31: =B20+E20+H20+K20+N20+Q20 -> 5.5 | C31: =C20+F20+I20+L20+O20+R20 -> 5.6666667 | D31: =D20+G20+J20+M20+P20+S20 -> 6
A32: Pencapaian SPG | B32: =B21+E21+H21+K21+N21+Q21 -> 5.5 | C32: =C21+F21+I21+L21+O21+R21 -> 5.6666667 | D32: =D21+G21+J21+M21+P21+S21 -> 6
A33: Kesehatan Jasmani | B33: =B22+E22+H22+K22+N22+Q22 -> 6 | C33: =C22+F22+I22+L22+O22+R22 -> 6.5 | D33: =D22+G22+J22+M22+P22+S22 -> 7
A34: Tes Wawancara | B34: =B23+E23+H23+K23+N23+Q23 -> 6.5 | C34: =C23+F23+I23+L23+O23+R23 -> 7 | D34: =D23+G23+J23+M23+P23+S23 -> 7.5
A35: Tes Pilihan Ganda | B35: =B24+E24+H24+K24+N24+Q24 -> 7 | C35: =C24+F24+I24+L24+O24+R24 -> 8.5 | D35: =D24+G24+J24+M24+P24+S24 -> 10
A36: Total | B36: =SUM(B30:B35) -> 34.733333 | C36: =SUM(C30:C35) -> 37.9 | D36: =SUM(D30:D35) -> 41.666667
A38: Fuzzy Synthetic Extent (Si)
A39: Kriteria | B39: Si(l) | C39: Si(m) | D39: Si(u)
A40: Status Keaktifan | B40: =B30/$D$36 -> 0.1016 | C40: =C30/$C$36 -> 0.12049252 | D40: =D30/$B$36 -> 0.1487524
A41: Pencapaian SKU | B41: =B31/$D$36 -> 0.132 | C41: =C31/$C$36 -> 0.14951627 | D41: =D31/$B$36 -> 0.17274472
A42: Pencapaian SPG | B42: =B32/$D$36 -> 0.132 | C42: =C32/$C$36 -> 0.14951627 | D42: =D32/$B$36 -> 0.17274472
A43: Kesehatan Jasmani | B43: =B33/$D$36 -> 0.144 | C43: =C33/$C$36 -> 0.17150396 | D43: =D33/$B$36 -> 0.20153551
A44: Tes Wawancara | B44: =B34/$D$36 -> 0.156 | C44: =C34/$C$36 -> 0.18469657 | D44: =D34/$B$36 -> 0.2159309
A45: Tes Pilihan Ganda | B45: =B35/$D$36 -> 0.168 | C45: =C35/$C$36 -> 0.22427441 | D45: =D35/$B$36 -> 0.28790787
...

Sheet Nilai Peserta
A1: INPUT NILAI PESERTA PER KRITERIA
A2: Masukkan nilai 0-100 untuk setiap kriteria
A4: No | B4: Nama Peserta | C4: K1 | D4: K2 | E4: K3 | F4: K4 | G4: K5 | H4: K6
A5: 1 | B5: ='Input Data'!B20 -> Gading Martin | C5: 4 | D5: 5 | E5: 3 | F5: 5 | G5: 4 | H5: 87
A6: 2 | B6: ='Input Data'!B21 -> Taufik Iriansyah | C6: 5 | D6: 4 | E6: 3 | F6: 4 | G6: 3 | H6: 77
A7: 3 | B7: ='Input Data'!B22 -> 0 | C7: 0 | D7: 0 | E7: 0 | F7: 0 | G7: 0 | H7: 0
A8: 4 | B8: ='Input Data'!B23 -> 0 | C8: 0 | D8: 0 | E8: 0 | F8: 0 | G8: 0 | H8: 0
A9: 5 | B9: ='Input Data'!B24 -> 0 | C9: 0 | D9: 0 | E9: 0 | F9: 0 | G9: 0 | H9: 0
A10: 6 | B10: ='Input Data'!B25 -> 0 | C10: 0 | D10: 0 | E10: 0 | F10: 0 | G10: 0 | H10: 0
A11: 7 | B11: ='Input Data'!B26 -> 0 | C11: 0 | D11: 0 | E11: 0 | F11: 0 | G11: 0 | H11: 0
A12: 8 | B12: ='Input Data'!B27 -> 0 | C12: 0 | D12: 0 | E12: 0 | F12: 0 | G12: 0 | H12: 0
A13: 9 | B13: ='Input Data'!B28 -> 0 | C13: 0 | D13: 0 | E13: 0 | F13: 0 | G13: 0 | H13: 0
A14: 10 | B14: ='Input Data'!B29 -> 0 | C14: 0 | D14: 0 | E14: 0 | F14: 0 | G14: 0 | H14: 0

Sheet Hasil & Ranking
A1: PERHITUNGAN SKOR AKHIR & RANKING
A2: Skor Akhir = Σ(Nilai × Bobot Global)
A4: BOBOT GLOBAL KRITERIA
A5: K1 | B5: K2 | C5: K3 | D5: K4 | E5: K5 | F5: K6
A6: ='4-6. Fuzzy & Bobot'!C51 -> 0.12226129 | B6: ='4-6. Fuzzy & Bobot'!C52 -> 0.14976216 | C6: ='4-6. Fuzzy & Bobot'!C53 -> 0.14976216 | D6: ='4-6. Fuzzy & Bobot'!C54 -> 0.17045916 | E6: ='4-6. Fuzzy & Bobot'!C55 -> 0.18351065 | F6: ='4-6. Fuzzy & Bobot'!C56 -> 0.22424458
A8: PERHITUNGAN SKOR AKHIR
A9: No | B9: Nama | C9: K1×W | D9: K2×W | E9: K3×W | F9: K4×W | G9: K5×W | H9: K6×W | I9: Skor Akhir | J9: Ranking
A10: 1 | B10: ='Input Data'!B20 -> Gading Martin | C10: ='Nilai Peserta'!C5*$A$6 -> 0.48904517 | D10: ='Nilai Peserta'!D5*$B$6 -> 0.74881079 | E10: ='Nilai Peserta'!E5*$C$6 -> 0.44928647 | F10: ='Nilai Peserta'!F5*$D$6 -> 0.85229579 | G10: ='Nilai Peserta'!G5*$E$6 -> 0.73404261 | H10: ='Nilai Peserta'!H5*$F$6 -> 19.509278 | I10: =SUM(C10:H10) -> 22.782759 | J10: =IF(B10="","",RANK(I10,$I$10:$I$19,0)) -> 1
A11: 2 | B11: ='Input Data'!B21 -> Taufik Iriansyah | C11: ='Nilai Peserta'!C6*$A$6 -> 0.61130646 | D11: ='Nilai Peserta'!D6*$B$6 -> 0.59904863 | E11: ='Nilai Peserta'!E6*$C$6 -> 0.44928647 | F11: ='Nilai Peserta'!F6*$D$6 -> 0.68183663 | G11: ='Nilai Peserta'!G6*$E$6 -> 0.55053196 | H11: ='Nilai Peserta'!H6*$F$6 -> 17.266833 | I11: =SUM(C11:H11) -> 20.158843 | J11: =IF(B11="","",RANK(I11,$I$10:$I$19,0)) -> 2
A12: 3 | B12: ='Input Data'!B22 -> 0 | C12: ='Nilai Peserta'!C7*$A$6 -> 0 | D12: ='Nilai Peserta'!D7*$B$6 -> 0 | E12: ='Nilai Peserta'!E7*$C$6 -> 0 | F12: ='Nilai Peserta'!F7*$D$6 -> 0 | G12: ='Nilai Peserta'!G7*$E$6 -> 0 | H12: ='Nilai Peserta'!H7*$F$6 -> 0 | I12: =SUM(C12:H12) -> 0 | J12: =IF(B12="","",RANK(I12,$I$10:$I$19,0)) -> 3
A13: 4 | B13: ='Input Data'!B23 -> 0 | C13: ='Nilai Peserta'!C8*$A$6 -> 0 | D13: ='Nilai Peserta'!D8*$B$6 -> 0 | E13: ='Nilai Peserta'!E8*$C$6 -> 0 | F13: ='Nilai Peserta'!F8*$D$6 -> 0 | G13: ='Nilai Peserta'!G8*$E$6 -> 0 | H13: ='Nilai Peserta'!H8*$F$6 -> 0 | I13: =SUM(C13:H13) -> 0 | J13: =IF(B13="","",RANK(I13,$I$10:$I$19,0)) -> 3
A14: 5 | B14: ='Input Data'!B24 -> 0 | C14: ='Nilai Peserta'!C9*$A$6 -> 0 | D14: ='Nilai Peserta'!D9*$B$6 -> 0 | E14: ='Nilai Peserta'!E9*$C$6 -> 0 | F14: ='Nilai Peserta'!F9*$D$6 -> 0 | G14: ='Nilai Peserta'!G9*$E$6 -> 0 | H14: ='Nilai Peserta'!H9*$F$6 -> 0 | I14: =SUM(C14:H14) -> 0 | J14: =IF(B14="","",RANK(I14,$I$10:$I$19,0)) -> 3
A15: 6 | B15: ='Input Data'!B25 -> 0 | C15: ='Nilai Peserta'!C10*$A$6 -> 0 | D15: ='Nilai Peserta'!D10*$B$6 -> 0 | E15: ='Nilai Peserta'!E10*$C$6 -> 0 | F15: ='Nilai Peserta'!F10*$D$6 -> 0 | G15: ='Nilai Peserta'!G10*$E$6 -> 0 | H15: ='Nilai Peserta'!H10*$F$6 -> 0 | I15: =SUM(C15:H15) -> 0 | J15: =IF(B15="","",RANK(I15,$I$10:$I$19,0)) -> 3
A16: 7 | B16: ='Input Data'!B26 -> 0 | C16: ='Nilai Peserta'!C11*$A$6 -> 0 | D16: ='Nilai Peserta'!D11*$B$6 -> 0 | E16: ='Nilai Peserta'!E11*$C$6 -> 0 | F16: ='Nilai Peserta'!F11*$D$6 -> 0 | G16: ='Nilai Peserta'!G11*$E$6 -> 0 | H16: ='Nilai Peserta'!H11*$F$6 -> 0 | I16: =SUM(C16:H16) -> 0 | J16: =IF(B16="","",RANK(I16,$I$10:$I$19,0)) -> 3
A17: 8 | B17: ='Input Data'!B27 -> 0 | C17: ='Nilai Peserta'!C12*$A$6 -> 0 | D17: ='Nilai Peserta'!D12*$B$6 -> 0 | E17: ='Nilai Peserta'!E12*$C$6 -> 0 | F17: ='Nilai Peserta'!F12*$D$6 -> 0 | G17: ='Nilai Peserta'!G12*$E$6 -> 0 | H17: ='Nilai Peserta'!H12*$F$6 -> 0 | I17: =SUM(C17:H17) -> 0 | J17: =IF(B17="","",RANK(I17,$I$10:$I$19,0)) -> 3
A18: 9 | B18: ='Input Data'!B28 -> 0 | C18: ='Nilai Peserta'!C13*$A$6 -> 0 | D18: ='Nilai Peserta'!D13*$B$6 -> 0 | E18: ='Nilai Peserta'!E13*$C$6 -> 0 | F18: ='Nilai Peserta'!F13*$D$6 -> 0 | G18: ='Nilai Peserta'!G13*$E$6 -> 0 | H18: ='Nilai Peserta'!H13*$F$6 -> 0 | I18: =SUM(C18:H18) -> 0 | J18: =IF(B18="","",RANK(I18,$I$10:$I$19,0)) -> 3
A19: 10 | B19: ='Input Data'!B29 -> 0 | C19: ='Nilai Peserta'!C14*$A$6 -> 0 | D19: ='Nilai Peserta'!D14*$B$6 -> 0 | E19: ='Nilai Peserta'!E14*$C$6 -> 0 | F19: ='Nilai Peserta'!F14*$D$6 -> 0 | G19: ='Nilai Peserta'!G14*$E$6 -> 0 | H19: ='Nilai Peserta'!H14*$F$6 -> 0 | I19: =SUM(C19:H19) -> 0 | J19: =IF(B19="","",RANK(I19,$I$10:$I$19,0)) -> 3
