Workbook

Sheet Input
A1: FUZZY AHP - 3 PENILAI
A3: BOBOT KRITERIA
A4: Kode | B4: Kriteria | C4: Bobot
A5: K1 | B5: Status Keaktifan | C5: 5
A6: K2 | B6: Pencapaian SKU | C6: 8
A7: K3 | B7: Pencapaian SPG | C7: 7
A8: K4 | B8: Kesehatan Jasmani | C8: 2
A9: K5 | B9: Tes Wawancara | C9: 4
A10: K6 | B10: Tes Pilihan Ganda | C10: 8
A12: PESERTA
A13: No | B13: Nama
A14: 1 | B14: David Kulian
A15: 2 | B15: Siti Aminah
A16: 3 | B16: Budi Santoso
A17: 4 | B17: Dewi Lestari
A18: 5 | B18: Ahmad Fauzi
A19: 6 | B19: Rina Wati
A20: 7 | B20: Joko Susilo
A21: 8 | B21: Maya Sari
A22: 9 | B22: Andi Pratama
A23: 10 | B23: Lina Marlina

Sheet Penilai 1
A1: INPUT PENILAI 1 (Semua Kriteria K1-K6)
A3: No | B3: Nama | C3: K1 | D3: K2 | E3: K3 | F3: K4 | G3: K5 | H3: K6
A4: 1 | B4: =Input!B14 -> David Kulian | C4: 4 | D4: 5 | E4: 3 | F4: 4 | G4: 4 | H4: 88
A5: 2 | B5: =Input!B15 -> Siti Aminah | C5: 78 | D5: 82 | E5: 82 | F5: 88 | G5: 80 | H5: 78
A6: 3 | B6: =Input!B16 -> Budi Santoso | C6: 92 | D6: 88 | E6: 90 | F6: 85 | G6: 88 | H6: 90
A7: 4 | B7: =Input!B17 -> Dewi Lestari | C7: 80 | D7: 85 | E7: 85 | F7: 90 | G7: 82 | H7: 80
A8: 5 | B8: =Input!B18 -> Ahmad Fauzi | C8: 88 | D8: 90 | E8: 87 | F8: 80 | G8: 90 | H8: 88
A9: 6 | B9: =Input!B19 -> Rina Wati | C9: 75 | D9: 80 | E9: 80 | F9: 85 | G9: 85 | H9: 82
A10: 7 | B10: =Input!B20 -> Joko Susilo | C10: 82 | D10: 78 | E10: 88 | F10: 82 | G10: 80 | H10: 85
A11: 8 | B11: =Input!B21 -> Maya Sari | C11: 90 | D11: 85 | E11: 85 | F11: 88 | G11: 88 | H11: 92
A12: 9 | B12: =Input!B22 -> Andi Pratama | C12: 85 | D12: 82 | E12: 82 | F12: 85 | G12: 85 | H12: 80
A13: 10 | B13: =Input!B23 -> Lina Marlina | C13: 78 | D13: 80 | E13: 85 | F13: 90 | G13: 82 | H13: 85

Sheet Penilai 2
A1: INPUT PENILAI 2 (Semua Kriteria K1-K6)
A3: No | B3: Nama | C3: K1 | D3: K2 | E3: K3 | F3: K4 | G3: K5 | H3: K6
A4: 1 | B4: =Input!B14 -> David Kulian | C4: 4 | D4: 4 | E4: 3 | F4: 5 | G4: 4 | H4: 88
A5: 2 | B5: =Input!B15 -> Siti Aminah | C5: 82 | D5: 85 | E5: 88 | F5: 85 | G5: 82 | H5: 80
A6: 3 | B6: =Input!B16 -> Budi Santoso | C6: 90 | D6: 82 | E6: 85 | F6: 90 | G6: 90 | H6: 88
A7: 4 | B7: =Input!B17 -> Dewi Lestari | C7: 85 | D7: 88 | E7: 90 | F7: 85 | G7: 80 | H7: 82
A8: 5 | B8: =Input!B18 -> Ahmad Fauzi | C8: 87 | D8: 90 | E8: 80 | F8: 87 | G8: 88 | H8: 90
A9: 6 | B9: =Input!B19 -> Rina Wati | C9: 80 | D9: 78 | E9: 85 | F9: 80 | G9: 82 | H9: 85
A10: 7 | B10: =Input!B20 -> Joko Susilo | C10: 88 | D10: 82 | E10: 82 | F10: 88 | G10: 85 | H10: 80
A11: 8 | B11: =Input!B21 -> Maya Sari | C11: 85 | D11: 90 | E11: 88 | F11: 85 | G11: 92 | H11: 88
A12: 9 | B12: =Input!B22 -> Andi Pratama | C12: 82 | D12: 85 | E12: 85 | F12: 82 | G12: 80 | H12: 85
A13: 10 | B13: =Input!B23 -> Lina Marlina | C13: 85 | D13: 82 | E13: 90 | F13: 85 | G13: 85 | H13: 82

Sheet Penilai 3
A1: INPUT PENILAI 3 (Semua Kriteria K1-K6)
A3: No | B3: Nama | C3: K1 | D3: K2 | E3: K3 | F3: K4 | G3: K5 | H3: K6
A4: 1 | B4: =Input!B14 -> David Kulian | C4: 3 | D4: 4 | E4: 5 | F4: 4 | G4: 4 | H4: 88
A5: 2 | B5: =Input!B15 -> Siti Aminah | C5: 80 | D5: 80 | E5: 78 | F5: 82 | G5: 78 | H5: 80
A6: 3 | B6: =Input!B16 -> Budi Santoso | C6: 88 | D6: 90 | E6: 90 | F6: 88 | G6: 90 | H6: 88
A7: 4 | B7: =Input!B17 -> Dewi Lestari | C7: 82 | D7: 85 | E7: 80 | F7: 88 | G7: 80 | H7: 82
A8: 5 | B8: =Input!B18 -> Ahmad Fauzi | C8: 90 | D8: 88 | E8: 88 | F8: 85 | G8: 90 | H8: 87
A9: 6 | B9: =Input!B19 -> Rina Wati | C9: 85 | D9: 82 | E9: 82 | F9: 78 | G9: 82 | H9: 80
A10: 7 | B10: =Input!B20 -> Joko Susilo | C10: 80 | D10: 85 | E10: 85 | F10: 80 | G10: 85 | H10: 82
A11: 8 | B11: =Input!B21 -> Maya Sari | C11: 88 | D11: 88 | E11: 92 | F11: 90 | G11: 88 | H11: 90
A12: 9 | B12: =Input!B22 -> Andi Pratama | C12: 85 | D12: 80 | E12: 80 | F12: 85 | G12: 80 | H12: 82
A13: 10 | B13: =Input!B23 -> Lina Marlina | C13: 82 | D13: 85 | E13: 85 | F13: 82 | G13: 85 | H13: 80

Sheet Rekap Nilai
A1: REKAP NILAI (RATA-RATA 3 PENILAI)
A2: Nilai = AVERAGE(Penilai1, Penilai2, Penilai3) per kriteria
A4: No | B4: Nama | C4: K1 | D4: K2 | E4: K3 | F4: K4 | G4: K5 | H4: K6
A5: 1 | B5: =Input!B14 -> David Kulian | C5: =AVERAGE('Penilai 1'!C4,'Penilai 2'!C4,'Penilai 3'!C4) -> 3.6666667 | D5: =AVERAGE('Penilai 1'!D4,'Penilai 2'!D4,'Penilai 3'!D4) -> 4.3333333 | E5: =AVERAGE('Penilai 1'!E4,'Penilai 2'!E4,'Penilai 3'!E4) -> 3.6666667 | F5: =AVERAGE('Penilai 1'!F4,'Penilai 2'!F4,'Penilai 3'!F4) -> 4.3333333 | G5: =AVERAGE('Penilai 1'!G4,'Penilai 2'!G4,'Penilai 3'!G4) -> 4 | H5: =AVERAGE('Penilai 1'!H4,'Penilai 2'!H4,'Penilai 3'!H4) -> 88
A6: 2 | B6: =Input!B15 -> Siti Aminah | C6: =AVERAGE('Penilai 1'!C5,'Penilai 2'!C5,'Penilai 3'!C5) -> 80 | D6: =AVERAGE('Penilai 1'!D5,'Penilai 2'!D5,'Penilai 3'!D5) -> 82.333333 | E6: =AVERAGE('Penilai 1'!E5,'Penilai 2'!E5,'Penilai 3'!E5) -> 82.666667 | F6: =AVERAGE('Penilai 1'!F5,'Penilai 2'!F5,'Penilai 3'!F5) -> 85 | G6: =AVERAGE('Penilai 1'!G5,'Penilai 2'!G5,'Penilai 3'!G5) -> 80 | H6: =AVERAGE('Penilai 1'!H5,'Penilai 2'!H5,'Penilai 3'!H5) -> 79.333333
A7: 3 | B7: =Input!B16 -> Budi Santoso | C7: =AVERAGE('Penilai 1'!C6,'Penilai 2'!C6,'Penilai 3'!C6) -> 90 | D7: =AVERAGE('Penilai 1'!D6,'Penilai 2'!D6,'Penilai 3'!D6) -> 86.666667 | E7: =AVERAGE('Penilai 1'!E6,'Penilai 2'!E6,'Penilai 3'!E6) -> 88.333333 | F7: =AVERAGE('Penilai 1'!F6,'Penilai 2'!F6,'Penilai 3'!F6) -> 87.666667 | G7: =AVERAGE('Penilai 1'!G6,'Penilai 2'!G6,'Penilai 3'!G6) -> 89.333333 | H7: =AVERAGE('Penilai 1'!H6,'Penilai 2'!H6,'Penilai 3'!H6) -> 88.666667
A8: 4 | B8: =Input!B17 -> Dewi Lestari | C8: =AVERAGE('Penilai 1'!C7,'Penilai 2'!C7,'Penilai 3'!C7) -> 82.333333 | D8: =AVERAGE('Penilai 1'!D7,'Penilai 2'!D7,'Penilai 3'!D7) -> 86 | E8: =AVERAGE('Penilai 1'!E7,'Penilai 2'!E7,'Penilai 3'!E7) -> 85 | F8: =AVERAGE('Penilai 1'!F7,'Penilai 2'!F7,'Penilai 3'!F7) -> 87.666667 | G8: =AVERAGE('Penilai 1'!G7,'Penilai 2'!G7,'Penilai 3'!G7) -> 80.666667 | H8: =AVERAGE('Penilai 1'!H7,'Penilai 2'!H7,'Penilai 3'!H7) -> 81.333333
A9: 5 | B9: =Input!B18 -> Ahmad Fauzi | C9: =AVERAGE('Penilai 1'!C8,'Penilai 2'!C8,'Penilai 3'!C8) -> 88.333333 | D9: =AVERAGE('Penilai 1'!D8,'Penilai 2'!D8,'Penilai 3'!D8) -> 89.333333 | E9: =AVERAGE('Penilai 1'!E8,'Penilai 2'!E8,'Penilai 3'!E8) -> 85 | F9: =AVERAGE('Penilai 1'!F8,'Penilai 2'!F8,'Penilai 3'!F8) -> 84 | G9: =AVERAGE('Penilai 1'!G8,'Penilai 2'!G8,'Penilai 3'!G8) -> 89.333333 | H9: =AVERAGE('Penilai 1'!H8,'Penilai 2'!H8,'Penilai 3'!H8) -> 88.333333
A10: 6 | B10: =Input!B19 -> Rina Wati | C10: =AVERAGE('Penilai 1'!C9,'Penilai 2'!C9,'Penilai 3'!C9) -> 80 | D10: =AVERAGE('Penilai 1'!D9,'Penilai 2'!D9,'Penilai 3'!D9) -> 80 | E10: =AVERAGE('Penilai 1'!E9,'Penilai 2'!E9,'Penilai 3'!E9) -> 82.333333 | F10: =AVERAGE('Penilai 1'!F9,'Penilai 2'!F9,'Penilai 3'!F9) -> 81 | G10: =AVERAGE('Penilai 1'!G9,'Penilai 2'!G9,'Penilai 3'!G9) -> 83 | H10: =AVERAGE('Penilai 1'!H9,'Penilai 2'!H9,'Penilai 3'!H9) -> 82.333333
A11: 7 | B11: =Input!B20 -> Joko Susilo | C11: =AVERAGE('Penilai 1'!C10,'Penilai 2'!C10,'Penilai 3'!C10) -> 83.333333 | D11: =AVERAGE('Penilai 1'!D10,'Penilai 2'!D10,'Penilai 3'!D10) -> 81.666667 | E11: =AVERAGE('Penilai 1'!E10,'Penilai 2'!E10,'Penilai 3'!E10) -> 85 | F11: =AVERAGE('Penilai 1'!F10,'Penilai 2'!F10,'Penilai 3'!F10) -> 83.333333 | G11: =AVERAGE('Penilai 1'!G10,'Penilai 2'!G10,'Penilai 3'!G10) -> 83.333333 | H11: =AVERAGE('Penilai 1'!H10,'Penilai 2'!H10,'Penilai 3'!H10) -> 82.333333
A12: 8 | B12: =Input!B21 -> Maya Sari | C12: =AVERAGE('Penilai 1'!C11,'Penilai 2'!C11,'Penilai 3'!C11) -> 87.666667 | D12: =AVERAGE('Penilai 1'!D11,'Penilai 2'!D11,'Penilai 3'!D11) -> 87.666667 | E12: =AVERAGE('Penilai 1'!E11,'Penilai 2'!E11,'Penilai 3'!E11) -> 88.333333 | F12: =AVERAGE('Penilai 1'!F11,'Penilai 2'!F11,'Penilai 3'!F11) -> 87.666667 | G12: =AVERAGE('Penilai 1'!G11,'Penilai 2'!G11,'Penilai 3'!G11) -> 89.333333 | H12: =AVERAGE('Penilai 1'!H11,'Penilai 2'!H11,'Penilai 3'!H11) -> 90
A13: 9 | B13: =Input!B22 -> Andi Pratama | C13: =AVERAGE('Penilai 1'!C12,'Penilai 2'!C12,'Penilai 3'!C12) -> 84 | D13: =AVERAGE('Penilai 1'!D12,'Penilai 2'!D12,'Penilai 3'!D12) -> 82.333333 | E13: =AVERAGE('Penilai 1'!E12,'Penilai 2'!E12,'Penilai 3'!E12) -> 82.333333 | F13: =AVERAGE('Penilai 1'!F12,'Penilai 2'!F12,'Penilai 3'!F12) -> 84 | G13: =AVERAGE('Penilai 1'!G12,'Penilai 2'!G12,'Penilai 3'!G12) -> 81.666667 | H13: =AVERAGE('Penilai 1'!H12,'Penilai 2'!H12,'Penilai 3'!H12) -> 82.333333
A14: 10 | B14: =Input!B23 -> Lina Marlina | C14: =AVERAGE('Penilai 1'!C13,'Penilai 2'!C13,'Penilai 3'!C13) -> 81.666667 | D14: =AVERAGE('Penilai 1'!D13,'Penilai 2'!D13,'Penilai 3'!D13) -> 82.333333 | E14: =AVERAGE('Penilai 1'!E13,'Penilai 2'!E13,'Penilai 3'!E13) -> 86.666667 | F14: =AVERAGE('Penilai 1'!F13,'Penilai 2'!F13,'Penilai 3'!F13) -> 85.666667 | G14: =AVERAGE('Penilai 1'!G13,'Penilai 2'!G13,'Penilai 3'!G13) -> 84 | H14: =AVERAGE('Penilai 1'!H13,'Penilai 2'!H13,'Penilai 3'!H13) -> 82.333333

Sheet Langkah 1-3
A1: LANGKAH 1-3: MATRIKS CRISP, EIGENVECTOR & UJI KONSISTENSI
A3: LANGKAH 1: MATRIKS PERBANDINGAN BERPASANGAN (CRISP)
B4: K1 | C4: K2 | D4: K3 | E4: K4 | F4: K5 | G4: K6
A5: K1 | B5: 1 | C5: =IF(Input!$C$5/Input!$C$6>=1,MIN(9,MAX(1,Input!$C$5/Input!$C$6)),MAX(1/9,Input!$C$5/Input!$C$6)) -> 0.625 | D5: =IF(Input!$C$5/Input!$C$7>=1,MIN(9,MAX(1,Input!$C$5/Input!$C$7)),MAX(1/9,Input!$C$5/Input!$C$7)) -> 0.71428571 | E5: =IF(Input!$C$5/Input!$C$8>=1,MIN(9,MAX(1,Input!$C$5/Input!$C$8)),MAX(1/9,Input!$C$5/Input!$C$8)) -> 2.5 | F5: =IF(Input!$C$5/Input!$C$9>=1,MIN(9,MAX(1,Input!$C$5/Input!$C$9)),MAX(1/9,Input!$C$5/Input!$C$9)) -> 1.25 | G5: =IF(Input!$C$5/Input!$C$10>=1,MIN(9,MAX(1,Input!$C$5/Input!$C$10)),MAX(1/9,Input!$C$5/Input!$C$10)) -> 0.625
A6: K2 | B6: =IF(Input!$C$6/Input!$C$5>=1,MIN(9,MAX(1,Input!$C$6/Input!$C$5)),MAX(1/9,Input!$C$6/Input!$C$5)) -> 1.6 | C6: 1 | D6: =IF(Input!$C$6/Input!$C$7>=1,MIN(9,MAX(1,Input!$C$6/Input!$C$7)),MAX(1/9,Input!$C$6/Input!$C$7)) -> 1.1428571 | E6: =IF(Input!$C$6/Input!$C$8>=1,MIN(9,MAX(1,Input!$C$6/Input!$C$8)),MAX(1/9,Input!$C$6/Input!$C$8)) -> 4 | F6: =IF(Input!$C$6/Input!$C$9>=1,MIN(9,MAX(1,Input!$C$6/Input!$C$9)),MAX(1/9,Input!$C$6/Input!$C$9)) -> 2 | G6: =IF(Input!$C$6/Input!$C$10>=1,MIN(9,MAX(1,Input!$C$6/Input!$C$10)),MAX(1/9,Input!$C$6/Input!$C$10)) -> 1
A7: K3 | B7: =IF(Input!$C$7/Input!$C$5>=1,MIN(9,MAX(1,Input!$C$7/Input!$C$5)),MAX(1/9,Input!$C$7/Input!$C$5)) -> 1.4 | C7: =IF(Input!$C$7/Input!$C$6>=1,MIN(9,MAX(1,Input!$C$7/Input!$C$6)),MAX(1/9,Input!$C$7/Input!$C$6)) -> 0.875 | D7: 1 | E7: =IF(Input!$C$7/Input!$C$8>=1,MIN(9,MAX(1,Input!$C$7/Input!$C$8)),MAX(1/9,Input!$C$7/Input!$C$8)) -> 3.5 | F7: =IF(Input!$C$7/Input!$C$9>=1,MIN(9,MAX(1,Input!$C$7/Input!$C$9)),MAX(1/9,Input!$C$7/Input!$C$9)) -> 1.75 | G7: =IF(Input!$C$7/Input!$C$10>=1,MIN(9,MAX(1,Input!$C$7/Input!$C$10)),MAX(1/9,Input!$C$7/Input!$C$10)) -> 0.875
A8: K4 | B8: =IF(Input!$C$8/Input!$C$5>=1,MIN(9,MAX(1,Input!$C$8/Input!$C$5)),MAX(1/9,Input!$C$8/Input!$C$5)) -> 0.4 | C8: =IF(Input!$C$8/Input!$C$6>=1,MIN(9,MAX(1,Input!$C$8/Input!$C$6)),MAX(1/9,Input!$C$8/Input!$C$6)) -> 0.25 | D8: =IF(Input!$C$8/Input!$C$7>=1,MIN(9,MAX(1,Input!$C$8/Input!$C$7)),MAX(1/9,Input!$C$8/Input!$C$7)) -> 0.28571429 | E8: 1 | F8: =IF(Input!$C$8/Input!$C$9>=1,MIN(9,MAX(1,Input!$C$8/Input!$C$9)),MAX(1/9,Input!$C$8/Input!$C$9)) -> 0.5 | G8: =IF(Input!$C$8/Input!$C$10>=1,MIN(9,MAX(1,Input!$C$8/Input!$C$10)),MAX(1/9,Input!$C$8/Input!$C$10)) -> 0.25
A9: K5 | B9: =IF(Input!$C$9/Input!$C$5>=1,MIN(9,MAX(1,Input!$C$9/Input!$C$5)),MAX(1/9,Input!$C$9/Input!$C$5)) -> 0.8 | C9: =IF(Input!$C$9/Input!$C$6>=1,MIN(9,MAX(1,Input!$C$9/Input!$C$6)),MAX(1/9,Input!$C$9/Input!$C$6)) -> 0.5 | D9: =IF(Input!$C$9/Input!$C$7>=1,MIN(9,MAX(1,Input!$C$9/Input!$C$7)),MAX(1/9,Input!$C$9/Input!$C$7)) -> 0.57142857 | E9: =IF(Input!$C$9/Input!$C$8>=1,MIN(9,MAX(1,Input!$C$9/Input!$C$8)),MAX(1/9,Input!$C$9/Input!$C$8)) -> 2 | F9: 1 | G9: =IF(Input!$C$9/Input!$C$10>=1,MIN(9,MAX(1,Input!$C$9/Input!$C$10)),MAX(1/9,Input!$C$9/Input!$C$10)) -> 0.5
A10: K6 | B10: =IF(Input!$C$10/Input!$C$5>=1,MIN(9,MAX(1,Input!$C$10/Input!$C$5)),MAX(1/9,Input!$C$10/Input!$C$5)) -> 1.6 | C10: =IF(Input!$C$10/Input!$C$6>=1,MIN(9,MAX(1,Input!$C$10/Input!$C$6)),MAX(1/9,Input!$C$10/Input!$C$6)) -> 1 | D10: =IF(Input!$C$10/Input!$C$7>=1,MIN(9,MAX(1,Input!$C$10/Input!$C$7)),MAX(1/9,Input!$C$10/Input!$C$7)) -> 1.1428571 | E10: =IF(Input!$C$10/Input!$C$8>=1,MIN(9,MAX(1,Input!$C$10/Input!$C$8)),MAX(1/9,Input!$C$10/Input!$C$8)) -> 4 | F10: =IF(Input!$C$10/Input!$C$9>=1,MIN(9,MAX(1,Input!$C$10/Input!$C$9)),MAX(1/9,Input!$C$10/Input!$C$9)) -> 2 | G10: 1
A12: LANGKAH 2: PERHITUNGAN VECTOR EIGEN (GEOMETRIC MEAN)
A13: Kriteria | B13: Geometric Mean | C13: Eigenvector (Wi)
A14: Status Keaktifan | B14: =(B5*C5*D5*E5*F5*G5)^(1/6) -> 0.97741801 | C14: =B14/$B$20 -> 0.14705882
A15: Pencapaian SKU | B15: =(B6*C6*D6*E6*F6*G6)^(1/6) -> 1.5638688 | C15: =B15/$B$20 -> 0.23529412
A16: Pencapaian SPG | B16: =(B7*C7*D7*E7*F7*G7)^(1/6) -> 1.3683852 | C16: =B16/$B$20 -> 0.20588235
A17: Kesehatan Jasmani | B17: =(B8*C8*D8*E8*F8*G8)^(1/6) -> 0.3909672 | C17: =B17/$B$20 -> 0.058823529
A18: Tes Wawancara | B18: =(B9*C9*D9*E9*F9*G9)^(1/6) -> 0.78193441 | C18: =B18/$B$20 -> 0.11764706
A19: Tes Pilihan Ganda | B19: =(B10*C10*D10*E10*F10*G10)^(1/6) -> 1.5638688 | C19: =B19/$B$20 -> 0.23529412
A20: Total | B20: =SUM(B14:B19) -> 6.6464425 | C20: =SUM(C14:C19) -> 1
A22: LANGKAH 3: UJI KONSISTENSI
A23: Kriteria | B23: A*w | C23: (A*w)/w
A24: Status Keaktifan | B24: =B5*$C$14+C5*$C$15+D5*$C$16+E5*$C$17+F5*$C$18+G5*$C$19 -> 0.88235294 | C24: =B24/$C$14 -> 6
A25: Pencapaian SKU | B25: =B6*$C$14+C6*$C$15+D6*$C$16+E6*$C$17+F6*$C$18+G6*$C$19 -> 1.4117647 | C25: =B25/$C$15 -> 6
A26: Pencapaian SPG | B26: =B7*$C$14+C7*$C$15+D7*$C$16+E7*$C$17+F7*$C$18+G7*$C$19 -> 1.2352941 | C26: =B26/$C$16 -> 6
A27: Kesehatan Jasmani | B27: =B8*$C$14+C8*$C$15+D8*$C$16+E8*$C$17+F8*$C$18+G8*$C$19 -> 0.35294118 | C27: =B27/$C$17 -> 6
A28: Tes Wawancara | B28: =B9*$C$14+C9*$C$15+D9*$C$16+E9*$C$17+F9*$C$18+G9*$C$19 -> 0.70588235 | C28: =B28/$C$18 -> 6
A29: Tes Pilihan Ganda | B29: =B10*$C$14+C10*$C$15+D10*$C$16+E10*$C$17+F10*$C$18+G10*$C$19 -> 1.4117647 | C29: =B29/$C$19 -> 6
A31: Lambda Max: | B31: =AVERAGE(C24:C29) -> 6
A32: CI: | B32: =(B31-6)/(6-1) -> 0
A33: RI (n=6): | B33: 1.24
A34: CR: | B34: =B32/B33 -> 0
A35: Status: | B35: =IF(B34<=0.1,"KONSISTEN","TIDAK KONSISTEN") -> KONSISTEN

Sheet Langkah 4-6
A1: LANGKAH 4-6: FUZZIFIKASI, SYNTHETIC EXTENT & BOBOT GLOBAL
A3: LANGKAH 4: FUZZIFIKASI MATRIKS PERBANDINGAN BERPASANGAN | X3: Key | Y3: l | Z3: m | AA3: u
B4: K1 | E4: K2 | H4: K3 | K4: K4 | N4: K5 | Q4: K6 | X4: 1 | Y4: 1 | Z4: 1 | AA4: 1
B5: l | C5: m | D5: u | E5: l | F5: m | G5: u | H5: l | I5: m | J5: u | K5: l | L5: m | M5: u | N5: l | O5: m | P5: u | Q5: l | R5: m | S5: u | X5: 2 | Y5: 0.5 | Z5: 1 | AA5: 1.5
A6: K1 | B6: =IF('Langkah 1-3'!B$5>=1,VLOOKUP(MAX(1,MIN(9,IF(MOD(IF('Langkah 1-3'!B$5>=1,'Langkah 1-3'!B$5,1/'Langkah 1-3'!B$5),1)=0.5,2*ROUND(IF('Langkah 1-3'!B$5>=1,'Langkah 1-3'!B$5,1/'Langkah 1-3'!B$5)/2,0),ROUND(IF('Langkah 1-3'!B$5>=1,'Langkah 1-3'!B$5,1/'Langkah 1-3'!B$5),0)))),$X$4:$AA$12,2,FALSE),1/VLOOKUP(MAX(1,MIN(9,IF(MOD(IF('Langkah 1-3'!B$5>=1,'Langkah 1-3'!B$5,1/'Langkah 1-3'!B$5),1)=0.5,2*ROUND(IF('Langkah 1-3'!B$5>=1,'Langkah 1-3'!B$5,1/'Langkah 1-3'!B$5)/2,0),ROUND(IF('Langkah 1-3'!B$5>=1,'Langkah 1-3'!B$5,1/'Langkah 1-3'!B$5),0)))),$X$4:$AA$12,4,FALSE)) -> 1 | C6: =IF('Langkah 1-3'!B$5>=1,VLOOKUP(MAX(1,MIN(9,IF(MOD(IF('Langkah 1-3'!B$5>=1,'Langkah 1-3'!B$5,1/'Langkah 1-3'!B$5),1)=0.5,2*ROUND(IF('Langkah 1-3'!B$5>=1,'Langkah 1-3'!B$5,1/'Langkah 1-3'!B$5)/2,0),ROUND(IF('Langkah 1-3'!B$5>=1,'Langkah 1-3'!B$5,1/'Langkah 1-3'!B$5),0)))),$X$4:$AA$12,3,FALSE),1/VLOOKUP(MAX(1,MIN(9,IF(MOD(IF('Langkah 1-3'!B$5>=1,'Langkah 1-3'!B$5,1/'Langkah 1-3'!B$5),1)=0.5,2*ROUND(IF('Langkah 1-3'!B$5>=1,'Langkah 1-3'!B$5,1/'Langkah 1-3'!B$5)/2,0),ROUND(IF('Langkah 1-3'!B$5>=1,'Langkah 1-3'!B$5,1/'Langkah 1-3'!B$5),0)))),$X$4:$AA$12,3,FALSE)) -> 1 | D6: =IF('Langkah 1-3'!B$5>=1,VLOOKUP(MAX(1,MIN(9,IF(MOD(IF('Langkah 1-3'!B$5>=1,'Langkah 1-3'!B$5,1/'Langkah 1-3'!B$5),1)=0.5,2*ROUND(IF('Langkah 1-3'!B$5>=1,'Langkah 1-3'!B$5,1/'Langkah 1-3'!B$5)/2,0),ROUND(IF('Langkah 1-3'!B$5>=1,'Langkah 1-3'!B$5,1/'Langkah 1-3'!B$5),0)))),$X$4:$AA$12,4,FALSE),1/VLOOKUP(MAX(1,MIN(9,IF(MOD(IF('Langkah 1-3'!B$5>=1,'Langkah 1-3'!B$5,1/'Langkah 1-3'!B$5),1)=0.5,2*ROUND(IF('Langkah 1-3'!B$5>=1,'Langkah 1-3'!B$5,1/'Langkah 1-3'!B$5)/2,0),ROUND(IF('Langkah 1-3'!B$5>=1,'Langkah 1-3'!B$5,1/'Langkah 1-3'!B$5),0)))),$X$4:$AA$12,2,FALSE)) -> 1 | E6: =IF('Langkah 1-3'!C$5>=1,VLOOKUP(MAX(1,MIN(9,IF(MOD(IF('Langkah 1-3'!C$5>=1,'Langkah 1-3'!C$5,1/'Langkah 1-3'!C$5),1)=0.5,2*ROUND(IF('Langkah 1-3'!C$5>=1,'Langkah 1-3'!C$5,1/'Langkah 1-3'!C$5)/2,0),ROUND(IF('Langkah 1-3'!C$5>=1,'Langkah 1-3'!C$5,1/'Langkah 1-3'!C$5),0)))),$X$4:$AA$12,2,FALSE),1/VLOOKUP(MAX(1,MIN(9,IF(MOD(IF('Langkah 1-3'!C$5>=1,'Langkah 1-3'!C$5,1/'Langkah 1-3'!C$5),1)=0.5,2*ROUND(IF('Langkah 1-3'!C$5>=1,'Langkah 1-3'!C$5,1/'Langkah 1-3'!C$5)/2,0),ROUND(IF('Langkah 1-3'!C$5>=1,'Langkah 1-3'!C$5,1/'Langkah 1-3'!C$5),0)))),$X$4:$AA$12,4,FALSE)) -> 0.66666667 | F6: =IF('Langkah 1-3'!C$5>=1,VLOOKUP(MAX(1,MIN(9,IF(MOD(IF('Langkah 1-3'!C$5>=1,'Langkah 1-3'!C$5,1/'Langkah 1-3'!C$5),1)=0.5,2*ROUND(IF('Langkah 1-3'!C$5>=1,'Langkah 1-3'!C$5,1/'Langkah 1-3'!C$5)/2,0),ROUND(IF('Langkah 1-3'!C$5>=1,'Langkah 1-3'!C$5,1/'Langkah 1-3'!C$5),0)))),$X$4:$AA$12,3,FALSE),1/VLOOKUP(MAX(1,MIN(9,IF(MOD(IF('Langkah 1-3'!C$5>=1,'Langkah 1-3'!C$5,1/'Langkah 1-3'!C$5),1)=0.5,2*ROUND(IF('Langkah 1-3'!C$5>=1,'Langkah 1-3'!C$5,1/'Langkah 1-3'!C$5)/2,0),ROUND(IF('Langkah 1-3'!C$5>=1,'Langkah 1-3'!C$5,1/'Langkah 1-3'!C$5),0)))),$X$4:$AA$12,3,FALSE)) -> 1 | G6: =IF('Langkah 1-3'!C$5>=1,VLOOKUP(MAX(1,MIN(9,IF(MOD(IF('Langkah 1-3'!C$5>=1,'Langkah 1-3'!C$5,1/'Langkah 1-3'!C$5),1)=0.5,2*ROUND(IF('Langkah 1-3'!C$5>=1,'Langkah 1-3'!C$5,1/'Langkah 1-3'!C$5)/2,0),ROUND(IF('Langkah 1-3'!C$5>=1,'Langkah 1-3'!C$5,1/'Langkah 1-3'!C$5),0)))),$X$4:$AA$12,4,FALSE),1/VLOOKUP(MAX(1,MIN(9,IF(MOD(IF('Langkah 1-3'!C$5>=1,'Langkah 1-3'!C$5,1/'Langkah 1-3'!C$5),1)=0.5,2*ROUND(IF('Langkah 1-3'!C$5>=1,'Langkah 1-3'!C$5,1/'Langkah 1-3'!C$5)/2,0),ROUND(IF('Langkah 1-3'!C$5>=1,'Langkah 1-3'!C$5,1/'Langkah 1-3'!C$5),0)))),$X$4:$AA$12,2,FALSE)) -> 2 | H6: =IF('Langkah 1-3'!D$5>=1,VLOOKUP(MAX(1,MIN(9,IF(MOD(IF('Langkah 1-3'!D$5>=1,'Langkah 1-3'!D$5,1/'Langkah 1-3'!D$5),1)=0.5,2*ROUND(IF('Langkah 1-3'!D$5>=1,'Langkah 1-3'!D$5,1/'Langkah 1-3'!D$5)/2,0),ROUND(IF('Langkah 1-3'!D$5>=1,'Langkah 1-3'!D$5,1/'Langkah 1-3'!D$5),0)))),$X$4:$AA$12,2,FALSE),1/VLOOKUP(MAX(1,MIN(9,IF(MOD(IF('Langkah 1-3'!D$5>=1,'Langkah 1-3'!D$5,1/'Langkah 1-3'!D$5),1)=0.5,2*ROUND(IF('Langkah 1-3'!D$5>=1,'Langkah 1-3'!D$5,1/'Langkah 1-3'!D$5)/2,0),ROUND(IF('Langkah 1-3'!D$5>=1,'Langkah 1-3'!D$5,1/'Langkah 1-3'!D$5),0)))),$X$4:$AA$12,4,FALSE)) -> 1 | I6: =IF('Langkah 1-3'!D$5>=1,VLOOKUP(MAX(1,MIN(9,IF(MOD(IF('Langkah 1-3'!D$5>=1,'Langkah 1-3'!D$5,1/'Langkah 1-3'!D$5),1)=0.5,2*ROUND(IF('Langkah 1-3'!D$5>=1,'Langkah 1-3'!D$5,1/'Langkah 1-3'!D$5)/2,0),ROUND(IF('Langkah 1-3'!D$5>=1,'Langkah 1-3'!D$5,1/'Langkah 1-3'!D$5),0)))),$X$4:$AA$12,3,FALSE),1/VLOOKUP(MAX(1,MIN(9,IF(MOD(IF('Langkah 1-3'!D$5>=1,'Langkah 1-3'!D$5,1/'Langkah 1-3'!D$5),1)=0.5,2*ROUND(IF('Langkah 1-3'!D$5>=1,'Langkah 1-3'!D$5,1/'Langkah 1-3'!D$5)/2,0),ROUND(IF('Langkah 1-3'!D$5>=1,'Langkah 1-3'!D$5,1/'Langkah 1-3'!D$5),0)))),$X$4:$AA$12,3,FALSE)) -> 1 | J6: =IF('Langkah 1-3'!D$5>=1,VLOOKUP(MAX(1,MIN(9,IF(MOD(IF('Langkah 1-3'!D$5>=1,'Langkah 1-3'!D$5,1/'Langkah 1-3'!D$5),1)=0.5,2*ROUND(IF('Langkah 1-3'!D$5>=1,'Langkah 1-3'!D$5,1/'Langkah 1-3'!D$5)/2,0),ROUND(IF('Langkah 1-3'!D$5>=1,'Langkah 1-3'!D$5,1/'Langkah 1-3'!D$5),0)))),$X$4:$AA$12,4,FALSE),1/VLOOKUP(MAX(1,MIN(9,IF(MOD(IF('Langkah 1-3'!D$5>=1,'Langkah 1-3'!D$5,1/'Langkah 1-3'!D$5),1)=0.5,2*ROUND(IF('Langkah 1-3'!D$5>=1,'Langkah 1-3'!D$5,1/'Langkah 1-3'!D$5)/2,0),ROUND(IF('Langkah 1-3'!D$5>=1,'Langkah 1-3'!D$5,1/'Langkah 1-3'!D$5),0)))),$X$4:$AA$12,2,FALSE)) -> 1 | K6: =IF('Langkah 1-3'!E$5>=1,VLOOKUP(MAX(1,MIN(9,IF(MOD(IF('Langkah 1-3'!E$5>=1,'Langkah 1-3'!E$5,1/'Langkah 1-3'!E$5),1)=0.5,2*ROUND(IF('Langkah 1-3'!E$5>=1,'Langkah 1-3'!E$5,1/'Langkah 1-3'!E$5)/2,0),ROUND(IF('Langkah 1-3'!E$5>=1,'Langkah 1-3'!E$5,1/'Langkah 1-3'!E$5),0)))),$X$4:$AA$12,2,FALSE),1/VLOOKUP(MAX(1,MIN(9,IF(MOD(IF('Langkah 1-3'!E$5>=1,'Langkah 1-3'!E$5,1/'Langkah 1-3'!E$5),1)=0.5,2*ROUND(IF('Langkah 1-3'!E$5>=1,'Langkah 1-3'!E$5,1/'Langkah 1-3'!E$5)/2,0),ROUND(IF('Langkah 1-3'!E$5>=1,'Langkah 1-3'!E$5,1/'Langkah 1-3'!E$5),0)))),$X$4:$AA$12,4,FALSE)) -> 0.5 | L6: =IF('Langkah 1-3'!E$5>=1,VLOOKUP(MAX(1,MIN(9,IF(MOD(IF('Langkah 1-3'!E$5>=1,'Langkah 1-3'!E$5,1/'Langkah 1-3'!E$5),1)=0.5,2*ROUND(IF('Langkah 1-3'!E$5>=1,'Langkah 1-3'!E$5,1/'Langkah 1-3'!E$5)/2,0),ROUND(IF('Langkah 1-3'!E$5>=1,'Langkah 1-3'!E$5,1/'Langkah 1-3'!E$5),0)))),$X$4:$AA$12,3,FALSE),1/VLOOKUP(MAX(1,MIN(9,IF(MOD(IF('Langkah 1-3'!E$5>=1,'Langkah 1-3'!E$5,1/'Langkah 1-3'!E$5),1)=0.5,2*ROUND(IF('Langkah 1-3'!E$5>=1,'Langkah 1-3'!E$5,1/'Langkah 1-3'!E$5)/2,0),ROUND(IF('Langkah 1-3'!E$5>=1,'Langkah 1-3'!E$5,1/'Langkah 1-3'!E$5),0)))),$X$4:$AA$12,3,FALSE)) -> 1 | M6: =IF('Langkah 1-3'!E$5>=1,VLOOKUP(MAX(1,MIN(9,IF(MOD(IF('Langkah 1-3'!E$5>=1,'Langkah 1-3'!E$5,1/'Langkah 1-3'!E$5),1)=0.5,2*ROUND(IF('Langkah 1-3'!E$5>=1,'Langkah 1-3'!E$5,1/'Langkah 1-3'!E$5)/2,0),ROUND(IF('Langkah 1-3'!E$5>=1,'Langkah 1-3'!E$5,1/'Langkah 1-3'!E$5),0)))),$X$4:$AA$12,4,FALSE),1/VLOOKUP(MAX(1,MIN(9,IF(MOD(IF('Langkah 1-3'!E$5>=1,'Langkah 1-3'!E$5,1/'Langkah 1-3'!E$5),1)=0.5,2*ROUND(IF('Langkah 1-3'!E$5>=1,'Langkah 1-3'!E$5,1/'Langkah 1-3'!E$5)/2,0),ROUND(IF('Langkah 1-3'!E$5>=1,'Langkah 1-3'!E$5,1/'Langkah 1-3'!E$5),0)))),$X$4:$AA$12,2,FALSE)) -> 1.5 | N6: =IF('Langkah 1-3'!F$5>=1,VLOOKUP(MAX(1,MIN(9,IF(MOD(IF('Langkah 1-3'!F$5>=1,'Langkah 1-3'!F$5,1/'Langkah 1-3'!F$5),1)=0.5,2*ROUND(IF('Langkah 1-3'!F$5>=1,'Langkah 1-3'!F$5,1/'Langkah 1-3'!F$5)/2,0),ROUND(IF('Langkah 1-3'!F$5>=1,'Langkah 1-3'!F$5,1/'Langkah 1-3'!F$5),0)))),$X$4:$AA$12,2,FALSE),1/VLOOKUP(MAX(1,MIN(9,IF(MOD(IF('Langkah 1-3'!F$5>=1,'Langkah 1-3'!F$5,1/'Langkah 1-3'!F$5),1)=0.5,2*ROUND(IF('Langkah 1-3'!F$5>=1,'Langkah 1-3'!F$5,1/'Langkah 1-3'!F$5)/2,0),ROUND(IF('Langkah 1-3'!F$5>=1,'Langkah 1-3'!F$5,1/'Langkah 1-3'!F$5),0)))),$X$4:$AA$12,4,FALSE)) -> 1 | O6: =IF('Langkah 1-3'!F$5>=1,VLOOKUP(MAX(1,MIN(9,IF(MOD(IF('Langkah 1-3'!F$5>=1,'Langkah 1-3'!F$5,1/'Langkah 1-3'!F$5),1)=0.5,2*ROUND(IF('Langkah 1-3'!F$5>=1,'Langkah 1-3'!F$5,1/'Langkah 1-3'!F$5)/2,0),ROUND(IF('Langkah 1-3'!F$5>=1,'Langkah 1-3'!F$5,1/'Langkah 1-3'!F$5),0)))),$X$4:$AA$12,3,FALSE),1/VLOOKUP(MAX(1,MIN(9,IF(MOD(IF('Langkah 1-3'!F$5>=1,'Langkah 1-3'!F$5,1/'Langkah 1-3'!F$5),1)=0.5,2*ROUND(IF('Langkah 1-3'!F$5>=1,'Langkah 1-3'!F$5,1/'Langkah 1-3'!F$5)/2,0),ROUND(IF('Langkah 1-3'!F$5>=1,'Langkah 1-3'!F$5,1/'Langkah 1-3'!F$5),0)))),$X$4:$AA$12,3,FALSE)) -> 1 | P6: =IF('Langkah 1-3'!F$5>=1,VLOOKUP(MAX(1,MIN(9,IF(MOD(IF('Langkah 1-3'!F$5>=1,'Langkah 1-3'!F$5,1/'Langkah 1-3'!F$5),1)=0.5,2*ROUND(IF('Langkah 1-3'!F$5>=1,'Langkah 1-3'!F$5,1/'Langkah 1-3'!F$5)/2,0),ROUND(IF('Langkah 1-3'!F$5>=1,'Langkah 1-3'!F$5,1/'Langkah 1-3'!F$5),0)))),$X$4:$AA$12,4,FALSE),1/VLOOKUP(MAX(1,MIN(9,IF(MOD(IF('Langkah 1-3'!F$5>=1,'Langkah 1-3'!F$5,1/'Langkah 1-3'!F$5),1)=0.5,2*ROUND(IF('Langkah 1-3'!F$5>=1,'Langkah 1-3'!F$5,1/'Langkah 1-3'!F$5)/2,0),ROUND(IF('Langkah 1-3'!F$5>=1,'Langkah 1-3'!F$5,1/'Langkah 1-3'!F$5),0)))),$X$4:$AA$12,2,FALSE)) -> 1 | Q6: =IF('Langkah 1-3'!G$5>=1,VLOOKUP(MAX(1,MIN(9,IF(MOD(IF('Langkah 1-3'!G$5>=1,'Langkah 1-3'!G$5,1/'Langkah 1-3'!G$5),1)=0.5,2*ROUND(IF('Langkah 1-3'!G$5>=1,'Langkah 1-3'!G$5,1/'Langkah 1-3'!G$5)/2,0),ROUND(IF('Langkah 1-3'!G$5>=1,'Langkah 1-3'!G$5,1/'Langkah 1-3'!G$5),0)))),$X$4:$AA$12,2,FALSE),1/VLOOKUP(MAX(1,MIN(9,IF(MOD(IF('Langkah 1-3'!G$5>=1,'Langkah 1-3'!G$5,1/'Langkah 1-3'!G$5),1)=0.5,2*ROUND(IF('Langkah 1-3'!G$5>=1,'Langkah 1-3'!G$5,1/'Langkah 1-3'!G$5)/2,0),ROUND(IF('Langkah 1-3'!G$5>=1,'Langkah 1-3'!G$5,1/'Langkah 1-3'!G$5),0)))),$X$4:$AA$12,4,FALSE)) -> 0.66666667 | R6: =IF('Langkah 1-3'!G$5>=1,VLOOKUP(MAX(1,MIN(9,IF(MOD(IF('Langkah 1-3'!G$5>=1,'Langkah 1-3'!G$5,1/'Langkah 1-3'!G$5),1)=0.5,2*ROUND(IF('Langkah 1-3'!G$5>=1,'Langkah 1-3'!G$5,1/'Langkah 1-3'!G$5)/2,0),ROUND(IF('Langkah 1-3'!G$5>=1,'Langkah 1-3'!G$5,1/'Langkah 1-3'!G$5),0)))),$X$4:$AA$12,3,FALSE),1/VLOOKUP(MAX(1,MIN(9,IF(MOD(IF('Langkah 1-3'!G$5>=1,'Langkah 1-3'!G$5,1/'Langkah 1-3'!G$5),1)=0.5,2*ROUND(IF('Langkah 1-3'!G$5>=1,'Langkah 1-3'!G$5,1/'Langkah 1-3'!G$5)/2,0),ROUND(IF('Langkah 1-3'!G$5>=1,'Langkah 1-3'!G$5,1/'Langkah 1-3'!G$5),0)))),$X$4:$AA$12,3,FALSE)) -> 1 | S6: =IF('Langkah 1-3'!G$5>=1,VLOOKUP(MAX(1,MIN(9,IF(MOD(IF('Langkah 1-3'!G$5>=1,'Langkah 1-3'!G$5,1/'Langkah 1-3'!G$5),1)=0.5,2*ROUND(IF('Langkah 1-3'!G$5>=1,'Langkah 1-3'!G$5,1/'Langkah 1-3'!G$5)/2,0),ROUND(IF('Langkah 1-3'!G$5>=1,'Langkah 1-3'!G$5,1/'Langkah 1-3'!G$5),0)))),$X$4:$AA$12,4,FALSE),1/VLOOKUP(MAX(1,MIN(9,IF(MOD(IF('Langkah 1-3'!G$5>=1,'Langkah 1-3'!G$5,1/'Langkah 1-3'!G$5),1)=0.5,2*ROUND(IF('Langkah 1-3'!G$5>=1,'Langkah 1-3'!G$5,1/'Langkah 1-3'!G$5)/2,0),ROUND(IF('Langkah 1-3'!G$5>=1,'Langkah 1-3'!G$5,1/'Langkah 1-3'!G$5),0)))),$X$4:$AA$12,2,FALSE)) -> 2 | X6: 3 | Y6: 1 | Z6: 1.5 | AA6: 2
A7: K2 | B7: =IF('Langkah 1-3'!B$6>=1,VLOOKUP(MAX(1,MIN(9,IF(MOD(IF('Langkah 1-3'!B$6>=1,'Langkah 1-3'!B$6,1/'Langkah 1-3'!B$6),1)=0.5,2*ROUND(IF('Langkah 1-3'!B$6>=1,'Langkah 1-3'!B$6,1/'Langkah 1-3'!B$6)/2,0),ROUND(IF('Langkah 1-3'!B$6>=1,'Langkah 1-3'!B$6,1/'Langkah 1-3'!B$6),0)))),$X$4:$AA$12,2,FALSE),1/VLOOKUP(MAX(1,MIN(9,IF(MOD(IF('Langkah 1-3'!B$6>=1,'Langkah 1-3'!B$6,1/'Langkah 1-3'!B$6),1)=0.5,2*ROUND(IF('Langkah 1-3'!B$6>=1,'Langkah 1-3'!B$6,1/'Langkah 1-3'!B$6)/2,0),ROUND(IF('Langkah 1-3'!B$6>=1,'Langkah 1-3'!B$6,1/'Langkah 1-3'!B$6),0)))),$X$4:$AA$12,4,FALSE)) -> 0.5 | C7: =IF('Langkah 1-3'!B$6>=1,VLOOKUP(MAX(1,MIN(9,IF(MOD(IF('Langkah 1-3'!B$6>=1,'Langkah 1-3'!B$6,1/'Langkah 1-3'!B$6),1)=0.5,2*ROUND(IF('Langkah 1-3'!B$6>=1,'Langkah 1-3'!B$6,1/'Langkah 1-3'!B$6)/2,0),ROUND(IF('Langkah 1-3'!B$6>=1,'Langkah 1-3'!B$6,1/'Langkah 1-3'!B$6),0)))),$X$4:$AA$12,3,FALSE),1/VLOOKUP(MAX(1,MIN(9,IF(MOD(IF('Langkah 1-3'!B$6>=1,'Langkah 1-3'!B$6,1/'Langkah 1-3'!B$6),1)=0.5,2*ROUND(IF('Langkah 1-3'!B$6>=1,'Langkah 1-3'!B$6,1/'Langkah 1-3'!B$6)/2,0),ROUND(IF('Langkah 1-3'!B$6>=1,'Langkah 1-3'!B$6,1/'Langkah 1-3'!B$6),0)))),$X$4:$AA$12,3,FALSE)) -> 1 | D7: =IF('Langkah 1-3'!B$6>=1,VLOOKUP(MAX(1,MIN(9,IF(MOD(IF('Langkah 1-3'!B$6>=1,'Langkah 1-3'!B$6,1/'Langkah 1-3'!B$6),1)=0.5,2*ROUND(IF('Langkah 1-3'!B$6>=1,'Langkah 1-3'!B$6,1/'Langkah 1-3'!B$6)/2,0),ROUND(IF('Langkah 1-3'!B$6>=1,'Langkah 1-3'!B$6,1/'Langkah 1-3'!B$6),0)))),$X$4:$AA$12,4,FALSE),1/VLOOKUP(MAX(1,MIN(9,IF(MOD(IF('Langkah 1-3'!B$6>=1,'Langkah 1-3'!B$6,1/'Langkah 1-3'!B$6),1)=0.5,2*ROUND(IF('Langkah 1-3'!B$6>=1,'Langkah 1-3'!B$6,1/'Langkah 1-3'!B$6)/2,0),ROUND(IF('Langkah 1-3'!B$6>=1,'Langkah 1-3'!B$6,1/'Langkah 1-3'!B$6),0)))),$X$4:$AA$12,2,FALSE)) -> 1.5 | E7: =IF('Langkah 1-3'!C$6>=1,VLOOKUP(MAX(1,MIN(9,IF(MOD(IF('Langkah 1-3'!C$6>=1,'Langkah 1-3'!C$6,1/'Langkah 1-3'!C$6),1)=0.5,2*ROUND(IF('Langkah 1-3'!C$6>=1,'Langkah 1-3'!C$6,1/'Langkah 1-3'!C$6)/2,0),ROUND(IF('Langkah 1-3'!C$6>=1,'Langkah 1-3'!C$6,1/'Langkah 1-3'!C$6),0)))),$X$4:$AA$12,2,FALSE),1/VLOOKUP(MAX(1,MIN(9,IF(MOD(IF('Langkah 1-3'!C$6>=1,'Langkah 1-3'!C$6,1/'Langkah 1-3'!C$6),1)=0.5,2*ROUND(IF('Langkah 1-3'!C$6>=1,'Langkah 1-3'!C$6,1/'Langkah 1-3'!C$6)/2,0),ROUND(IF('Langkah 1-3'!C$6>=1,'Langkah 1-3'!C$6,1/'Langkah 1-3'!C$6),0)))),$X$4:$AA$12,4,FALSE)) -> 1 | F7: =IF('Langkah 1-3'!C$6>=1,VLOOKUP(MAX(1,MIN(9,IF(MOD(IF('Langkah 1-3'!C$6>=1,'Langkah 1-3'!C$6,1/'Langkah 1-3'!C$6),1)=0.5,2*ROUND(IF('Langkah 1-3'!C$6>=1,'Langkah 1-3'!C$6,1/'Langkah 1-3'!C$6)/2,0),ROUND(IF('Langkah 1-3'!C$6>=1,'Langkah 1-3'!C$6,1/'Langkah 1-3'!C$6),0)))),$X$4:$AA$12,3,FALSE),1/VLOOKUP(MAX(1,MIN(9,IF(MOD(IF('Langkah 1-3'!C$6>=1,'Langkah 1-3'!C$6,1/'Langkah 1-3'!C$6),1)=0.5,2*ROUND(IF('Langkah 1-3'!C$6>=1,'Langkah 1-3'!C$6,1/'Langkah 1-3'!C$6)/2,0),ROUND(IF('Langkah 1-3'!C$6>=1,'Langkah 1-3'!C$6,1/'Langkah 1-3'!C$6),0)))),$X$4:$AA$12,3,FALSE)) -> 1 | G7: =IF('Langkah 1-3'!C$6>=1,VLOOKUP(MAX(1,MIN(9,IF(MOD(IF('Langkah 1-3'!C$6>=1,'Langkah 1-3'!C$6,1/'Langkah 1-3'!C$6),1)=0.5,2*ROUND(IF('Langkah 1-3'!C$6>=1,'Langkah 1-3'!C$6,1/'Langkah 1-3'!C$6)/2,0),ROUND(IF('Langkah 1-3'!C$6>=1,'Langkah 1-3'!C$6,1/'Langkah 1-3'!C$6),0)))),$X$4:$AA$12,4,FALSE),1/VLOOKUP(MAX(1,MIN(9,IF(MOD(IF('Langkah 1-3'!C$6>=1,'Langkah 1-3'!C$6,1/'Langkah 1-3'!C$6),1)=0.5,2*ROUND(IF('Langkah 1-3'!C$6>=1,'Langkah 1-3'!C$6,1/'Langkah 1-3'!C$6)/2,0),ROUND(IF('Langkah 1-3'!C$6>=1,'Langkah 1-3'!C$6,1/'Langkah 1-3'!C$6),0)))),$X$4:$AA$12,2,FALSE)) -> 1 | H7: =IF('Langkah 1-3'!D$6>=1,VLOOKUP(MAX(1,MIN(9,IF(MOD(IF('Langkah 1-3'!D$6>=1,'Langkah 1-3'!D$6,1/'Langkah 1-3'!D$6),1)=0.5,2*ROUND(IF('Langkah 1-3'!D$6>=1,'Langkah 1-3'!D$6,1/'Langkah 1-3'!D$6)/2,0),ROUND(IF('Langkah 1-3'!D$6>=1,'Langkah 1-3'!D$6,1/'Langkah 1-3'!D$6),0)))),$X$4:$AA$12,2,FALSE),1/VLOOKUP(MAX(1,MIN(9,IF(MOD(IF('Langkah 1-3'!D$6>=1,'Langkah 1-3'!D$6,1/'Langkah 1-3'!D$6),1)=0.5,2*ROUND(IF('Langkah 1-3'!D$6>=1,'Langkah 1-3'!D$6,1/'Langkah 1-3'!D$6)/2,0),ROUND(IF('Langkah 1-3'!D$6>=1,'Langkah 1-3'!D$6,1/'Langkah 1-3'!D$6),0)))),$X$4:$AA$12,4,FALSE)) -> 1 | I7: =IF('Langkah 1-3'!D$6>=1,VLOOKUP(MAX(1,MIN(9,IF(MOD(IF('Langkah 1-3'!D$6>=1,'Langkah 1-3'!D$6,1/'Langkah 1-3'!D$6),1)=0.5,2*ROUND(IF('Langkah 1-3'!D$6>=1,'Langkah 1-3'!D$6,1/'Langkah 1-3'!D$6)/2,0),ROUND(IF('Langkah 1-3'!D$6>=1,'Langkah 1-3'!D$6,1/'Langkah 1-3'!D$6),0)))),$X$4:$AA$12,3,FALSE),1/VLOOKUP(MAX(1,MIN(9,IF(MOD(IF('Langkah 1-3'!D$6>=1,'Langkah 1-3'!D$6,1/'Langkah 1-3'!D$6),1)=0.5,2*ROUND(IF('Langkah 1-3'!D$6>=1,'Langkah 1-3'!D$6,1/'Langkah 1-3'!D$6)/2,0),ROUND(IF('Langkah 1-3'!D$6>=1,'Langkah 1-3'!D$6,1/'Langkah 1-3'!D$6),0)))),$X$4:$AA$12,3,FALSE)) -> 1 | J7: =IF('Langkah 1-3'!D$6>=1,VLOOKUP(MAX(1,MIN(9,IF(MOD(IF('Langkah 1-3'!D$6>=1,'Langkah 1-3'!D$6,1/'Langkah 1-3'!D$6),1)=0.5,2*ROUND(IF('Langkah 1-3'!D$6>=1,'Langkah 1-3'!D$6,1/'Langkah 1-3'!D$6)/2,0),ROUND(IF('Langkah 1-3'!D$6>=1,'Langkah 1-3'!D$6,1/'Langkah 1-3'!D$6),0)))),$X$4:$AA$12,4,FALSE),1/VLOOKUP(MAX(1,MIN(9,IF(MOD(IF('Langkah 1-3'!D$6>=1,'Langkah 1-3'!D$6,1/'Langkah 1-3'!D$6),1)=0.5,2*ROUND(IF('Langkah 1-3'!D$6>=1,'Langkah 1-3'!D$6,1/'Langkah 1-3'!D$6)/2,0),ROUND(IF('Langkah 1-3'!D$6>=1,'Langkah 1-3'!D$6,1/'Langkah 1-3'!D$6),0)))),$X$4:$AA$12,2,FALSE)) -> 1 | K7: =IF('Langkah 1-3'!E$6>=1,VLOOKUP(MAX(1,MIN(9,IF(MOD(IF('Langkah 1-3'!E$6>=1,'Langkah 1-3'!E$6,1/'Langkah 1-3'!E$6),1)=0.5,2*ROUND(IF('Langkah 1-3'!E$6>=1,'Langkah 1-3'!E$6,1/'Langkah 1-3'!E$6)/2,0),ROUND(IF('Langkah 1-3'!E$6>=1,'Langkah 1-3'!E$6,1/'Langkah 1-3'!E$6),0)))),$X$4:$AA$12,2,FALSE),1/VLOOKUP(MAX(1,MIN(9,IF(MOD(IF('Langkah 1-3'!E$6>=1,'Langkah 1-3'!E$6,1/'Langkah 1-3'!E$6),1)=0.5,2*ROUND(IF('Langkah 1-3'!E$6>=1,'Langkah 1-3'!E$6,1/'Langkah 1-3'!E$6)/2,0),ROUND(IF('Langkah 1-3'!E$6>=1,'Langkah 1-3'!E$6,1/'Langkah 1-3'!E$6),0)))),$X$4:$AA$12,4,FALSE)) -> 1.5 | L7: =IF('Langkah 1-3'!E$6>=1,VLOOKUP(MAX(1,MIN(9,IF(MOD(IF('Langkah 1-3'!E$6>=1,'Langkah 1-3'!E$6,1/'Langkah 1-3'!E$6),1)=0.5,2*ROUND(IF('Langkah 1-3'!E$6>=1,'Langkah 1-3'!E$6,1/'Langkah 1-3'!E$6)/2,0),ROUND(IF('Langkah 1-3'!E$6>=1,'Langkah 1-3'!E$6,1/'Langkah 1-3'!E$6),0)))),$X$4:$AA$12,3,FALSE),1/VLOOKUP(MAX(1,MIN(9,IF(MOD(IF('Langkah 1-3'!E$6>=1,'Langkah 1-3'!E$6,1/'Langkah 1-3'!E$6),1)=0.5,2*ROUND(IF('Langkah 1-3'!E$6>=1,'Langkah 1-3'!E$6,1/'Langkah 1-3'!E$6)/2,0),ROUND(IF('Langkah 1-3'!E$6>=1,'Langkah 1-3'!E$6,1/'Langkah 1-3'!E$6),0)))),$X$4:$AA$12,3,FALSE)) -> 2 | M7: =IF('Langkah 1-3'!E$6>=1,VLOOKUP(MAX(1,MIN(9,IF(MOD(IF('Langkah 1-3'!E$6>=1,'Langkah 1-3'!E$6,1/'Langkah 1-3'!E$6),1)=0.5,2*ROUND(IF('Langkah 1-3'!E$6>=1,'Langkah 1-3'!E$6,1/'Langkah 1-3'!E$6)/2,0),ROUND(IF('Langkah 1-3'!E$6>=1,'Langkah 1-3'!E$6,1/'Langkah 1-3'!E$6),0)))),$X$4:$AA$12,4,FALSE),1/VLOOKUP(MAX(1,MIN(9,IF(MOD(IF('Langkah 1-3'!E$6>=1,'Langkah 1-3'!E$6,1/'Langkah 1-3'!E$6),1)=0.5,2*ROUND(IF('Langkah 1-3'!E$6>=1,'Langkah 1-3'!E$6,1/'Langkah 1-3'!E$6)/2,0),ROUND(IF('Langkah 1-3'!E$6>=1,'Langkah 1-3'!E$6,1/'Langkah 1-3'!E$6),0)))),$X$4:$AA$12,2,FALSE)) -> 2.5 | N7: =IF('Langkah 1-3'!F$6>=1,VLOOKUP(MAX(1,MIN(9,IF(MOD(IF('Langkah 1-3'!F$6>=1,'Langkah 1-3'!F$6,1/'Langkah 1-3'!F$6),1)=0.5,2*ROUND(IF('Langkah 1-3'!F$6>=1,'Langkah 1-3'!F$6,1/'Langkah 1-3'!F$6)/2,0),ROUND(IF('Langkah 1-3'!F$6>=1,'Langkah 1-3'!F$6,1/'Langkah 1-3'!F$6),0)))),$X$4:$AA$12,2,FALSE),1/VLOOKUP(MAX(1,MIN(9,IF(MOD(IF('Langkah 1-3'!F$6>=1,'Langkah 1-3'!F$6,1/'Langkah 1-3'!F$6),1)=0.5,2*ROUND(IF('Langkah 1-3'!F$6>=1,'Langkah 1-3'!F$6,1/'Langkah 1-3'!F$6)/2,0),ROUND(IF('Langkah 1-3'!F$6>=1,'Langkah 1-3'!F$6,1/'Langkah 1-3'!F$6),0)))),$X$4:$AA$12,4,FALSE)) -> 0.5 | O7: =IF('Langkah 1-3'!F$6>=1,VLOOKUP(MAX(1,MIN(9,IF(MOD(IF('Langkah 1-3'!F$6>=1,'Langkah 1-3'!F$6,1/'Langkah 1-3'!F$6),1)=0.5,2*ROUND(IF('Langkah 1-3'!F$6>=1,'Langkah 1-3'!F$6,1/'Langkah 1-3'!F$6)/2,0),ROUND(IF('Langkah 1-3'!F$6>=1,'Langkah 1-3'!F$6,1/'Langkah 1-3'!F$6),0)))),$X$4:$AA$12,3,FALSE),1/VLOOKUP(MAX(1,MIN(9,IF(MOD(IF('Langkah 1-3'!F$6>=1,'Langkah 1-3'!F$6,1/'Langkah 1-3'!F$6),1)=0.5,2*ROUND(IF('Langkah 1-3'!F$6>=1,'Langkah 1-3'!F$6,1/'Langkah 1-3'!F$6)/2,0),ROUND(IF('Langkah 1-3'!F$6>=1,'Langkah 1-3'!F$6,1/'Langkah 1-3'!F$6),0)))),$X$4:$AA$12,3,FALSE)) -> 1 | P7: =IF('Langkah 1-3'!F$6>=1,VLOOKUP(MAX(1,MIN(9,IF(MOD(IF('Langkah 1-3'!F$6>=1,'Langkah 1-3'!F$6,1/'Langkah 1-3'!F$6),1)=0.5,2*ROUND(IF('Langkah 1-3'!F$6>=1,'Langkah 1-3'!F$6,1/'Langkah 1-3'!F$6)/2,0),ROUND(IF('Langkah 1-3'!F$6>=1,'Langkah 1-3'!F$6,1/'Langkah 1-3'!F$6),0)))),$X$4:$AA$12,4,FALSE),1/VLOOKUP(MAX(1,MIN(9,IF(MOD(IF('Langkah 1-3'!F$6>=1,'Langkah 1-3'!F$6,1/'Langkah 1-3'!F$6),1)=0.5,2*ROUND(IF('Langkah 1-3'!F$6>=1,'Langkah 1-3'!F$6,1/'Langkah 1-3'!F$6)/2,0),ROUND(IF('Langkah 1-3'!F$6>=1,'Langkah 1-3'!F$6,1/'Langkah 1-3'!F$6),0)))),$X$4:$AA$12,2,FALSE)) -> 1.5 | Q7: =IF('Langkah 1-3'!G$6>=1,VLOOKUP(MAX(1,MIN(9,IF(MOD(IF('Langkah 1-3'!G$6>=1,'Langkah 1-3'!G$6,1/'Langkah 1-3'!G$6),1)=0.5,2*ROUND(IF('Langkah 1-3'!G$6>=1,'Langkah 1-3'!G$6,1/'Langkah 1-3'!G$6)/2,0),ROUND(IF('Langkah 1-3'!G$6>=1,'Langkah 1-3'!G$6,1/'Langkah 1-3'!G$6),0)))),$X$4:$AA$12,2,FALSE),1/VLOOKUP(MAX(1,MIN(9,IF(MOD(IF('Langkah 1-3'!G$6>=1,'Langkah 1-3'!G$6,1/'Langkah 1-3'!G$6),1)=0.5,2*ROUND(IF('Langkah 1-3'!G$6>=1,'Langkah 1-3'!G$6,1/'Langkah 1-3'!G$6)/2,0),ROUND(IF('Langkah 1-3'!G$6>=1,'Langkah 1-3'!G$6,1/'Langkah 1-3'!G$6),0)))),$X$4:$AA$12,4,FALSE)) -> 1 | R7: =IF('Langkah 1-3'!G$6>=1,VLOOKUP(MAX(1,MIN(9,IF(MOD(IF('Langkah 1-3'!G$6>=1,'Langkah 1-3'!G$6,1/'Langkah 1-3'!G$6),1)=0.5,2*ROUND(IF('Langkah 1-3'!G$6>=1,'Langkah 1-3'!G$6,1/'Langkah 1-3'!G$6)/2,0),ROUND(IF('Langkah 1-3'!G$6>=1,'Langkah 1-3'!G$6,1/'Langkah 1-3'!G$6),0)))),$X$4:$AA$12,3,FALSE),1/VLOOKUP(MAX(1,MIN(9,IF(MOD(IF('Langkah 1-3'!G$6>=1,'Langkah 1-3'!G$6,1/'Langkah 1-3'!G$6),1)=0.5,2*ROUND(IF('Langkah 1-3'!G$6>=1,'Langkah 1-3'!G$6,1/'Langkah 1-3'!G$6)/2,0),ROUND(IF('Langkah 1-3'!G$6>=1,'Langkah 1-3'!G$6,1/'Langkah 1-3'!G$6),0)))),$X$4:$AA$12,3,FALSE)) -> 1 | S7: =IF('Langkah 1-3'!G$6>=1,VLOOKUP(MAX(1,MIN(9,IF(MOD(IF('Langkah 1-3'!G$6>=1,'Langkah 1-3'!G$6,1/'Langkah 1-3'!G$6),1)=0.5,2*ROUND(IF('Langkah 1-3'!G$6>=1,'Langkah 1-3'!G$6,1/'Langkah 1-3'!G$6)/2,0),ROUND(IF('Langkah 1-3'!G$6>=1,'Langkah 1-3'!G$6,1/'Langkah 1-3'!G$6),0)))),$X$4:$AA$12,4,FALSE),1/VLOOKUP(MAX(1,MIN(9,IF(MOD(IF('Langkah 1-3'!G$6>=1,'Langkah 1-3'!G$6,1/'Langkah 1-3'!G$6),1)=0.5,2*ROUND(IF('Langkah 1-3'!G$6>=1,'Langkah 1-3'!G$6,1/'Langkah 1-3'!G$6)/2,0),ROUND(IF('Langkah 1-3'!G$6>=1,'Langkah 1-3'!G$6,1/'Langkah 1-3'!G$6),0)))),$X$4:$AA$12,2,FALSE)) -> 1 | X7: 4 | Y7: 1.5 | Z7: 2 | AA7: 2.5
A8: K3 | B8: =IF('Langkah 1-3'!B$7>=1,VLOOKUP(MAX(1,MIN(9,IF(MOD(IF('Langkah 1-3'!B$7>=1,'Langkah 1-3'!B$7,1/'Langkah 1-3'!B$7),1)=0.5,2*ROUND(IF('Langkah 1-3'!B$7>=1,'Langkah 1-3'!B$7,1/'Langkah 1-3'!B$7)/2,0),ROUND(IF('Langkah 1-3'!B$7>=1,'Langkah 1-3'!B$7,1/'Langkah 1-3'!B$7),0)))),$X$4:$AA$12,2,FALSE),1/VLOOKUP(MAX(1,MIN(9,IF(MOD(IF('Langkah 1-3'!B$7>=1,'Langkah 1-3'!B$7,1/'Langkah 1-3'!B$7),1)=0.5,2*ROUND(IF('Langkah 1-3'!B$7>=1,'Langkah 1-3'!B$7,1/'Langkah 1-3'!B$7)/2,0),ROUND(IF('Langkah 1-3'!B$7>=1,'Langkah 1-3'!B$7,1/'Langkah 1-3'!B$7),0)))),$X$4:$AA$12,4,FALSE)) -> 1 | C8: =IF('Langkah 1-3'!B$7>=1,VLOOKUP(MAX(1,MIN(9,IF(MOD(IF('Langkah 1-3'!B$7>=1,'Langkah 1-3'!B$7,1/'Langkah 1-3'!B$7),1)=0.5,2*ROUND(IF('Langkah 1-3'!B$7>=1,'Langkah 1-3'!B$7,1/'Langkah 1-3'!B$7)/2,0),ROUND(IF('Langkah 1-3'!B$7>=1,'Langkah 1-3'!B$7,1/'Langkah 1-3'!B$7),0)))),$X$4:$AA$12,3,FALSE),1/VLOOKUP(MAX(1,MIN(9,IF(MOD(IF('Langkah 1-3'!B$7>=1,'Langkah 1-3'!B$7,1/'Langkah 1-3'!B$7),1)=0.5,2*ROUND(IF('Langkah 1-3'!B$7>=1,'Langkah 1-3'!B$7,1/'Langkah 1-3'!B$7)/2,0),ROUND(IF('Langkah 1-3'!B$7>=1,'Langkah 1-3'!B$7,1/'Langkah 1-3'!B$7),0)))),$X$4:$AA$12,3,FALSE)) -> 1 | D8: =IF('Langkah 1-3'!B$7>=1,VLOOKUP(MAX(1,MIN(9,IF(MOD(IF('Langkah 1-3'!B$7>=1,'Langkah 1-3'!B$7,1/'Langkah 1-3'!B$7),1)=0.5,2*ROUND(IF('Langkah 1-3'!B$7>=1,'Langkah 1-3'!B$7,1/'Langkah 1-3'!B$7)/2,0),ROUND(IF('Langkah 1-3'!B$7>=1,'Langkah 1-3'!B$7,1/'Langkah 1-3'!B$7),0)))),$X$4:$AA$12,4,FALSE),1/VLOOKUP(MAX(1,MIN(9,IF(MOD(IF('Langkah 1-3'!B$7>=1,'Langkah 1-3'!B$7,1/'Langkah 1-3'!B$7),1)=0.5,2*ROUND(IF('Langkah 1-3'!B$7>=1,'Langkah 1-3'!B$7,1/'Langkah 1-3'!B$7)/2,0),ROUND(IF('Langkah 1-3'!B$7>=1,'Langkah 1-3'!B$7,1/'Langkah 1-3'!B$7),0)))),$X$4:$AA$12,2,FALSE)) -> 1 | E8: =IF('Langkah 1-3'!C$7>=1,VLOOKUP(MAX(1,MIN(9,IF(MOD(IF('Langkah 1-3'!C$7>=1,'Langkah 1-3'!C$7,1/'Langkah 1-3'!C$7),1)=0.5,2*ROUND(IF('Langkah 1-3'!C$7>=1,'Langkah 1-3'!C$7,1/'Langkah 1-3'!C$7)/2,0),ROUND(IF('Langkah 1-3'!C$7>=1,'Langkah 1-3'!C$7,1/'Langkah 1-3'!C$7),0)))),$X$4:$AA$12,2,FALSE),1/VLOOKUP(MAX(1,MIN(9,IF(MOD(IF('Langkah 1-3'!C$7>=1,'Langkah 1-3'!C$7,1/'Langkah 1-3'!C$7),1)=0.5,2*ROUND(IF('Langkah 1-3'!C$7>=1,'Langkah 1-3'!C$7,1/'Langkah 1-3'!C$7)/2,0),ROUND(IF('Langkah 1-3'!C$7>=1,'Langkah 1-3'!C$7,1/'Langkah 1-3'!C$7),0)))),$X$4:$AA$12,4,FALSE)) -> 1 | F8: =IF('Langkah 1-3'!C$7>=1,VLOOKUP(MAX(1,MIN(9,IF(MOD(IF('Langkah 1-3'!C$7>=1,'Langkah 1-3'!C$7,1/'Langkah 1-3'!C$7),1)=0.5,2*ROUND(IF('Langkah 1-3'!C$7>=1,'Langkah 1-3'!C$7,1/'Langkah 1-3'!C$7)/2,0),ROUND(IF('Langkah 1-3'!C$7>=1,'Langkah 1-3'!C$7,1/'Langkah 1-3'!C$7),0)))),$X$4:$AA$12,3,FALSE),1/VLOOKUP(MAX(1,MIN(9,IF(MOD(IF('Langkah 1-3'!C$7>=1,'Langkah 1-3'!C$7,1/'Langkah 1-3'!C$7),1)=0.5,2*ROUND(IF('Langkah 1-3'!C$7>=1,'Langkah 1-3'!C$7,1/'Langkah 1-3'!C$7)/2,0),ROUND(IF('Langkah 1-3'!C$7>=1,'Langkah 1-3'!C$7,1/'Langkah 1-3'!C$7),0)))),$X$4:$AA$12,3,FALSE)) -> 1 | G8: =IF('Langkah 1-3'!C$7>=1,VLOOKUP(MAX(1,MIN(9,IF(MOD(IF('Langkah 1-3'!C$7>=1,'Langkah 1-3'!C$7,1/'Langkah 1-3'!C$7),1)=0.5,2*ROUND(IF('Langkah 1-3'!C$7>=1,'Langkah 1-3'!C$7,1/'Langkah 1-3'!C$7)/2,0),ROUND(IF('Langkah 1-3'!C$7>=1,'Langkah 1-3'!C$7,1/'Langkah 1-3'!C$7),0)))),$X$4:$AA$12,4,FALSE),1/VLOOKUP(MAX(1,MIN(9,IF(MOD(IF('Langkah 1-3'!C$7>=1,'Langkah 1-3'!C$7,1/'Langkah 1-3'!C$7),1)=0.5,2*ROUND(IF('Langkah 1-3'!C$7>=1,'Langkah 1-3'!C$7,1/'Langkah 1-3'!C$7)/2,0),ROUND(IF('Langkah 1-3'!C$7>=1,'Langkah 1-3'!C$7,1/'Langkah 1-3'!C$7),0)))),$X$4:$AA$12,2,FALSE)) -> 1 | H8: =IF('Langkah 1-3'!D$7>=1,VLOOKUP(MAX(1,MIN(9,IF(MOD(IF('Langkah 1-3'!D$7>=1,'Langkah 1-3'!D$7,1/'Langkah 1-3'!D$7),1)=0.5,2*ROUND(IF('Langkah 1-3'!D$7>=1,'Langkah 1-3'!D$7,1/'Langkah 1-3'!D$7)/2,0),ROUND(IF('Langkah 1-3'!D$7>=1,'Langkah 1-3'!D$7,1/'Langkah 1-3'!D$7),0)))),$X$4:$AA$12,2,FALSE),1/VLOOKUP(MAX(1,MIN(9,IF(MOD(IF('Langkah 1-3'!D$7>=1,'Langkah 1-3'!D$7,1/'Langkah 1-3'!D$7),1)=0.5,2*ROUND(IF('Langkah 1-3'!D$7>=1,'Langkah 1-3'!D$7,1/'Langkah 1-3'!D$7)/2,0),ROUND(IF('Langkah 1-3'!D$7>=1,'Langkah 1-3'!D$7,1/'Langkah 1-3'!D$7),0)))),$X$4:$AA$12,4,FALSE)) -> 1 | I8: =IF('Langkah 1-3'!D$7>=1,VLOOKUP(MAX(1,MIN(9,IF(MOD(IF('Langkah 1-3'!D$7>=1,'Langkah 1-3'!D$7,1/'Langkah 1-3'!D$7),1)=0.5,2*ROUND(IF('Langkah 1-3'!D$7>=1,'Langkah 1-3'!D$7,1/'Langkah 1-3'!D$7)/2,0),ROUND(IF('Langkah 1-3'!D$7>=1,'Langkah 1-3'!D$7,1/'Langkah 1-3'!D$7),0)))),$X$4:$AA$12,3,FALSE),1/VLOOKUP(MAX(1,MIN(9,IF(MOD(IF('Langkah 1-3'!D$7>=1,'Langkah 1-3'!D$7,1/'Langkah 1-3'!D$7),1)=0.5,2*ROUND(IF('Langkah 1-3'!D$7>=1,'Langkah 1-3'!D$7,1/'Langkah 1-3'!D$7)/2,0),ROUND(IF('Langkah 1-3'!D$7>=1,'Langkah 1-3'!D$7,1/'Langkah 1-3'!D$7),0)))),$X$4:$AA$12,3,FALSE)) -> 1 | J8: =IF('Langkah 1-3'!D$7>=1,VLOOKUP(MAX(1,MIN(9,IF(MOD(IF('Langkah 1-3'!D$7>=1,'Langkah 1-3'!D$7,1/'Langkah 1-3'!D$7),1)=0.5,2*ROUND(IF('Langkah 1-3'!D$7>=1,'Langkah 1-3'!D$7,1/'Langkah 1-3'!D$7)/2,0),ROUND(IF('Langkah 1-3'!D$7>=1,'Langkah 1-3'!D$7,1/'Langkah 1-3'!D$7),0)))),$X$4:$AA$12,4,FALSE),1/VLOOKUP(MAX(1,MIN(9,IF(MOD(IF('Langkah 1-3'!D$7>=1,'Langkah 1-3'!D$7,1/'Langkah 1-3'!D$7),1)=0.5,2*ROUND(IF('Langkah 1-3'!D$7>=1,'Langkah 1-3'!D$7,1/'Langkah 1-3'!D$7)/2,0),ROUND(IF('Langkah 1-3'!D$7>=1,'Langkah 1-3'!D$7,1/'Langkah 1-3'!D$7),0)))),$X$4:$AA$12,2,FALSE)) -> 1 | K8: =IF('Langkah 1-3'!E$7>=1,VLOOKUP(MAX(1,MIN(9,IF(MOD(IF('Langkah 1-3'!E$7>=1,'Langkah 1-3'!E$7,1/'Langkah 1-3'!E$7),1)=0.5,2*ROUND(IF('Langkah 1-3'!E$7>=1,'Langkah 1-3'!E$7,1/'Langkah 1-3'!E$7)/2,0),ROUND(IF('Langkah 1-3'!E$7>=1,'Langkah 1-3'!E$7,1/'Langkah 1-3'!E$7),0)))),$X$4:$AA$12,2,FALSE),1/VLOOKUP(MAX(1,MIN(9,IF(MOD(IF('Langkah 1-3'!E$7>=1,'Langkah 1-3'!E$7,1/'Langkah 1-3'!E$7),1)=0.5,2*ROUND(IF('Langkah 1-3'!E$7>=1,'Langkah 1-3'!E$7,1/'Langkah 1-3'!E$7)/2,0),ROUND(IF('Langkah 1-3'!E$7>=1,'Langkah 1-3'!E$7,1/'Langkah 1-3'!E$7),0)))),$X$4:$AA$12,4,FALSE)) -> 1.5 | L8: =IF('Langkah 1-3'!E$7>=1,VLOOKUP(MAX(1,MIN(9,IF(MOD(IF('Langkah 1-3'!E$7>=1,'Langkah 1-3'!E$7,1/'Langkah 1-3'!E$7),1)=0.5,2*ROUND(IF('Langkah 1-3'!E$7>=1,'Langkah 1-3'!E$7,1/'Langkah 1-3'!E$7)/2,0),ROUND(IF('Langkah 1-3'!E$7>=1,'Langkah 1-3'!E$7,1/'Langkah 1-3'!E$7),0)))),$X$4:$AA$12,3,FALSE),1/VLOOKUP(MAX(1,MIN(9,IF(MOD(IF('Langkah 1-3'!E$7>=1,'Langkah 1-3'!E$7,1/'Langkah 1-3'!E$7),1)=0.5,2*ROUND(IF('Langkah 1-3'!E$7>=1,'Langkah 1-3'!E$7,1/'Langkah 1-3'!E$7)/2,0),ROUND(IF('Langkah 1-3'!E$7>=1,'Langkah 1-3'!E$7,1/'Langkah 1-3'!E$7),0)))),$X$4:$AA$12,3,FALSE)) -> 2 | M8: =IF('Langkah 1-3'!E$7>=1,VLOOKUP(MAX(1,MIN(9,IF(MOD(IF('Langkah 1-3'!E$7>=1,'Langkah 1-3'!E$7,1/'Langkah 1-3'!E$7),1)=0.5,2*ROUND(IF('Langkah 1-3'!E$7>=1,'Langkah 1-3'!E$7,1/'Langkah 1-3'!E$7)/2,0),ROUND(IF('Langkah 1-3'!E$7>=1,'Langkah 1-3'!E$7,1/'Langkah 1-3'!E$7),0)))),$X$4:$AA$12,4,FALSE),1/VLOOKUP(MAX(1,MIN(9,IF(MOD(IF('Langkah 1-3'!E$7>=1,'Langkah 1-3'!E$7,1/'Langkah 1-3'!E$7),1)=0.5,2*ROUND(IF('Langkah 1-3'!E$7>=1,'Langkah 1-3'!E$7,1/'Langkah 1-3'!E$7)/2,0),ROUND(IF('Langkah 1-3'!E$7>=1,'Langkah 1-3'!E$7,1/'Langkah 1-3'!E$7),0)))),$X$4:$AA$12,2,FALSE)) -> 2.5 | N8: =IF('Langkah 1-3'!F$7>=1,VLOOKUP(MAX(1,MIN(9,IF(MOD(IF('Langkah 1-3'!F$7>=1,'Langkah 1-3'!F$7,1/'Langkah 1-3'!F$7),1)=0.5,2*ROUND(IF('Langkah 1-3'!F$7>=1,'Langkah 1-3'!F$7,1/'Langkah 1-3'!F$7)/2,0),ROUND(IF('Langkah 1-3'!F$7>=1,'Langkah 1-3'!F$7,1/'Langkah 1-3'!F$7),0)))),$X$4:$AA$12,2,FALSE),1/VLOOKUP(MAX(1,MIN(9,IF(MOD(IF('Langkah 1-3'!F$7>=1,'Langkah 1-3'!F$7,1/'Langkah 1-3'!F$7),1)=0.5,2*ROUND(IF('Langkah 1-3'!F$7>=1,'Langkah 1-3'!F$7,1/'Langkah 1-3'!F$7)/2,0),ROUND(IF('Langkah 1-3'!F$7>=1,'Langkah 1-3'!F$7,1/'Langkah 1-3'!F$7),0)))),$X$4:$AA$12,4,FALSE)) -> 0.5 | O8: =IF('Langkah 1-3'!F$7>=1,VLOOKUP(MAX(1,MIN(9,IF(MOD(IF('Langkah 1-3'!F$7>=1,'Langkah 1-3'!F$7,1/'Langkah 1-3'!F$7),1)=0.5,2*ROUND(IF('Langkah 1-3'!F$7>=1,'Langkah 1-3'!F$7,1/'Langkah 1-3'!F$7)/2,0),ROUND(IF('Langkah 1-3'!F$7>=1,'Langkah 1-3'!F$7,1/'Langkah 1-3'!F$7),0)))),$X$4:$AA$12,3,FALSE),1/VLOOKUP(MAX(1,MIN(9,IF(MOD(IF('Langkah 1-3'!F$7>=1,'Langkah 1-3'!F$7,1/'Langkah 1-3'!F$7),1)=0.5,2*ROUND(IF('Langkah 1-3'!F$7>=1,'Langkah 1-3'!F$7,1/'Langkah 1-3'!F$7)/2,0),ROUND(IF('Langkah 1-3'!F$7>=1,'Langkah 1-3'!F$7,1/'Langkah 1-3'!F$7),0)))),$X$4:$AA$12,3,FALSE)) -> 1 | P8: =IF('Langkah 1-3'!F$7>=1,VLOOKUP(MAX(1,MIN(9,IF(MOD(IF('Langkah 1-3'!F$7>=1,'Langkah 1-3'!F$7,1/'Langkah 1-3'!F$7),1)=0.5,2*ROUND(IF('Langkah 1-3'!F$7>=1,'Langkah 1-3'!F$7,1/'Langkah 1-3'!F$7)/2,0),ROUND(IF('Langkah 1-3'!F$7>=1,'Langkah 1-3'!F$7,1/'Langkah 1-3'!F$7),0)))),$X$4:$AA$12,4,FALSE),1/VLOOKUP(MAX(1,MIN(9,IF(MOD(IF('Langkah 1-3'!F$7>=1,'Langkah 1-3'!F$7,1/'Langkah 1-3'!F$7),1)=0.5,2*ROUND(IF('Langkah 1-3'!F$7>=1,'Langkah 1-3'!F$7,1/'Langkah 1-3'!F$7)/2,0),ROUND(IF('Langkah 1-3'!F$7>=1,'Langkah 1-3'!F$7,1/'Langkah 1-3'!F$7),0)))),$X$4:$AA$12,2,FALSE)) -> 1.5 | Q8: =IF('Langkah 1-3'!G$7>=1,VLOOKUP(MAX(1,MIN(9,IF(MOD(IF('Langkah 1-3'!G$7>=1,'Langkah 1-3'!G$7,1/'Langkah 1-3'!G$7),1)=0.5,2*ROUND(IF('Langkah 1-3'!G$7>=1,'Langkah 1-3'!G$7,1/'Langkah 1-3'!G$7)/2,0),ROUND(IF('Langkah 1-3'!G$7>=1,'Langkah 1-3'!G$7,1/'Langkah 1-3'!G$7),0)))),$X$4:$AA$12,2,FALSE),1/VLOOKUP(MAX(1,MIN(9,IF(MOD(IF('Langkah 1-3'!G$7>=1,'Langkah 1-3'!G$7,1/'Langkah 1-3'!G$7),1)=0.5,2*ROUND(IF('Langkah 1-3'!G$7>=1,'Langkah 1-3'!G$7,1/'Langkah 1-3'!G$7)/2,0),ROUND(IF('Langkah 1-3'!G$7>=1,'Langkah 1-3'!G$7,1/'Langkah 1-3'!G$7),0)))),$X$4:$AA$12,4,FALSE)) -> 1 | R8: =IF('Langkah 1-3'!G$7>=1,VLOOKUP(MAX(1,MIN(9,IF(MOD(IF('Langkah 1-3'!G$7>=1,'Langkah 1-3'!G$7,1/'Langkah 1-3'!G$7),1)=0.5,2*ROUND(IF('Langkah 1-3'!G$7>=1,'Langkah 1-3'!G$7,1/'Langkah 1-3'!G$7)/2,0),ROUND(IF('Langkah 1-3'!G$7>=1,'Langkah 1-3'!G$7,1/'Langkah 1-3'!G$7),0)))),$X$4:$AA$12,3,FALSE),1/VLOOKUP(MAX(1,MIN(9,IF(MOD(IF('Langkah 1-3'!G$7>=1,'Langkah 1-3'!G$7,1/'Langkah 1-3'!G$7),1)=0.5,2*ROUND(IF('Langkah 1-3'!G$7>=1,'Langkah 1-3'!G$7,1/'Langkah 1-3'!G$7)/2,0),ROUND(IF('Langkah 1-3'!G$7>=1,'Langkah 1-3'!G$7,1/'Langkah 1-3'!G$7),0)))),$X$4:$AA$12,3,FALSE)) -> 1 | S8: =IF('Langkah 1-3'!G$7>=1,VLOOKUP(MAX(1,MIN(9,IF(MOD(IF('Langkah 1-3'!G$7>=1,'Langkah 1-3'!G$7,1/'Langkah 1-3'!G$7),1)=0.5,2*ROUND(IF('Langkah 1-3'!G$7>=1,'Langkah 1-3'!G$7,1/'Langkah 1-3'!G$7)/2,0),ROUND(IF('Langkah 1-3'!G$7>=1,'Langkah 1-3'!G$7,1/'Langkah 1-3'!G$7),0)))),$X$4:$AA$12,4,FALSE),1/VLOOKUP(MAX(1,MIN(9,IF(MOD(IF('Langkah 1-3'!G$7>=1,'Langkah 1-3'!G$7,1/'Langkah 1-3'!G$7),1)=0.5,2*ROUND(IF('Langkah 1-3'!G$7>=1,'Langkah 1-3'!G$7,1/'Langkah 1-3'!G$7)/2,0),ROUND(IF('Langkah 1-3'!G$7>=1,'Langkah 1-3'!G$7,1/'Langkah 1-3'!G$7),0)))),$X$4:$AA$12,2,FALSE)) -> 1 | X8: 5 | Y8: 2 | Z8: 2.5 | AA8: 3
A9: K4 | B9: =IF('Langkah 1-3'!B$8>=1,VLOOKUP(MAX(1,MIN(9,IF(MOD(IF('Langkah 1-3'!B$8>=1,'Langkah 1-3'!B$8,1/'Langkah 1-3'!B$8),1)=0.5,2*ROUND(IF('Langkah 1-3'!B$8>=1,'Langkah 1-3'!B$8,1/'Langkah 1-3'!B$8)/2,0),ROUND(IF('Langkah 1-3'!B$8>=1,'Langkah 1-3'!B$8,1/'Langkah 1-3'!B$8),0)))),$X$4:$AA$12,2,FALSE),1/VLOOKUP(MAX(1,MIN(9,IF(MOD(IF('Langkah 1-3'!B$8>=1,'Langkah 1-3'!B$8,1/'Langkah 1-3'!B$8),1)=0.5,2*ROUND(IF('Langkah 1-3'!B$8>=1,'Langkah 1-3'!B$8,1/'Langkah 1-3'!B$8)/2,0),ROUND(IF('Langkah 1-3'!B$8>=1,'Langkah 1-3'!B$8,1/'Langkah 1-3'!B$8),0)))),$X$4:$AA$12,4,FALSE)) -> 0.66666667 | C9: =IF('Langkah 1-3'!B$8>=1,VLOOKUP(MAX(1,MIN(9,IF(MOD(IF('Langkah 1-3'!B$8>=1,'Langkah 1-3'!B$8,1/'Langkah 1-3'!B$8),1)=0.5,2*ROUND(IF('Langkah 1-3'!B$8>=1,'Langkah 1-3'!B$8,1/'Langkah 1-3'!B$8)/2,0),ROUND(IF('Langkah 1-3'!B$8>=1,'Langkah 1-3'!B$8,1/'Langkah 1-3'!B$8),0)))),$X$4:$AA$12,3,FALSE),1/VLOOKUP(MAX(1,MIN(9,IF(MOD(IF('Langkah 1-3'!B$8>=1,'Langkah 1-3'!B$8,1/'Langkah 1-3'!B$8),1)=0.5,2*ROUND(IF('Langkah 1-3'!B$8>=1,'Langkah 1-3'!B$8,1/'Langkah 1-3'!B$8)/2,0),ROUND(IF('Langkah 1-3'!B$8>=1,'Langkah 1-3'!B$8,1/'Langkah 1-3'!B$8),0)))),$X$4:$AA$12,3,FALSE)) -> 1 | D9: =IF('Langkah 1-3'!B$8>=1,VLOOKUP(MAX(1,MIN(9,IF(MOD(IF('Langkah 1-3'!B$8>=1,'Langkah 1-3'!B$8,1/'Langkah 1-3'!B$8),1)=0.5,2*ROUND(IF('Langkah 1-3'!B$8>=1,'Langkah 1-3'!B$8,1/'Langkah 1-3'!B$8)/2,0),ROUND(IF('Langkah 1-3'!B$8>=1,'Langkah 1-3'!B$8,1/'Langkah 1-3'!B$8),0)))),$X$4:$AA$12,4,FALSE),1/VLOOKUP(MAX(1,MIN(9,IF(MOD(IF('Langkah 1-3'!B$8>=1,'Langkah 1-3'!B$8,1/'Langkah 1-3'!B$8),1)=0.5,2*ROUND(IF('Langkah 1-3'!B$8>=1,'Langkah 1-3'!B$8,1/'Langkah 1-3'!B$8)/2,0),ROUND(IF('Langkah 1-3'!B$8>=1,'Langkah 1-3'!B$8,1/'Langkah 1-3'!B$8),0)))),$X$4:$AA$12,2,FALSE)) -> 2 | E9: =IF('Langkah 1-3'!C$8>=1,VLOOKUP(MAX(1,MIN(9,IF(MOD(IF('Langkah 1-3'!C$8>=1,'Langkah 1-3'!C$8,1/'Langkah 1-3'!C$8),1)=0.5,2*ROUND(IF('Langkah 1-3'!C$8>=1,'Langkah 1-3'!C$8,1/'Langkah 1-3'!C$8)/2,0),ROUND(IF('Langkah 1-3'!C$8>=1,'Langkah 1-3'!C$8,1/'Langkah 1-3'!C$8),0)))),$X$4:$AA$12,2,FALSE),1/VLOOKUP(MAX(1,MIN(9,IF(MOD(IF('Langkah 1-3'!C$8>=1,'Langkah 1-3'!C$8,1/'Langkah 1-3'!C$8),1)=0.5,2*ROUND(IF('Langkah 1-3'!C$8>=1,'Langkah 1-3'!C$8,1/'Langkah 1-3'!C$8)/2,0),ROUND(IF('Langkah 1-3'!C$8>=1,'Langkah 1-3'!C$8,1/'Langkah 1-3'!C$8),0)))),$X$4:$AA$12,4,FALSE)) -> 0.4 | F9: =IF('Langkah 1-3'!C$8>=1,VLOOKUP(MAX(1,MIN(9,IF(MOD(IF('Langkah 1-3'!C$8>=1,'Langkah 1-3'!C$8,1/'Langkah 1-3'!C$8),1)=0.5,2*ROUND(IF('Langkah 1-3'!C$8>=1,'Langkah 1-3'!C$8,1/'Langkah 1-3'!C$8)/2,0),ROUND(IF('Langkah 1-3'!C$8>=1,'Langkah 1-3'!C$8,1/'Langkah 1-3'!C$8),0)))),$X$4:$AA$12,3,FALSE),1/VLOOKUP(MAX(1,MIN(9,IF(MOD(IF('Langkah 1-3'!C$8>=1,'Langkah 1-3'!C$8,1/'Langkah 1-3'!C$8),1)=0.5,2*ROUND(IF('Langkah 1-3'!C$8>=1,'Langkah 1-3'!C$8,1/'Langkah 1-3'!C$8)/2,0),ROUND(IF('Langkah 1-3'!C$8>=1,'Langkah 1-3'!C$8,1/'Langkah 1-3'!C$8),0)))),$X$4:$AA$12,3,FALSE)) -> 0.5 | G9: =IF('Langkah 1-3'!C$8>=1,VLOOKUP(MAX(1,MIN(9,IF(MOD(IF('Langkah 1-3'!C$8>=1,'Langkah 1-3'!C$8,1/'Langkah 1-3'!C$8),1)=0.5,2*ROUND(IF('Langkah 1-3'!C$8>=1,'Langkah 1-3'!C$8,1/'Langkah 1-3'!C$8)/2,0),ROUND(IF('Langkah 1-3'!C$8>=1,'Langkah 1-3'!C$8,1/'Langkah 1-3'!C$8),0)))),$X$4:$AA$12,4,FALSE),1/VLOOKUP(MAX(1,MIN(9,IF(MOD(IF('Langkah 1-3'!C$8>=1,'Langkah 1-3'!C$8,1/'Langkah 1-3'!C$8),1)=0.5,2*ROUND(IF('Langkah 1-3'!C$8>=1,'Langkah 1-3'!C$8,1/'Langkah 1-3'!C$8)/2,0),ROUND(IF('Langkah 1-3'!C$8>=1,'Langkah 1-3'!C$8,1/'Langkah 1-3'!C$8),0)))),$X$4:$AA$12,2,FALSE)) -> 0.66666667 | H9: =IF('Langkah 1-3'!D$8>=1,VLOOKUP(MAX(1,MIN(9,IF(MOD(IF('Langkah 1-3'!D$8>=1,'Langkah 1-3'!D$8,1/'Langkah 1-3'!D$8),1)=0.5,2*ROUND(IF('Langkah 1-3'!D$8>=1,'Langkah 1-3'!D$8,1/'Langkah 1-3'!D$8)/2,0),ROUND(IF('Langkah 1-3'!D$8>=1,'Langkah 1-3'!D$8,1/'Langkah 1-3'!D$8),0)))),$X$4:$AA$12,2,FALSE),1/VLOOKUP(MAX(1,MIN(9,IF(MOD(IF('Langkah 1-3'!D$8>=1,'Langkah 1-3'!D$8,1/'Langkah 1-3'!D$8),1)=0.5,2*ROUND(IF('Langkah 1-3'!D$8>=1,'Langkah 1-3'!D$8,1/'Langkah 1-3'!D$8)/2,0),ROUND(IF('Langkah 1-3'!D$8>=1,'Langkah 1-3'!D$8,1/'Langkah 1-3'!D$8),0)))),$X$4:$AA$12,4,FALSE)) -> 0.4 | I9: =IF('Langkah 1-3'!D$8>=1,VLOOKUP(MAX(1,MIN(9,IF(MOD(IF('Langkah 1-3'!D$8>=1,'Langkah 1-3'!D$8,1/'Langkah 1-3'!D$8),1)=0.5,2*ROUND(IF('Langkah 1-3'!D$8>=1,'Langkah 1-3'!D$8,1/'Langkah 1-3'!D$8)/2,0),ROUND(IF('Langkah 1-3'!D$8>=1,'Langkah 1-3'!D$8,1/'Langkah 1-3'!D$8),0)))),$X$4:$AA$12,3,FALSE),1/VLOOKUP(MAX(1,MIN(9,IF(MOD(IF('Langkah 1-3'!D$8>=1,'Langkah 1-3'!D$8,1/'Langkah 1-3'!D$8),1)=0.5,2*ROUND(IF('Langkah 1-3'!D$8>=1,'Langkah 1-3'!D$8,1/'Langkah 1-3'!D$8)/2,0),ROUND(IF('Langkah 1-3'!D$8>=1,'Langkah 1-3'!D$8,1/'Langkah 1-3'!D$8),0)))),$X$4:$AA$12,3,FALSE)) -> 0.5 | J9: =IF('Langkah 1-3'!D$8>=1,VLOOKUP(MAX(1,MIN(9,IF(MOD(IF('Langkah 1-3'!D$8>=1,'Langkah 1-3'!D$8,1/'Langkah 1-3'!D$8),1)=0.5,2*ROUND(IF('Langkah 1-3'!D$8>=1,'Langkah 1-3'!D$8,1/'Langkah 1-3'!D$8)/2,0),ROUND(IF('Langkah 1-3'!D$8>=1,'Langkah 1-3'!D$8,1/'Langkah 1-3'!D$8),0)))),$X$4:$AA$12,4,FALSE),1/VLOOKUP(MAX(1,MIN(9,IF(MOD(IF('Langkah 1-3'!D$8>=1,'Langkah 1-3'!D$8,1/'Langkah 1-3'!D$8),1)=0.5,2*ROUND(IF('Langkah 1-3'!D$8>=1,'Langkah 1-3'!D$8,1/'Langkah 1-3'!D$8)/2,0),ROUND(IF('Langkah 1-3'!D$8>=1,'Langkah 1-3'!D$8,1/'Langkah 1-3'!D$8),0)))),$X$4:$AA$12,2,FALSE)) -> 0.66666667 | K9: =IF('Langkah 1-3'!E$8>=1,VLOOKUP(MAX(1,MIN(9,IF(MOD(IF('Langkah 1-3'!E$8>=1,'Langkah 1-3'!E$8,1/'Langkah 1-3'!E$8),1)=0.5,2*ROUND(IF('Langkah 1-3'!E$8>=1,'Langkah 1-3'!E$8,1/'Langkah 1-3'!E$8)/2,0),ROUND(IF('Langkah 1-3'!E$8>=1,'Langkah 1-3'!E$8,1/'Langkah 1-3'!E$8),0)))),$X$4:$AA$12,2,FALSE),1/VLOOKUP(MAX(1,MIN(9,IF(MOD(IF('Langkah 1-3'!E$8>=1,'Langkah 1-3'!E$8,1/'Langkah 1-3'!E$8),1)=0.5,2*ROUND(IF('Langkah 1-3'!E$8>=1,'Langkah 1-3'!E$8,1/'Langkah 1-3'!E$8)/2,0),ROUND(IF('Langkah 1-3'!E$8>=1,'Langkah 1-3'!E$8,1/'Langkah 1-3'!E$8),0)))),$X$4:$AA$12,4,FALSE)) -> 1 | L9: =IF('Langkah 1-3'!E$8>=1,VLOOKUP(MAX(1,MIN(9,IF(MOD(IF('Langkah 1-3'!E$8>=1,'Langkah 1-3'!E$8,1/'Langkah 1-3'!E$8),1)=0.5,2*ROUND(IF('Langkah 1-3'!E$8>=1,'Langkah 1-3'!E$8,1/'Langkah 1-3'!E$8)/2,0),ROUND(IF('Langkah 1-3'!E$8>=1,'Langkah 1-3'!E$8,1/'Langkah 1-3'!E$8),0)))),$X$4:$AA$12,3,FALSE),1/VLOOKUP(MAX(1,MIN(9,IF(MOD(IF('Langkah 1-3'!E$8>=1,'Langkah 1-3'!E$8,1/'Langkah 1-3'!E$8),1)=0.5,2*ROUND(IF('Langkah 1-3'!E$8>=1,'Langkah 1-3'!E$8,1/'Langkah 1-3'!E$8)/2,0),ROUND(IF('Langkah 1-3'!E$8>=1,'Langkah 1-3'!E$8,1/'Langkah 1-3'!E$8),0)))),$X$4:$AA$12,3,FALSE)) -> 1 | M9: =IF('Langkah 1-3'!E$8>=1,VLOOKUP(MAX(1,MIN(9,IF(MOD(IF('Langkah 1-3'!E$8>=1,'Langkah 1-3'!E$8,1/'Langkah 1-3'!E$8),1)=0.5,2*ROUND(IF('Langkah 1-3'!E$8>=1,'Langkah 1-3'!E$8,1/'Langkah 1-3'!E$8)/2,0),ROUND(IF('Langkah 1-3'!E$8>=1,'Langkah 1-3'!E$8,1/'Langkah 1-3'!E$8),0)))),$X$4:$AA$12,4,FALSE),1/VLOOKUP(MAX(1,MIN(9,IF(MOD(IF('Langkah 1-3'!E$8>=1,'Langkah 1-3'!E$8,1/'Langkah 1-3'!E$8),1)=0.5,2*ROUND(IF('Langkah 1-3'!E$8>=1,'Langkah 1-3'!E$8,1/'Langkah 1-3'!E$8)/2,0),ROUND(IF('Langkah 1-3'!E$8>=1,'Langkah 1-3'!E$8,1/'Langkah 1-3'!E$8),0)))),$X$4:$AA$12,2,FALSE)) -> 1 | N9: =IF('Langkah 1-3'!F$8>=1,VLOOKUP(MAX(1,MIN(9,IF(MOD(IF('Langkah 1-3'!F$8>=1,'Langkah 1-3'!F$8,1/'Langkah 1-3'!F$8),1)=0.5,2*ROUND(IF('Langkah 1-3'!F$8>=1,'Langkah 1-3'!F$8,1/'Langkah 1-3'!F$8)/2,0),ROUND(IF('Langkah 1-3'!F$8>=1,'Langkah 1-3'!F$8,1/'Langkah 1-3'!F$8),0)))),$X$4:$AA$12,2,FALSE),1/VLOOKUP(MAX(1,MIN(9,IF(MOD(IF('Langkah 1-3'!F$8>=1,'Langkah 1-3'!F$8,1/'Langkah 1-3'!F$8),1)=0.5,2*ROUND(IF('Langkah 1-3'!F$8>=1,'Langkah 1-3'!F$8,1/'Langkah 1-3'!F$8)/2,0),ROUND(IF('Langkah 1-3'!F$8>=1,'Langkah 1-3'!F$8,1/'Langkah 1-3'!F$8),0)))),$X$4:$AA$12,4,FALSE)) -> 0.66666667 | O9: =IF('Langkah 1-3'!F$8>=1,VLOOKUP(MAX(1,MIN(9,IF(MOD(IF('Langkah 1-3'!F$8>=1,'Langkah 1-3'!F$8,1/'Langkah 1-3'!F$8),1)=0.5,2*ROUND(IF('Langkah 1-3'!F$8>=1,'Langkah 1-3'!F$8,1/'Langkah 1-3'!F$8)/2,0),ROUND(IF('Langkah 1-3'!F$8>=1,'Langkah 1-3'!F$8,1/'Langkah 1-3'!F$8),0)))),$X$4:$AA$12,3,FALSE),1/VLOOKUP(MAX(1,MIN(9,IF(MOD(IF('Langkah 1-3'!F$8>=1,'Langkah 1-3'!F$8,1/'Langkah 1-3'!F$8),1)=0.5,2*ROUND(IF('Langkah 1-3'!F$8>=1,'Langkah 1-3'!F$8,1/'Langkah 1-3'!F$8)/2,0),ROUND(IF('Langkah 1-3'!F$8>=1,'Langkah 1-3'!F$8,1/'Langkah 1-3'!F$8),0)))),$X$4:$AA$12,3,FALSE)) -> 1 | P9: =IF('Langkah 1-3'!F$8>=1,VLOOKUP(MAX(1,MIN(9,IF(MOD(IF('Langkah 1-3'!F$8>=1,'Langkah 1-3'!F$8,1/'Langkah 1-3'!F$8),1)=0.5,2*ROUND(IF('Langkah 1-3'!F$8>=1,'Langkah 1-3'!F$8,1/'Langkah 1-3'!F$8)/2,0),ROUND(IF('Langkah 1-3'!F$8>=1,'Langkah 1-3'!F$8,1/'Langkah 1-3'!F$8),0)))),$X$4:$AA$12,4,FALSE),1/VLOOKUP(MAX(1,MIN(9,IF(MOD(IF('Langkah 1-3'!F$8>=1,'Langkah 1-3'!F$8,1/'Langkah 1-3'!F$8),1)=0.5,2*ROUND(IF('Langkah 1-3'!F$8>=1,'Langkah 1-3'!F$8,1/'Langkah 1-3'!F$8)/2,0),ROUND(IF('Langkah 1-3'!F$8>=1,'Langkah 1-3'!F$8,1/'Langkah 1-3'!F$8),0)))),$X$4:$AA$12,2,FALSE)) -> 2 | Q9: =IF('Langkah 1-3'!G$8>=1,VLOOKUP(MAX(1,MIN(9,IF(MOD(IF('Langkah 1-3'!G$8>=1,'Langkah 1-3'!G$8,1/'Langkah 1-3'!G$8),1)=0.5,2*ROUND(IF('Langkah 1-3'!G$8>=1,'Langkah 1-3'!G$8,1/'Langkah 1-3'!G$8)/2,0),ROUND(IF('Langkah 1-3'!G$8>=1,'Langkah 1-3'!G$8,1/'Langkah 1-3'!G$8),0)))),$X$4:$AA$12,2,FALSE),1/VLOOKUP(MAX(1,MIN(9,IF(MOD(IF('Langkah 1-3'!G$8>=1,'Langkah 1-3'!G$8,1/'Langkah 1-3'!G$8),1)=0.5,2*ROUND(IF('Langkah 1-3'!G$8>=1,'Langkah 1-3'!G$8,1/'Langkah 1-3'!G$8)/2,0),ROUND(IF('Langkah 1-3'!G$8>=1,'Langkah 1-3'!G$8,1/'Langkah 1-3'!G$8),0)))),$X$4:$AA$12,4,FALSE)) -> 0.4 | R9: =IF('Langkah 1-3'!G$8>=1,VLOOKUP(MAX(1,MIN(9,IF(MOD(IF('Langkah 1-3'!G$8>=1,'Langkah 1-3'!G$8,1/'Langkah 1-3'!G$8),1)=0.5,2*ROUND(IF('Langkah 1-3'!G$8>=1,'Langkah 1-3'!G$8,1/'Langkah 1-3'!G$8)/2,0),ROUND(IF('Langkah 1-3'!G$8>=1,'Langkah 1-3'!G$8,1/'Langkah 1-3'!G$8),0)))),$X$4:$AA$12,3,FALSE),1/VLOOKUP(MAX(1,MIN(9,IF(MOD(IF('Langkah 1-3'!G$8>=1,'Langkah 1-3'!G$8,1/'Langkah 1-3'!G$8),1)=0.5,2*ROUND(IF('Langkah 1-3'!G$8>=1,'Langkah 1-3'!G$8,1/'Langkah 1-3'!G$8)/2,0),ROUND(IF('Langkah 1-3'!G$8>=1,'Langkah 1-3'!G$8,1/'Langkah 1-3'!G$8),0)))),$X$4:$AA$12,3,FALSE)) -> 0.5 | S9: =IF('Langkah 1-3'!G$8>=1,VLOOKUP(MAX(1,MIN(9,IF(MOD(IF('Langkah 1-3'!G$8>=1,'Langkah 1-3'!G$8,1/'Langkah 1-3'!G$8),1)=0.5,2*ROUND(IF('Langkah 1-3'!G$8>=1,'Langkah 1-3'!G$8,1/'Langkah 1-3'!G$8)/2,0),ROUND(IF('Langkah 1-3'!G$8>=1,'Langkah 1-3'!G$8,1/'Langkah 1-3'!G$8),0)))),$X$4:$AA$12,4,FALSE),1/VLOOKUP(MAX(1,MIN(9,IF(MOD(IF('Langkah 1-3'!G$8>=1,'Langkah 1-3'!G$8,1/'Langkah 1-3'!G$8),1)=0.5,2*ROUND(IF('Langkah 1-3'!G$8>=1,'Langkah 1-3'!G$8,1/'Langkah 1-3'!G$8)/2,0),ROUND(IF('Langkah 1-3'!G$8>=1,'Langkah 1-3'!G$8,1/'Langkah 1-3'!G$8),0)))),$X$4:$AA$12,2,FALSE)) -> 0.66666667 | X9: 6 | Y9: 2.5 | Z9: 3 | AA9: 3.5
