Workbook

Sheet Input
A1: FUZZY AHP - 3 PENILAI
A3: BOBOT KRITERIA
A4: Kode | B4: Kriteria | C4: Bobot
A5: K1 | B5: Status Keaktifan | C5: 1
A6: K2 | B6: Pencapaian SKU | C6: 2
A7: K3 | B7: Pencapaian SPG | C7: 2
A8: K4 | B8: Kesehatan Jasmani | C8: 3
A9: K5 | B9: Tes Wawancara | C9: 4
A10: K6 | B10: Tes Pilihan Ganda | C10: 5
A12: PESERTA
A13: No | B13: Nama
A14: 1 | B14: David Kulian
A15: 2 | B15: Siti Aminah
A16: 3 | B16: Budi Santoso
A17: 4 | B17: Dewi Lestari
A18: 5 | B18: Ahmad Fauzi
A19: 6 | B19: Rina Wati
A20: 7 | B20: Joko Susilo
A21: 8 | B21: Maya Sari
A22: 9 | B22: Andi Pratama
A23: 10 | B23: Lina Marlina

Sheet Penilai 1
A1: INPUT PENILAI 1 (K1, K2)
A3: No | B3: Nama | C3: K1 | D3: K2
A4: 1 | B4: ='Input'!B14 | C4: 85 | D4: 78
A5: 2 | B5: ='Input'!B15 | C5: 78 | D5: 82
A6: 3 | B6: ='Input'!B16 | C6: 92 | D6: 88
A7: 4 | B7: ='Input'!B17 | C7: 80 | D7: 85
A8: 5 | B8: ='Input'!B18 | C8: 88 | D8: 90
A9: 6 | B9: ='Input'!B19 | C9: 75 | D9: 80
A10: 7 | B10: ='Input'!B20 | C10: 82 | D10: 78
A11: 8 | B11: ='Input'!B21 | C11: 90 | D11: 85
A12: 9 | B12: ='Input'!B22 | C12: 85 | D12: 82
A13: 10 | B13: ='Input'!B23 | C13: 78 | D13: 80

Sheet Penilai 2
A1: INPUT PENILAI 2 (K3, K4)
A3: No | B3: Nama | C3: K3 | D3: K4
A4: 1 | B4: ='Input'!B14 | C4: 88 | D4: 92
A5: 2 | B5: ='Input'!B15 | C5: 82 | D5: 88
A6: 3 | B6: ='Input'!B16 | C6: 90 | D6: 85
A7: 4 | B7: ='Input'!B17 | C7: 85 | D7: 90
A8: 5 | B8: ='Input'!B18 | C8: 87 | D8: 80
A9: 6 | B9: ='Input'!B19 | C9: 80 | D9: 85
A10: 7 | B10: ='Input'!B20 | C10: 88 | D10: 82
A11: 8 | B11: ='Input'!B21 | C11: 85 | D11: 88
A12: 9 | B12: ='Input'!B22 | C12: 82 | D12: 85
A13: 10 | B13: ='Input'!B23 | C13: 85 | D13: 90

Sheet Penilai 3
A1: INPUT PENILAI 3 (K5, K6)
A3: No | B3: Nama | C3: K5 | D3: K6
A4: 1 | B4: ='Input'!B14 | C4: 87 | D4: 85
A5: 2 | B5: ='Input'!B15 | C5: 80 | D5: 78
A6: 3 | B6: ='Input'!B16 | C6: 88 | D6: 90
A7: 4 | B7: ='Input'!B17 | C7: 82 | D7: 80
A8: 5 | B8: ='Input'!B18 | C8: 90 | D8: 88
A9: 6 | B9: ='Input'!B19 | C9: 85 | D9: 82
A10: 7 | B10: ='Input'!B20 | C10: 80 | D10: 85
A11: 8 | B11: ='Input'!B21 | C11: 88 | D11: 92
A12: 9 | B12: ='Input'!B22 | C12: 85 | D12: 80
A13: 10 | B13: ='Input'!B23 | C13: 82 | D13: 85

Sheet Rekap Nilai
A1: REKAP NILAI DARI 3 PENILAI
A3: No | B3: Nama | C3: K1 | D3: K2 | E3: K3 | F3: K4 | G3: K5 | H3: K6
A4: 1 | B4: ='Input'!B14 | C4: ='Penilai 1'!C4 | D4: ='Penilai 1'!D4 | E4: ='Penilai 2'!C4 | F4: ='Penilai 2'!D4 | G4: ='Penilai 3'!C4 | H4: ='Penilai 3'!D4
A5: 2 | B5: ='Input'!B15 | C5: ='Penilai 1'!C5 | D5: ='Penilai 1'!D5 | E5: ='Penilai 2'!C5 | F5: ='Penilai 2'!D5 | G5: ='Penilai 3'!C5 | H5: ='Penilai 3'!D5
A6: 3 | B6: ='Input'!B16 | C6: ='Penilai 1'!C6 | D6: ='Penilai 1'!D6 | E6: ='Penilai 2'!C6 | F6: ='Penilai 2'!D6 | G6: ='Penilai 3'!C6 | H6: ='Penilai 3'!D6
A7: 4 | B7: ='Input'!B17 | C7: ='Penilai 1'!C7 | D7: ='Penilai 1'!D7 | E7: ='Penilai 2'!C7 | F7: ='Penilai 2'!D7 | G7: ='Penilai 3'!C7 | H7: ='Penilai 3'!D7
A8: 5 | B8: ='Input'!B18 | C8: ='Penilai 1'!C8 | D8: ='Penilai 1'!D8 | E8: ='Penilai 2'!C8 | F8: ='Penilai 2'!D8 | G8: ='Penilai 3'!C8 | H8: ='Penilai 3'!D8
A9: 6 | B9: ='Input'!B19 | C9: ='Penilai 1'!C9 | D9: ='Penilai 1'!D9 | E9: ='Penilai 2'!C9 | F9: ='Penilai 2'!D9 | G9: ='Penilai 3'!C9 | H9: ='Penilai 3'!D9
A10: 7 | B10: ='Input'!B20 | C10: ='Penilai 1'!C10 | D10: ='Penilai 1'!D10 | E10: ='Penilai 2'!C10 | F10: ='Penilai 2'!D10 | G10: ='Penilai 3'!C10 | H10: ='Penilai 3'!D10
A11: 8 | B11: ='Input'!B21 | C11: ='Penilai 1'!C11 | D11: ='Penilai 1'!D11 | E11: ='Penilai 2'!C11 | F11: ='Penilai 2'!D11 | G11: ='Penilai 3'!C11 | H11: ='Penilai 3'!D11
A12: 9 | B12: ='Input'!B22 | C12: ='Penilai 1'!C12 | D12: ='Penilai 1'!D12 | E12: ='Penilai 2'!C12 | F12: ='Penilai 2'!D12 | G12: ='Penilai 3'!C12 | H12: ='Penilai 3'!D12
A13: 10 | B13: ='Input'!B23 | C13: ='Penilai 1'!C13 | D13: ='Penilai 1'!D13 | E13: ='Penilai 2'!C13 | F13: ='Penilai 2'!D13 | G13: ='Penilai 3'!C13 | H13: ='Penilai 3'!D13

Sheet Langkah 1-3
A1: LANGKAH 1-3: MATRIKS CRISP, EIGENVECTOR & UJI KONSISTENSI
A3: LANGKAH 1: MATRIKS PERBANDINGAN BERPASANGAN (CRISP)
B4: K1 | C4: K2 | D4: K3 | E4: K4 | F4: K5 | G4: K6
A5: K1 | B5: 1 | C5: =IF('Input'!$C$5/'Input'!$C$6>=1,MIN(9,MAX(1,'Input'!$C$5/'Input'!$C$6)),MAX(1/9,'Input'!$C$5/'Input'!$C$6)) | D5: =IF('Input'!$C$5/'Input'!$C$7>=1,MIN(9,MAX(1,'Input'!$C$5/'Input'!$C$7)),MAX(1/9,'Input'!$C$5/'Input'!$C$7)) | E5: =IF('Input'!$C$5/'Input'!$C$8>=1,MIN(9,MAX(1,'Input'!$C$5/'Input'!$C$8)),MAX(1/9,'Input'!$C$5/'Input'!$C$8)) | F5: =IF('Input'!$C$5/'Input'!$C$9>=1,MIN(9,MAX(1,'Input'!$C$5/'Input'!$C$9)),MAX(1/9,'Input'!$C$5/'Input'!$C$9)) | G5: =IF('Input'!$C$5/'Input'!$C$10>=1,MIN(9,MAX(1,'Input'!$C$5/'Input'!$C$10)),MAX(1/9,'Input'!$C$5/'Input'!$C$10))
A6: K2 | B6: =IF('Input'!$C$6/'Input'!$C$5>=1,MIN(9,MAX(1,'Input'!$C$6/'Input'!$C$5)),MAX(1/9,'Input'!$C$6/'Input'!$C$5)) | C6: 1 | D6: =IF('Input'!$C$6/'Input'!$C$7>=1,MIN(9,MAX(1,'Input'!$C$6/'Input'!$C$7)),MAX(1/9,'Input'!$C$6/'Input'!$C$7)) | E6: =IF('Input'!$C$6/'Input'!$C$8>=1,MIN(9,MAX(1,'Input'!$C$6/'Input'!$C$8)),MAX(1/9,'Input'!$C$6/'Input'!$C$8)) | F6: =IF('Input'!$C$6/'Input'!$C$9>=1,MIN(9,MAX(1,'Input'!$C$6/'Input'!$C$9)),MAX(1/9,'Input'!$C$6/'Input'!$C$9)) | G6: =IF('Input'!$C$6/'Input'!$C$10>=1,MIN(9,MAX(1,'Input'!$C$6/'Input'!$C$10)),MAX(1/9,'Input'!$C$6/'Input'!$C$10))
A7: K3 | B7: =IF('Input'!$C$7/'Input'!$C$5>=1,MIN(9,MAX(1,'Input'!$C$7/'Input'!$C$5)),MAX(1/9,'Input'!$C$7/'Input'!$C$5)) | C7: =IF('Input'!$C$7/'Input'!$C$6>=1,MIN(9,MAX(1,'Input'!$C$7/'Input'!$C$6)),MAX(1/9,'Input'!$C$7/'Input'!$C$6)) | D7: 1 | E7: =IF('Input'!$C$7/'Input'!$C$8>=1,MIN(9,MAX(1,'Input'!$C$7/'Input'!$C$8)),MAX(1/9,'Input'!$C$7/'Input'!$C$8)) | F7: =IF('Input'!$C$7/'Input'!$C$9>=1,MIN(9,MAX(1,'Input'!$C$7/'Input'!$C$9)),MAX(1/9,'Input'!$C$7/'Input'!$C$9)) | G7: =IF('Input'!$C$7/'Input'!$C$10>=1,MIN(9,MAX(1,'Input'!$C$7/'Input'!$C$10)),MAX(1/9,'Input'!$C$7/'Input'!$C$10))
A8: K4 | B8: =IF('Input'!$C$8/'Input'!$C$5>=1,MIN(9,MAX(1,'Input'!$C$8/'Input'!$C$5)),MAX(1/9,'Input'!$C$8/'Input'!$C$5)) | C8: =IF('Input'!$C$8/'Input'!$C$6>=1,MIN(9,MAX(1,'Input'!$C$8/'Input'!$C$6)),MAX(1/9,'Input'!$C$8/'Input'!$C$6)) | D8: =IF('Input'!$C$8/'Input'!$C$7>=1,MIN(9,MAX(1,'Input'!$C$8/'Input'!$C$7)),MAX(1/9,'Input'!$C$8/'Input'!$C$7)) | E8: 1 | F8: =IF('Input'!$C$8/'Input'!$C$9>=1,MIN(9,MAX(1,'Input'!$C$8/'Input'!$C$9)),MAX(1/9,'Input'!$C$8/'Input'!$C$9)) | G8: =IF('Input'!$C$8/'Input'!$C$10>=1,MIN(9,MAX(1,'Input'!$C$8/'Input'!$C$10)),MAX(1/9,'Input'!$C$8/'Input'!$C$10))
A9: K5 | B9: =IF('Input'!$C$9/'Input'!$C$5>=1,MIN(9,MAX(1,'Input'!$C$9/'Input'!$C$5)),MAX(1/9,'Input'!$C$9/'Input'!$C$5)) | C9: =IF('Input'!$C$9/'Input'!$C$6>=1,MIN(9,MAX(1,'Input'!$C$9/'Input'!$C$6)),MAX(1/9,'Input'!$C$9/'Input'!$C$6)) | D9: =IF('Input'!$C$9/'Input'!$C$7>=1,MIN(9,MAX(1,'Input'!$C$9/'Input'!$C$7)),MAX(1/9,'Input'!$C$9/'Input'!$C$7)) | E9: =IF('Input'!$C$9/'Input'!$C$8>=1,MIN(9,MAX(1,'Input'!$C$9/'Input'!$C$8)),MAX(1/9,'Input'!$C$9/'Input'!$C$8)) | F9: 1 | G9: =IF('Input'!$C$9/'Input'!$C$10>=1,MIN(9,MAX(1,'Input'!$C$9/'Input'!$C$10)),MAX(1/9,'Input'!$C$9/'Input'!$C$10))
A10: K6 | B10: =IF('Input'!$C$10/'Input'!$C$5>=1,MIN(9,MAX(1,'Input'!$C$10/'Input'!$C$5)),MAX(1/9,'Input'!$C$10/'Input'!$C$5)) | C10: =IF('Input'!$C$10/'Input'!$C$6>=1,MIN(9,MAX(1,'Input'!$C$10/'Input'!$C$6)),MAX(1/9,'Input'!$C$10/'Input'!$C$6)) | D10: =IF('Input'!$C$10/'Input'!$C$7>=1,MIN(9,MAX(1,'Input'!$C$10/'Input'!$C$7)),MAX(1/9,'Input'!$C$10/'Input'!$C$7)) | E10: =IF('Input'!$C$10/'Input'!$C$8>=1,MIN(9,MAX(1,'Input'!$C$10/'Input'!$C$8)),MAX(1/9,'Input'!$C$10/'Input'!$C$8)) | F10: =IF('Input'!$C$10/'Input'!$C$9>=1,MIN(9,MAX(1,'Input'!$C$10/'Input'!$C$9)),MAX(1/9,'Input'!$C$10/'Input'!$C$9)) | G10: 1
A12: LANGKAH 2: PERHITUNGAN VECTOR EIGEN (GEOMETRIC MEAN)
A13: Kriteria | B13: Geometric Mean | C13: Eigenvector (Wi)
A14: Status Keaktifan | B14: =(B5*C5*D5*E5*F5*G5)^(1/6) | C14: =B14/$B$20
A15: Pencapaian SKU | B15: =(B6*C6*D6*E6*F6*G6)^(1/6) | C15: =B15/$B$20
A16: Pencapaian SPG | B16: =(B7*C7*D7*E7*F7*G7)^(1/6) | C16: =B16/$B$20
A17: Kesehatan Jasmani | B17: =(B8*C8*D8*E8*F8*G8)^(1/6) | C17: =B17/$B$20
A18: Tes Wawancara | B18: =(B9*C9*D9*E9*F9*G9)^(1/6) | C18: =B18/$B$20
A19: Tes Pilihan Ganda | B19: =(B10*C10*D10*E10*F10*G10)^(1/6) | C19: =B19/$B$20
A20: Total | B20: =SUM(B14:B19) | C20: =SUM(C14:C19)
A22: LANGKAH 3: UJI KONSISTENSI
A23: Kriteria | B23: A*w | C23: (A*w)/w
A24: Status Keaktifan | B24: =B5*$C$14+C5*$C$15+D5*$C$16+E5*$C$17+F5*$C$18+G5*$C$19 | C24: =B24/$C$14
A25: Pencapaian SKU | B25: =B6*$C$14+C6*$C$15+D6*$C$16+E6*$C$17+F6*$C$18+G6*$C$19 | C25: =B25/$C$15
A26: Pencapaian SPG | B26: =B7*$C$14+C7*$C$15+D7*$C$16+E7*$C$17+F7*$C$18+G7*$C$19 | C26: =B26/$C$16
A27: Kesehatan Jasmani | B27: =B8*$C$14+C8*$C$15+D8*$C$16+E8*$C$17+F8*$C$18+G8*$C$19 | C27: =B27/$C$17
A28: Tes Wawancara | B28: =B9*$C$14+C9*$C$15+D9*$C$16+E9*$C$17+F9*$C$18+G9*$C$19 | C28: =B28/$C$18
A29: Tes Pilihan Ganda | B29: =B10*$C$14+C10*$C$15+D10*$C$16+E10*$C$17+F10*$C$18+G10*$C$19 | C29: =B29/$C$19
A31: Lambda Max: | B31: =AVERAGE(C24:C29)
A32: CI: | B32: =(B31-6)/(6-1)
A33: RI (n=6): | B33: 1.24
A34: CR: | B34: =B32/B33
A35: Status: | B35: =IF(B34<=0.1,"KONSISTEN","TIDAK KONSISTEN")

Sheet Langkah 4-6
A1: LANGKAH 4-6: FUZZIFIKASI, SYNTHETIC EXTENT & BOBOT GLOBAL
A3: LANGKAH 4: FUZZIFIKASI MATRIKS PERBANDINGAN BERPASANGAN
B4: K1 | E4: K2 | H4: K3 | K4: K4 | N4: K5 | Q4: K6
B5: l | C5: m | D5: u | E5: l | F5: m | G5: u | H5: l | I5: m | J5: u | K5: l | L5: m | M5: u | N5: l | O5: m | P5: u | Q5: l | R5: m | S5: u
A6: K1 | B6: 1 | C6: 1 | D6: 1 | E6: 0.66666667 | F6: 1 | G6: 2 | H6: 0.66666667 | I6: 1 | J6: 2 | K6: 0.5 | L6: 0.66666667 | M6: 1 | N6: 0.4 | O6: 0.5 | P6: 0.66666667 | Q6: 0.33333333 | R6: 0.4 | S6: 0.5
A7: K2 | B7: 0.5 | C7: 1 | D7: 1.5 | E7: 1 | F7: 1 | G7: 1 | H7: 1 | I7: 1 | J7: 1 | K7: 0.66666667 | L7: 1 | M7: 2 | N7: 0.66666667 | O7: 1 | P7: 2 | Q7: 0.66666667 | R7: 1 | S7: 2
A8: K3 | B8: 0.5 | C8: 1 | D8: 1.5 | E8: 1 | F8: 1 | G8: 1 | H8: 1 | I8: 1 | J8: 1 | K8: 0.66666667 | L8: 1 | M8: 2 | N8: 0.66666667 | O8: 1 | P8: 2 | Q8: 0.66666667 | R8: 1 | S8: 2
A9: K4 | B9: 1 | C9: 1.5 | D9: 2 | E9: 0.5 | F9: 1 | G9: 1.5 | H9: 0.5 | I9: 1 | J9: 1.5 | K9: 1 | L9: 1 | M9: 1 | N9: 1 | O9: 1 | P9: 1 | Q9: 0.66666667 | R9: 1 | S9: 2
A10: K5 | B10: 1.5 | C10: 2 | D10: 2.5 | E10: 0.5 | F10: 1 | G10: 1.5 | H10: 0.5 | I10: 1 | J10: 1.5 | K10: 1 | L10: 1 | M10: 1 | N10: 1 | O10: 1 | P10: 1 | Q10: 1 | R10: 1 | S10: 1
A11: K6 | B11: 2 | C11: 2.5 | D11: 3 | E11: 0.5 | F11: 1 | G11: 1.5 | H11: 0.5 | I11: 1 | J11: 1.5 | K11: 0.5 | L11: 1 | M11: 1.5 | N11: 1 | O11: 1 | P11: 1 | Q11: 1 | R11: 1 | S11: 1
A13: LANGKAH 5: FUZZY SYNTHETIC EXTENT
A14: Penjumlahan Baris Matriks Fuzzy
A15: Kriteria | B15: Σl | C15: Σm | D15: Σu
A16: Status Keaktifan | B16: =B6+E6+H6+K6+N6+Q6 | C16: =C6+F6+I6+L6+O6+R6 | D16: =D6+G6+J6+M6+P6+S6
A17: Pencapaian SKU | B17: =B7+E7+H7+K7+N7+Q7 | C17: =C7+F7+I7+L7+O7+R7 | D17: =D7+G7+J7+M7+P7+S7
A18: Pencapaian SPG | B18: =B8+E8+H8+K8+N8+Q8 | C18: =C8+F8+I8+L8+O8+R8 | D18: =D8+G8+J8+M8+P8+S8
A19: Kesehatan Jasmani | B19: =B9+E9+H9+K9+N9+Q9 | C19: =C9+F9+I9+L9+O9+R9 | D19: =D9+G9+J9+M9+P9+S9
A20: Tes Wawancara | B20: =B10+E10+H10+K10+N10+Q10 | C20: =C10+F10+I10+L10+O10+R10 | D20: =D10+G10+J10+M10+P10+S10
A21: Tes Pilihan Ganda | B21: =B11+E11+H11+K11+N11+Q11 | C21: =C11+F11+I11+L11+O11+R11 | D21: =D11+G11+J11+M11+P11+S11
A22: Total | B22: =SUM(B16:B21) | C22: =SUM(C16:C21) | D22: =SUM(D16:D21)
A24: Fuzzy Synthetic Extent (Si)
A25: Kriteria | B25: Si(l) | C25: Si(m) | D25: Si(u)
A26: Status Keaktifan | B26: =B16/$D$22 | C26: =C16/$C$22 | D26: =D16/$B$22
A27: Pencapaian SKU | B27: =B17/$D$22 | C27: =C17/$C$22 | D27: =D17/$B$22
A28: Pencapaian SPG | B28: =B18/$D$22 | C28: =C18/$C$22 | D28: =D18/$B$22
A29: Kesehatan Jasmani | B29: =B19/$D$22 | C29: =C19/$C$22 | D29: =D19/$B$22
A30: Tes Wawancara | B30: =B20/$D$22 | C30: =C20/$C$22 | D30: =D20/$B$22
A31: Tes Pilihan Ganda | B31: =B21/$D$22 | C31: =C21/$C$22 | D31: =D21/$B$22
A33: LANGKAH 6: PERBANDINGAN PROBABILITAS, NORMALISASI & BOBOT GLOBAL
A34: V(Si>=Sk) = 1 jika mi>=mk | 0 jika lk>=ui | (lk-ui)/((mi-ui)-(mk-lk))
A35: Matriks V(Si >= Sk)
A36: V(Si>=Sk) | B36: K1 | C36: K2 | D36: K3 | E36: K4 | F36: K5 | G36: K6
A37: K1 | B37: - | C37: =IF($C$26>=$C$27,1,IF($B$27>=$D$26,0,($B$27-$D$26)/(($C$26-$D$26)-($C$27-$B$27)))) | D37: =IF($C$26>=$C$28,1,IF($B$28>=$D$26,0,($B$28-$D$26)/(($C$26-$D$26)-($C$28-$B$28)))) | E37: =IF($C$26>=$C$29,1,IF($B$29>=$D$26,0,($B$29-$D$26)/(($C$26-$D$26)-($C$29-$B$29)))) | F37: =IF($C$26>=$C$30,1,IF($B$30>=$D$26,0,($B$30-$D$26)/(($C$26-$D$26)-($C$30-$B$30)))) | G37: =IF($C$26>=$C$31,1,IF($B$31>=$D$26,0,($B$31-$D$26)/(($C$26-$D$26)-($C$31-$B$31))))
A38: K2 | B38: =IF($C$27>=$C$26,1,IF($B$26>=$D$27,0,($B$26-$D$27)/(($C$27-$D$27)-($C$26-$B$26)))) | C38: - | D38: =IF($C$27>=$C$28,1,IF($B$28>=$D$27,0,($B$28-$D$27)/(($C$27-$D$27)-($C$28-$B$28)))) | E38: =IF($C$27>=$C$29,1,IF($B$29>=$D$27,0,($B$29-$D$27)/(($C$27-$D$27)-($C$29-$B$29)))) | F38: =IF($C$27>=$C$30,1,IF($B$30>=$D$27,0,($B$30-$D$27)/(($C$27-$D$27)-($C$30-$B$30)))) | G38: =IF($C$27>=$C$31,1,IF($B$31>=$D$27,0,($B$31-$D$27)/(($C$27-$D$27)-($C$31-$B$31))))
A39: K3 | B39: =IF($C$28>=$C$26,1,IF($B$26>=$D$28,0,($B$26-$D$28)/(($C$28-$D$28)-($C$26-$B$26)))) | C39: =IF($C$28>=$C$27,1,IF($B$27>=$D$28,0,($B$27-$D$28)/(($C$28-$D$28)-($C$27-$B$27)))) | D39: - | E39: =IF($C$28>=$C$29,1,IF($B$29>=$D$28,0,($B$29-$D$28)/(($C$28-$D$28)-($C$29-$B$29)))) | F39: =IF($C$28>=$C$30,1,IF($B$30>=$D$28,0,($B$30-$D$28)/(($C$28-$D$28)-($C$30-$B$30)))) | G39: =IF($C$28>=$C$31,1,IF($B$31>=$D$28,0,($B$31-$D$28)/(($C$28-$D$28)-($C$31-$B$31))))
A40: K4 | B40: =IF($C$29>=$C$26,1,IF($B$26>=$D$29,0,($B$26-$D$29)/(($C$29-$D$29)-($C$26-$B$26)))) | C40: =IF($C$29>=$C$27,1,IF($B$27>=$D$29,0,($B$27-$D$29)/(($C$29-$D$29)-($C$27-$B$27)))) | D40: =IF($C$29>=$C$28,1,IF($B$28>=$D$29,0,($B$28-$D$29)/(($C$29-$D$29)-($C$28-$B$28)))) | E40: - | F40: =IF($C$29>=$C$30,1,IF($B$30>=$D$29,0,($B$30-$D$29)/(($C$29-$D$29)-($C$30-$B$30)))) | G40: =IF($C$29>=$C$31,1,IF($B$31>=$D$29,0,($B$31-$D$29)/(($C$29-$D$29)-($C$31-$B$31))))
A41: K5 | B41: =IF($C$30>=$C$26,1,IF($B$26>=$D$30,0,($B$26-$D$30)/(($C$30-$D$30)-($C$26-$B$26)))) | C41: =IF($C$30>=$C$27,1,IF($B$27>=$D$30,0,($B$27-$D$30)/(($C$30-$D$30)-($C$27-$B$27)))) | D41: =IF($C$30>=$C$28,1,IF($B$28>=$D$30,0,($B$28-$D$30)/(($C$30-$D$30)-($C$28-$B$28)))) | E41: =IF($C$30>=$C$29,1,IF($B$29>=$D$30,0,($B$29-$D$30)/(($C$30-$D$30)-($C$29-$B$29)))) | F41: - | G41: =IF($C$30>=$C$31,1,IF($B$31>=$D$30,0,($B$31-$D$30)/(($C$30-$D$30)-($C$31-$B$31))))
A42: K6 | B42: =IF($C$31>=$C$26,1,IF($B$26>=$D$31,0,($B$26-$D$31)/(($C$31-$D$31)-($C$26-$B$26)))) | C42: =IF($C$31>=$C$27,1,IF($B$27>=$D$31,0,($B$27-$D$31)/(($C$31-$D$31)-($C$27-$B$27)))) | D42: =IF($C$31>=$C$28,1,IF($B$28>=$D$31,0,($B$28-$D$31)/(($C$31-$D$31)-($C$28-$B$28)))) | E42: =IF($C$31>=$C$29,1,IF($B$29>=$D$31,0,($B$29-$D$31)/(($C$31-$D$31)-($C$29-$B$29)))) | F42: =IF($C$31>=$C$30,1,IF($B$30>=$D$31,0,($B$30-$D$31)/(($C$31-$D$31)-($C$30-$B$30)))) | G42: -
A44: Nilai Ordinat d'(Ai) = min V(Si >= Sk)
A45: Kriteria | B45: d'(Ai)
...

Sheet Hasil & Ranking
A1: SKOR AKHIR (DEFUZZIFIKASI)
A2: Skor = (ΣL×w + ΣM×w + ΣU×w) / 3
A3: Bobot = bobot_db / total_bobot. Fuzzy: nilai<=5 → Likert TFN, nilai>5 → (nilai-5, nilai, nilai+5)
A5: BOBOT (bobot/total)
A6: K1 | B6: K2 | C6: K3 | D6: K4 | E6: K5 | F6: K6
A7: ='Input'!$C$5/SUM('Input'!$C$5:'Input'!$C$10) | B7: ='Input'!$C$6/SUM('Input'!$C$5:'Input'!$C$10) | C7: ='Input'!$C$7/SUM('Input'!$C$5:'Input'!$C$10) | D7: ='Input'!$C$8/SUM('Input'!$C$5:'Input'!$C$10) | E7: ='Input'!$C$9/SUM('Input'!$C$5:'Input'!$C$10) | F7: ='Input'!$C$10/SUM('Input'!$C$5:'Input'!$C$10)
A9: PERHITUNGAN SKOR
A10: No | B10: Nama | C10: ΣL×w | D10: ΣM×w | E10: ΣU×w | F10: Skor | G10: Rank
A11: 1 | B11: ='Input'!B14 | C11: =IF('Rekap Nilai'!C4<=5,IF('Rekap Nilai'!C4<=1,1,IF('Rekap Nilai'!C4<=2,1,IF('Rekap Nilai'!C4<=3,2,IF('Rekap Nilai'!C4<=4,3,4)))),MAX(0,'Rekap Nilai'!C4-5))*$A$7+IF('Rekap Nilai'!D4<=5,IF('Rekap Nilai'!D4<=1,1,IF('Rekap Nilai'!D4<=2,1,IF('Rekap Nilai'!D4<=3,2,IF('Rekap Nilai'!D4<=4,3,4)))),MAX(0,'Rekap Nilai'!D4-5))*$B$7+IF('Rekap Nilai'!E4<=5,IF('Rekap Nilai'!E4<=1,1,IF('Rekap Nilai'!E4<=2,1,IF('Rekap Nilai'!E4<=3,2,IF('Rekap Nilai'!E4<=4,3,4)))),MAX(0,'Rekap Nilai'!E4-5))*$C$7+IF('Rekap Nilai'!F4<=5,IF('Rekap Nilai'!F4<=1,1,IF('Rekap Nilai'!F4<=2,1,IF('Rekap Nilai'!F4<=3,2,IF('Rekap Nilai'!F4<=4,3,4)))),MAX(0,'Rekap Nilai'!F4-5))*$D$7+IF('Rekap Nilai'!G4<=5,IF('Rekap Nilai'!G4<=1,1,IF('Rekap Nilai'!G4<=2,1,IF('Rekap Nilai'!G4<=3,2,IF('Rekap Nilai'!G4<=4,3,4)))),MAX(0,'Rekap Nilai'!G4-5))*$E$7+IF('Rekap Nilai'!H4<=5,IF('Rekap Nilai'!H4<=1,1,IF('Rekap Nilai'!H4<=2,1,IF('Rekap Nilai'!H4<=3,2,IF('Rekap Nilai'!H4<=4,3,4)))),MAX(0,'Rekap Nilai'!H4-5))*$F$7 | D11: =IF('Rekap Nilai'!C4<=5,'Rekap Nilai'!C4,'Rekap Nilai'!C4)*$A$7+IF('Rekap Nilai'!D4<=5,'Rekap Nilai'!D4,'Rekap Nilai'!D4)*$B$7+IF('Rekap Nilai'!E4<=5,'Rekap Nilai'!E4,'Rekap Nilai'!E4)*$C$7+IF('Rekap Nilai'!F4<=5,'Rekap Nilai'!F4,'Rekap Nilai'!F4)*$D$7+IF('Rekap Nilai'!G4<=5,'Rekap Nilai'!G4,'Rekap Nilai'!G4)*$E$7+IF('Rekap Nilai'!H4<=5,'Rekap Nilai'!H4,'Rekap Nilai'!H4)*$F$7 | E11: =IF('Rekap Nilai'!C4<=5,IF('Rekap Nilai'!C4<=1,2,IF('Rekap Nilai'!C4<=2,3,IF('Rekap Nilai'!C4<=3,4,IF('Rekap Nilai'!C4<=4,5,5)))),MIN(100,'Rekap Nilai'!C4+5))*$A$7+IF('Rekap Nilai'!D4<=5,IF('Rekap Nilai'!D4<=1,2,IF('Rekap Nilai'!D4<=2,3,IF('Rekap Nilai'!D4<=3,4,IF('Rekap Nilai'!D4<=4,5,5)))),MIN(100,'Rekap Nilai'!D4+5))*$B$7+IF('Rekap Nilai'!E4<=5,IF('Rekap Nilai'!E4<=1,2,IF('Rekap Nilai'!E4<=2,3,IF('Rekap Nilai'!E4<=3,4,IF('Rekap Nilai'!E4<=4,5,5)))),MIN(100,'Rekap Nilai'!E4+5))*$C$7+IF('Rekap Nilai'!F4<=5,IF('Rekap Nilai'!F4<=1,2,IF('Rekap Nilai'!F4<=2,3,IF('Rekap Nilai'!F4<=3,4,IF('Rekap Nilai'!F4<=4,5,5)))),MIN(100,'Rekap Nilai'!F4+5))*$D$7+IF('Rekap Nilai'!G4<=5,IF('Rekap Nilai'!G4<=1,2,IF('Rekap Nilai'!G4<=2,3,IF('Rekap Nilai'!G4<=3,4,IF('Rekap Nilai'!G4<=4,5,5)))),MIN(100,'Rekap Nilai'!G4+5))*$E$7+IF('Rekap Nilai'!H4<=5,IF('Rekap Nilai'!H4<=1,2,IF('Rekap Nilai'!H4<=2,3,IF('Rekap Nilai'!H4<=3,4,IF('Rekap Nilai'!H4<=4,5,5)))),MIN(100,'Rekap Nilai'!H4+5))*$F$7 | F11: =(C11+D11+E11)/3 | G11: =IF(B11="","",RANK(F11,$F$11:$F$20,0))
A12: 2 | B12: ='Input'!B15 | C12: =IF('Rekap Nilai'!C5<=5,IF('Rekap Nilai'!C5<=1,1,IF('Rekap Nilai'!C5<=2,1,IF('Rekap Nilai'!C5<=3,2,IF('Rekap Nilai'!C5<=4,3,4)))),MAX(0,'Rekap Nilai'!C5-5))*$A$7+IF('Rekap Nilai'!D5<=5,IF('Rekap Nilai'!D5<=1,1,IF('Rekap Nilai'!D5<=2,1,IF('Rekap Nilai'!D5<=3,2,IF('Rekap Nilai'!D5<=4,3,4)))),MAX(0,'Rekap Nilai'!D5-5))*$B$7+IF('Rekap Nilai'!E5<=5,IF('Rekap Nilai'!E5<=1,1,IF('Rekap Nilai'!E5<=2,1,IF('Rekap Nilai'!E5<=3,2,IF('Rekap Nilai'!E5<=4,3,4)))),MAX(0,'Rekap Nilai'!E5-5))*$C$7+IF('Rekap Nilai'!F5<=5,IF('Rekap Nilai'!F5<=1,1,IF('Rekap Nilai'!F5<=2,1,IF('Rekap Nilai'!F5<=3,2,IF('Rekap Nilai'!F5<=4,3,4)))),MAX(0,'Rekap Nilai'!F5-5))*$D$7+IF('Rekap Nilai'!G5<=5,IF('Rekap Nilai'!G5<=1,1,IF('Rekap Nilai'!G5<=2,1,IF('Rekap Nilai'!G5<=3,2,IF('Rekap Nilai'!G5<=4,3,4)))),MAX(0,'Rekap Nilai'!G5-5))*$E$7+IF('Rekap Nilai'!H5<=5,IF('Rekap Nilai'!H5<=1,1,IF('Rekap Nilai'!H5<=2,1,IF('Rekap Nilai'!H5<=3,2,IF('Rekap Nilai'!H5<=4,3,4)))),MAX(0,'Rekap Nilai'!H5-5))*$F$7 | D12: =IF('Rekap Nilai'!C5<=5,'Rekap Nilai'!C5,'Rekap Nilai'!C5)*$A$7+IF('Rekap Nilai'!D5<=5,'Rekap Nilai'!D5,'Rekap Nilai'!D5)*$B$7+IF('Rekap Nilai'!E5<=5,'Rekap Nilai'!E5,'Rekap Nilai'!E5)*$C$7+IF('Rekap Nilai'!F5<=5,'Rekap Nilai'!F5,'Rekap Nilai'!F5)*$D$7+IF('Rekap Nilai'!G5<=5,'Rekap Nilai'!G5,'Rekap Nilai'!G5)*$E$7+IF('Rekap Nilai'!H5<=5,'Rekap Nilai'!H5,'Rekap Nilai'!H5)*$F$7 | E12: =IF('Rekap Nilai'!C5<=5,IF('Rekap Nilai'!C5<=1,2,IF('Rekap Nilai'!C5<=2,3,IF('Rekap Nilai'!C5<=3,4,IF('Rekap Nilai'!C5<=4,5,5)))),MIN(100,'Rekap Nilai'!C5+5))*$A$7+IF('Rekap Nilai'!D5<=5,IF('Rekap Nilai'!D5<=1,2,IF('Rekap Nilai'!D5<=2,3,IF('Rekap Nilai'!D5<=3,4,IF('Rekap Nilai'!D5<=4,5,5)))),MIN(100,'Rekap Nilai'!D5+5))*$B$7+IF('Rekap Nilai'!E5<=5,IF('Rekap Nilai'!E5<=1,2,IF('Rekap Nilai'!E5<=2,3,IF('Rekap Nilai'!E5<=3,4,IF('Rekap Nilai'!E5<=4,5,5)))),MIN(100,'Rekap Nilai'!E5+5))*$C$7+IF('Rekap Nilai'!F5<=5,IF('Rekap Nilai'!F5<=1,2,IF('Rekap Nilai'!F5<=2,3,IF('Rekap Nilai'!F5<=3,4,IF('Rekap Nilai'!F5<=4,5,5)))),MIN(100,'Rekap Nilai'!F5+5))*$D$7+IF('Rekap Nilai'!G5<=5,IF('Rekap Nilai'!G5<=1,2,IF('Rekap Nilai'!G5<=2,3,IF('Rekap Nilai'!G5<=3,4,IF('Rekap Nilai'!G5<=4,5,5)))),MIN(100,'Rekap Nilai'!G5+5))*$E$7+IF('Rekap Nilai'!H5<=5,IF('Rekap Nilai'!H5<=1,2,IF('Rekap Nilai'!H5<=2,3,IF('Rekap Nilai'!H5<=3,4,IF('Rekap Nilai'!H5<=4,5,5)))),MIN(100,'Rekap Nilai'!H5+5))*$F$7 | F12: =(C12+D12+E12)/3 | G12: =IF(B12="","",RANK(F12,$F$11:$F$20,0))
A13: 3 | B13: ='Input'!B16 | C13: =IF('Rekap Nilai'!C6<=5,IF('Rekap Nilai'!C6<=1,1,IF('Rekap Nilai'!C6<=2,1,IF('Rekap Nilai'!C6<=3,2,IF('Rekap Nilai'!C6<=4,3,4)))),MAX(0,'Rekap Nilai'!C6-5))*$A$7+IF('Rekap Nilai'!D6<=5,IF('Rekap Nilai'!D6<=1,1,IF('Rekap Nilai'!D6<=2,1,IF('Rekap Nilai'!D6<=3,2,IF('Rekap Nilai'!D6<=4,3,4)))),MAX(0,'Rekap Nilai'!D6-5))*$B$7+IF('Rekap Nilai'!E6<=5,IF('Rekap Nilai'!E6<=1,1,IF('Rekap Nilai'!E6<=2,1,IF('Rekap Nilai'!E6<=3,2,IF('Rekap Nilai'!E6<=4,3,4)))),MAX(0,'Rekap Nilai'!E6-5))*$C$7+IF('Rekap Nilai'!F6<=5,IF('Rekap Nilai'!F6<=1,1,IF('Rekap Nilai'!F6<=2,1,IF('Rekap Nilai'!F6<=3,2,IF('Rekap Nilai'!F6<=4,3,4)))),MAX(0,'Rekap Nilai'!F6-5))*$D$7+IF('Rekap Nilai'!G6<=5,IF('Rekap Nilai'!G6<=1,1,IF('Rekap Nilai'!G6<=2,1,IF('Rekap Nilai'!G6<=3,2,IF('Rekap Nilai'!G6<=4,3,4)))),MAX(0,'Rekap Nilai'!G6-5))*$E$7+IF('Rekap Nilai'!H6<=5,IF('Rekap Nilai'!H6<=1,1,IF('Rekap Nilai'!H6<=2,1,IF('Rekap Nilai'!H6<=3,2,IF('Rekap Nilai'!H6<=4,3,4)))),MAX(0,'Rekap Nilai'!H6-5))*$F$7 | D13: =IF('Rekap Nilai'!C6<=5,'Rekap Nilai'!C6,'Rekap Nilai'!C6)*$A$7+IF('Rekap Nilai'!D6<=5,'Rekap Nilai'!D6,'Rekap Nilai'!D6)*$B$7+IF('Rekap Nilai'!E6<=5,'Rekap Nilai'!E6,'Rekap Nilai'!E6)*$C$7+IF('Rekap Nilai'!F6<=5,'Rekap Nilai'!F6,'Rekap Nilai'!F6)*$D$7+IF('Rekap Nilai'!G6<=5,'Rekap Nilai'!G6,'Rekap Nilai'!G6)*$E$7+IF('Rekap Nilai'!H6<=5,'Rekap Nilai'!H6,'Rekap Nilai'!H6)*$F$7 | E13: =IF('Rekap Nilai'!C6<=5,IF('Rekap Nilai'!C6<=1,2,IF('Rekap Nilai'!C6<=2,3,IF('Rekap Nilai'!C6<=3,4,IF('Rekap Nilai'!C6<=4,5,5)))),MIN(100,'Rekap Nilai'!C6+5))*$A$7+IF('Rekap Nilai'!D6<=5,IF('Rekap Nilai'!D6<=1,2,IF('Rekap Nilai'!D6<=2,3,IF('Rekap Nilai'!D6<=3,4,IF('Rekap Nilai'!D6<=4,5,5)))),MIN(100,'Rekap Nilai'!D6+5))*$B$7+IF('Rekap Nilai'!E6<=5,IF('Rekap Nilai'!E6<=1,2,IF('Rekap Nilai'!E6<=2,3,IF('Rekap Nilai'!E6<=3,4,IF('Rekap Nilai'!E6<=4,5,5)))),MIN(100,'Rekap Nilai'!E6+5))*$C$7+IF('Rekap Nilai'!F6<=5,IF('Rekap Nilai'!F6<=1,2,IF('Rekap Nilai'!F6<=2,3,IF('Rekap Nilai'!F6<=3,4,IF('Rekap Nilai'!F6<=4,5,5)))),MIN(100,'Rekap Nilai'!F6+5))*$D$7+IF('Rekap Nilai'!G6<=5,IF('Rekap Nilai'!G6<=1,2,IF('Rekap Nilai'!G6<=2,3,IF('Rekap Nilai'!G6<=3,4,IF('Rekap Nilai'!G6<=4,5,5)))),MIN(100,'Rekap Nilai'!G6+5))*$E$7+IF('Rekap Nilai'!H6<=5,IF('Rekap Nilai'!H6<=1,2,IF('Rekap Nilai'!H6<=2,3,IF('Rekap Nilai'!H6<=3,4,IF('Rekap Nilai'!H6<=4,5,5)))),MIN(100,'Rekap Nilai'!H6+5))*$F$7 | F13: =(C13+D13+E13)/3 | G13: =IF(B13="","",RANK(F13,$F$11:$F$20,0))
A14: 4 | B14: ='Input'!B17 | C14: =IF('Rekap Nilai'!C7<=5,IF('Rekap Nilai'!C7<=1,1,IF('Rekap Nilai'!C7<=2,1,IF('Rekap Nilai'!C7<=3,2,IF('Rekap Nilai'!C7<=4,3,4)))),MAX(0,'Rekap Nilai'!C7-5))*$A$7+IF('Rekap Nilai'!D7<=5,IF('Rekap Nilai'!D7<=1,1,IF('Rekap Nilai'!D7<=2,1,IF('Rekap Nilai'!D7<=3,2,IF('Rekap Nilai'!D7<=4,3,4)))),MAX(0,'Rekap Nilai'!D7-5))*$B$7+IF('Rekap Nilai'!E7<=5,IF('Rekap Nilai'!E7<=1,1,IF('Rekap Nilai'!E7<=2,1,IF('Rekap Nilai'!E7<=3,2,IF('Rekap Nilai'!E7<=4,3,4)))),MAX(0,'Rekap Nilai'!E7-5))*$C$7+IF('Rekap Nilai'!F7<=5,IF('Rekap Nilai'!F7<=1,1,IF('Rekap Nilai'!F7<=2,1,IF('Rekap Nilai'!F7<=3,2,IF('Rekap Nilai'!F7<=4,3,4)))),MAX(0,'Rekap Nilai'!F7-5))*$D$7+IF('Rekap Nilai'!G7<=5,IF('Rekap Nilai'!G7<=1,1,IF('Rekap Nilai'!G7<=2,1,IF('Rekap Nilai'!G7<=3,2,IF('Rekap Nilai'!G7<=4,3,4)))),MAX(0,'Rekap Nilai'!G7-5))*$E$7+IF('Rekap Nilai'!H7<=5,IF('Rekap Nilai'!H7<=1,1,IF('Rekap Nilai'!H7<=2,1,IF('Rekap Nilai'!H7<=3,2,IF('Rekap Nilai'!H7<=4,3,4)))),MAX(0,'Rekap Nilai'!H7-5))*$F$7 | D14: =IF('Rekap Nilai'!C7<=5,'Rekap Nilai'!C7,'Rekap Nilai'!C7)*$A$7+IF('Rekap Nilai'!D7<=5,'Rekap Nilai'!D7,'Rekap Nilai'!D7)*$B$7+IF('Rekap Nilai'!E7<=5,'Rekap Nilai'!E7,'Rekap Nilai'!E7)*$C$7+IF('Rekap Nilai'!F7<=5,'Rekap Nilai'!F7,'Rekap Nilai'!F7)*$D$7+IF('Rekap Nilai'!G7<=5,'Rekap Nilai'!G7,'Rekap Nilai'!G7)*$E$7+IF('Rekap Nilai'!H7<=5,'Rekap Nilai'!H7,'Rekap Nilai'!H7)*$F$7 | E14: =IF('Rekap Nilai'!C7<=5,IF('Rekap Nilai'!C7<=1,2,IF('Rekap Nilai'!C7<=2,3,IF('Rekap Nilai'!C7<=3,4,IF('Rekap Nilai'!C7<=4,5,5)))),MIN(100,'Rekap Nilai'!C7+5))*$A$7+IF('Rekap Nilai'!D7<=5,IF('Rekap Nilai'!D7<=1,2,IF('Rekap Nilai'!D7<=2,3,IF('Rekap Nilai'!D7<=3,4,IF('Rekap Nilai'!D7<=4,5,5)))),MIN(100,'Rekap Nilai'!D7+5))*$B$7+IF('Rekap Nilai'!E7<=5,IF('Rekap Nilai'!E7<=1,2,IF('Rekap Nilai'!E7<=2,3,IF('Rekap Nilai'!E7<=3,4,IF('Rekap Nilai'!E7<=4,5,5)))),MIN(100,'Rekap Nilai'!E7+5))*$C$7+IF('Rekap Nilai'!F7<=5,IF('Rekap Nilai'!F7<=1,2,IF('Rekap Nilai'!F7<=2,3,IF('Rekap Nilai'!F7<=3,4,IF('Rekap Nilai'!F7<=4,5,5)))),MIN(100,'Rekap Nilai'!F7+5))*$D$7+IF('Rekap Nilai'!G7<=5,IF('Rekap Nilai'!G7<=1,2,IF('Rekap Nilai'!G7<=2,3,IF('Rekap Nilai'!G7<=3,4,IF('Rekap Nilai'!G7<=4,5,5)))),MIN(100,'Rekap Nilai'!G7+5))*$E$7+IF('Rekap Nilai'!H7<=5,IF('Rekap Nilai'!H7<=1,2,IF('Rekap Nilai'!H7<=2,3,IF('Rekap Nilai'!H7<=3,4,IF('Rekap Nilai'!H7<=4,5,5)))),MIN(100,'Rekap Nilai'!H7+5))*$F$7 | F14: =(C14+D14+E14)/3 | G14: =IF(B14="","",RANK(F14,$F$11:$F$20,0))
A15: 5 | B15: ='Input'!B18 | C15: =IF('Rekap Nilai'!C8<=5,IF('Rekap Nilai'!C8<=1,1,IF('Rekap Nilai'!C8<=2,1,IF('Rekap Nilai'!C8<=3,2,IF('Rekap Nilai'!C8<=4,3,4)))),MAX(0,'Rekap Nilai'!C8-5))*$A$7+IF('Rekap Nilai'!D8<=5,IF('Rekap Nilai'!D8<=1,1,IF('Rekap Nilai'!D8<=2,1,IF('Rekap Nilai'!D8<=3,2,IF('Rekap Nilai'!D8<=4,3,4)))),MAX(0,'Rekap Nilai'!D8-5))*$B$7+IF('Rekap Nilai'!E8<=5,IF('Rekap Nilai'!E8<=1,1,IF('Rekap Nilai'!E8<=2,1,IF('Rekap Nilai'!E8<=3,2,IF('Rekap Nilai'!E8<=4,3,4)))),MAX(0,'Rekap Nilai'!E8-5))*$C$7+IF('Rekap Nilai'!F8<=5,IF('Rekap Nilai'!F8<=1,1,IF('Rekap Nilai'!F8<=2,1,IF('Rekap Nilai'!F8<=3,2,IF('Rekap Nilai'!F8<=4,3,4)))),MAX(0,'Rekap Nilai'!F8-5))*$D$7+IF('Rekap Nilai'!G8<=5,IF('Rekap Nilai'!G8<=1,1,IF('Rekap Nilai'!G8<=2,1,IF('Rekap Nilai'!G8<=3,2,IF('Rekap Nilai'!G8<=4,3,4)))),MAX(0,'Rekap Nilai'!G8-5))*$E$7+IF('Rekap Nilai'!H8<=5,IF('Rekap Nilai'!H8<=1,1,IF('Rekap Nilai'!H8<=2,1,IF('Rekap Nilai'!H8<=3,2,IF('Rekap Nilai'!H8<=4,3,4)))),MAX(0,'Rekap Nilai'!H8-5))*$F$7 | D15: =IF('Rekap Nilai'!C8<=5,'Rekap Nilai'!C8,'Rekap Nilai'!C8)*$A$7+IF('Rekap Nilai'!D8<=5,'Rekap Nilai'!D8,'Rekap Nilai'!D8)*$B$7+IF('Rekap Nilai'!E8<=5,'Rekap Nilai'!E8,'Rekap Nilai'!E8)*$C$7+IF('Rekap Nilai'!F8<=5,'Rekap Nilai'!F8,'Rekap Nilai'!F8)*$D$7+IF('Rekap Nilai'!G8<=5,'Rekap Nilai'!G8,'Rekap Nilai'!G8)*$E$7+IF('Rekap Nilai'!H8<=5,'Rekap Nilai'!H8,'Rekap Nilai'!H8)*$F$7 | E15: =IF('Rekap Nilai'!C8<=5,IF('Rekap Nilai'!C8<=1,2,IF('Rekap Nilai'!C8<=2,3,IF('Rekap Nilai'!C8<=3,4,IF('Rekap Nilai'!C8<=4,5,5)))),MIN(100,'Rekap Nilai'!C8+5))*$A$7+IF('Rekap Nilai'!D8<=5,IF('Rekap Nilai'!D8<=1,2,IF('Rekap Nilai'!D8<=2,3,IF('Rekap Nilai'!D8<=3,4,IF('Rekap Nilai'!D8<=4,5,5)))),MIN(100,'Rekap Nilai'!D8+5))*$B$7+IF('Rekap Nilai'!E8<=5,IF('Rekap Nilai'!E8<=1,2,IF('Rekap Nilai'!E8<=2,3,IF('Rekap Nilai'!E8<=3,4,IF('Rekap Nilai'!E8<=4,5,5)))),MIN(100,'Rekap Nilai'!E8+5))*$C$7+IF('Rekap Nilai'!F8<=5,IF('Rekap Nilai'!F8<=1,2,IF('Rekap Nilai'!F8<=2,3,IF('Rekap Nilai'!F8<=3,4,IF('Rekap Nilai'!F8<=4,5,5)))),MIN(100,'Rekap Nilai'!F8+5))*$D$7+IF('Rekap Nilai'!G8<=5,IF('Rekap Nilai'!G8<=1,2,IF('Rekap Nilai'!G8<=2,3,IF('Rekap Nilai'!G8<=3,4,IF('Rekap Nilai'!G8<=4,5,5)))),MIN(100,'Rekap Nilai'!G8+5))*$E$7+IF('Rekap Nilai'!H8<=5,IF('Rekap Nilai'!H8<=1,2,IF('Rekap Nilai'!H8<=2,3,IF('Rekap Nilai'!H8<=3,4,IF('Rekap Nilai'!H8<=4,5,5)))),MIN(100,'Rekap Nilai'!H8+5))*$F$7 | F15: =(C15+D15+E15)/3 | G15: =IF(B15="","",RANK(F15,$F$11:$F$20,0))
A16: 6 | B16: ='Input'!B19 | C16: =IF('Rekap Nilai'!C9<=5,IF('Rekap Nilai'!C9<=1,1,IF('Rekap Nilai'!C9<=2,1,IF('Rekap Nilai'!C9<=3,2,IF('Rekap Nilai'!C9<=4,3,4)))),MAX(0,'Rekap Nilai'!C9-5))*$A$7+IF('Rekap Nilai'!D9<=5,IF('Rekap Nilai'!D9<=1,1,IF('Rekap Nilai'!D9<=2,1,IF('Rekap Nilai'!D9<=3,2,IF('Rekap Nilai'!D9<=4,3,4)))),MAX(0,'Rekap Nilai'!D9-5))*$B$7+IF('Rekap Nilai'!E9<=5,IF('Rekap Nilai'!E9<=1,1,IF('Rekap Nilai'!E9<=2,1,IF('Rekap Nilai'!E9<=3,2,IF('Rekap Nilai'!E9<=4,3,4)))),MAX(0,'Rekap Nilai'!E9-5))*$C$7+IF('Rekap Nilai'!F9<=5,IF('Rekap Nilai'!F9<=1,1,IF('Rekap Nilai'!F9<=2,1,IF('Rekap Nilai'!F9<=3,2,IF('Rekap Nilai'!F9<=4,3,4)))),MAX(0,'Rekap Nilai'!F9-5))*$D$7+IF('Rekap Nilai'!G9<=5,IF('Rekap Nilai'!G9<=1,1,IF('Rekap Nilai'!G9<=2,1,IF('Rekap Nilai'!G9<=3,2,IF('Rekap Nilai'!G9<=4,3,4)))),MAX(0,'Rekap Nilai'!G9-5))*$E$7+IF('Rekap Nilai'!H9<=5,IF('Rekap Nilai'!H9<=1,1,IF('Rekap Nilai'!H9<=2,1,IF('Rekap Nilai'!H9<=3,2,IF('Rekap Nilai'!H9<=4,3,4)))),MAX(0,'Rekap Nilai'!H9-5))*$F$7 | D16: =IF('Rekap Nilai'!C9<=5,'Rekap Nilai'!C9,'Rekap Nilai'!C9)*$A$7+IF('Rekap Nilai'!D9<=5,'Rekap Nilai'!D9,'Rekap Nilai'!D9)*$B$7+IF('Rekap Nilai'!E9<=5,'Rekap Nilai'!E9,'Rekap Nilai'!E9)*$C$7+IF('Rekap Nilai'!F9<=5,'Rekap Nilai'!F9,'Rekap Nilai'!F9)*$D$7+IF('Rekap Nilai'!G9<=5,'Rekap Nilai'!G9,'Rekap Nilai'!G9)*$E$7+IF('Rekap Nilai'!H9<=5,'Rekap Nilai'!H9,'Rekap Nilai'!H9)*$F$7 | E16: =IF('Rekap Nilai'!C9<=5,IF('Rekap Nilai'!C9<=1,2,IF('Rekap Nilai'!C9<=2,3,IF('Rekap Nilai'!C9<=3,4,IF('Rekap Nilai'!C9<=4,5,5)))),MIN(100,'Rekap Nilai'!C9+5))*$A$7+IF('Rekap Nilai'!D9<=5,IF('Rekap Nilai'!D9<=1,2,IF('Rekap Nilai'!D9<=2,3,IF('Rekap Nilai'!D9<=3,4,IF('Rekap Nilai'!D9<=4,5,5)))),MIN(100,'Rekap Nilai'!D9+5))*$B$7+IF('Rekap Nilai'!E9<=5,IF('Rekap Nilai'!E9<=1,2,IF('Rekap Nilai'!E9<=2,3,IF('Rekap Nilai'!E9<=3,4,IF('Rekap Nilai'!E9<=4,5,5)))),MIN(100,'Rekap Nilai'!E9+5))*$C$7+IF('Rekap Nilai'!F9<=5,IF('Rekap Nilai'!F9<=1,2,IF('Rekap Nilai'!F9<=2,3,IF('Rekap Nilai'!F9<=3,4,IF('Rekap Nilai'!F9<=4,5,5)))),MIN(100,'Rekap Nilai'!F9+5))*$D$7+IF('Rekap Nilai'!G9<=5,IF('Rekap Nilai'!G9<=1,2,IF('Rekap Nilai'!G9<=2,3,IF('Rekap Nilai'!G9<=3,4,IF('Rekap Nilai'!G9<=4,5,5)))),MIN(100,'Rekap Nilai'!G9+5))*$E$7+IF('Rekap Nilai'!H9<=5,IF('Rekap Nilai'!H9<=1,2,IF('Rekap Nilai'!H9<=2,3,IF('Rekap Nilai'!H9<=3,4,IF('Rekap Nilai'!H9<=4,5,5)))),MIN(100,'Rekap Nilai'!H9+5))*$F$7 | F16: =(C16+D16+E16)/3 | G16: =IF(B16="","",RANK(F16,$F$11:$F$20,0))
A17: 7 | B17: ='Input'!B20 | C17: =IF('Rekap Nilai'!C10<=5,IF('Rekap Nilai'!C10<=1,1,IF('Rekap Nilai'!C10<=2,1,IF('Rekap Nilai'!C10<=3,2,IF('Rekap Nilai'!C10<=4,3,4)))),MAX(0,'Rekap Nilai'!C10-5))*$A$7+IF('Rekap Nilai'!D10<=5,IF('Rekap Nilai'!D10<=1,1,IF('Rekap Nilai'!D10<=2,1,IF('Rekap Nilai'!D10<=3,2,IF('Rekap Nilai'!D10<=4,3,4)))),MAX(0,'Rekap Nilai'!D10-5))*$B$7+IF('Rekap Nilai'!E10<=5,IF('Rekap Nilai'!E10<=1,1,IF('Rekap Nilai'!E10<=2,1,IF('Rekap Nilai'!E10<=3,2,IF('Rekap Nilai'!E10<=4,3,4)))),MAX(0,'Rekap Nilai'!E10-5))*$C$7+IF('Rekap Nilai'!F10<=5,IF('Rekap Nilai'!F10<=1,1,IF('Rekap Nilai'!F10<=2,1,IF('Rekap Nilai'!F10<=3,2,IF('Rekap Nilai'!F10<=4,3,4)))),MAX(0,'Rekap Nilai'!F10-5))*$D$7+IF('Rekap Nilai'!G10<=5,IF('Rekap Nilai'!G10<=1,1,IF('Rekap Nilai'!G10<=2,1,IF('Rekap Nilai'!G10<=3,2,IF('Rekap Nilai'!G10<=4,3,4)))),MAX(0,'Rekap Nilai'!G10-5))*$E$7+IF('Rekap Nilai'!H10<=5,IF('Rekap Nilai'!H10<=1,1,IF('Rekap Nilai'!H10<=2,1,IF('Rekap Nilai'!H10<=3,2,IF('Rekap Nilai'!H10<=4,3,4)))),MAX(0,'Rekap Nilai'!H10-5))*$F$7 | D17: =IF('Rekap Nilai'!C10<=5,'Rekap Nilai'!C10,'Rekap Nilai'!C10)*$A$7+IF('Rekap Nilai'!D10<=5,'Rekap Nilai'!D10,'Rekap Nilai'!D10)*$B$7+IF('Rekap Nilai'!E10<=5,'Rekap Nilai'!E10,'Rekap Nilai'!E10)*$C$7+IF('Rekap Nilai'!F10<=5,'Rekap Nilai'!F10,'Rekap Nilai'!F10)*$D$7+IF('Rekap Nilai'!G10<=5,'Rekap Nilai'!G10,'Rekap Nilai'!G10)*$E$7+IF('Rekap Nilai'!H10<=5,'Rekap Nilai'!H10,'Rekap Nilai'!H10)*$F$7 | E17: =IF('Rekap Nilai'!C10<=5,IF('Rekap Nilai'!C10<=1,2,IF('Rekap Nilai'!C10<=2,3,IF('Rekap Nilai'!C10<=3,4,IF('Rekap Nilai'!C10<=4,5,5)))),MIN(100,'Rekap Nilai'!C10+5))*$A$7+IF('Rekap Nilai'!D10<=5,IF('Rekap Nilai'!D10<=1,2,IF('Rekap Nilai'!D10<=2,3,IF('Rekap Nilai'!D10<=3,4,IF('Rekap Nilai'!D10<=4,5,5)))),MIN(100,'Rekap Nilai'!D10+5))*$B$7+IF('Rekap Nilai'!E10<=5,IF('Rekap Nilai'!E10<=1,2,IF('Rekap Nilai'!E10<=2,3,IF('Rekap Nilai'!E10<=3,4,IF('Rekap Nilai'!E10<=4,5,5)))),MIN(100,'Rekap Nilai'!E10+5))*$C$7+IF('Rekap Nilai'!F10<=5,IF('Rekap Nilai'!F10<=1,2,IF('Rekap Nilai'!F10<=2,3,IF('Rekap Nilai'!F10<=3,4,IF('Rekap Nilai'!F10<=4,5,5)))),MIN(100,'Rekap Nilai'!F10+5))*$D$7+IF('Rekap Nilai'!G10<=5,IF('Rekap Nilai'!G10<=1,2,IF('Rekap Nilai'!G10<=2,3,IF('Rekap Nilai'!G10<=3,4,IF('Rekap Nilai'!G10<=4,5,5)))),MIN(100,'Rekap Nilai'!G10+5))*$E$7+IF('Rekap Nilai'!H10<=5,IF('Rekap Nilai'!H10<=1,2,IF('Rekap Nilai'!H10<=2,3,IF('Rekap Nilai'!H10<=3,4,IF('Rekap Nilai'!H10<=4,5,5)))),MIN(100,'Rekap Nilai'!H10+5))*$F$7 | F17: =(C17+D17+E17)/3 | G17: =IF(B17="","",RANK(F17,$F$11:$F$20,0))
A18: 8 | B18: ='Input'!B21 | C18: =IF('Rekap Nilai'!C11<=5,IF('Rekap Nilai'!C11<=1,1,IF('Rekap Nilai'!C11<=2,1,IF('Rekap Nilai'!C11<=3,2,IF('Rekap Nilai'!C11<=4,3,4)))),MAX(0,'Rekap Nilai'!C11-5))*$A$7+IF('Rekap Nilai'!D11<=5,IF('Rekap Nilai'!D11<=1,1,IF('Rekap Nilai'!D11<=2,1,IF('Rekap Nilai'!D11<=3,2,IF('Rekap Nilai'!D11<=4,3,4)))),MAX(0,'Rekap Nilai'!D11-5))*$B$7+IF('Rekap Nilai'!E11<=5,IF('Rekap Nilai'!E11<=1,1,IF('Rekap Nilai'!E11<=2,1,IF('Rekap Nilai'!E11<=3,2,IF('Rekap Nilai'!E11<=4,3,4)))),MAX(0,'Rekap Nilai'!E11-5))*$C$7+IF('Rekap Nilai'!F11<=5,IF('Rekap Nilai'!F11<=1,1,IF('Rekap Nilai'!F11<=2,1,IF('Rekap Nilai'!F11<=3,2,IF('Rekap Nilai'!F11<=4,3,4)))),MAX(0,'Rekap Nilai'!F11-5))*$D$7+IF('Rekap Nilai'!G11<=5,IF('Rekap Nilai'!G11<=1,1,IF('Rekap Nilai'!G11<=2,1,IF('Rekap Nilai'!G11<=3,2,IF('Rekap Nilai'!G11<=4,3,4)))),MAX(0,'Rekap Nilai'!G11-5))*$E$7+IF('Rekap Nilai'!H11<=5,IF('Rekap Nilai'!H11<=1,1,IF('Rekap Nilai'!H11<=2,1,IF('Rekap Nilai'!H11<=3,2,IF('Rekap Nilai'!H11<=4,3,4)))),MAX(0,'Rekap Nilai'!H11-5))*$F$7 | D18: =IF('Rekap Nilai'!C11<=5,'Rekap Nilai'!C11,'Rekap Nilai'!C11)*$A$7+IF('Rekap Nilai'!D11<=5,'Rekap Nilai'!D11,'Rekap Nilai'!D11)*$B$7+IF('Rekap Nilai'!E11<=5,'Rekap Nilai'!E11,'Rekap Nilai'!E11)*$C$7+IF('Rekap Nilai'!F11<=5,'Rekap Nilai'!F11,'Rekap Nilai'!F11)*$D$7+IF('Rekap Nilai'!G11<=5,'Rekap Nilai'!G11,'Rekap Nilai'!G11)*$E$7+IF('Rekap Nilai'!H11<=5,'Rekap Nilai'!H11,'Rekap Nilai'!H11)*$F$7 | E18: =IF('Rekap Nilai'!C11<=5,IF('Rekap Nilai'!C11<=1,2,IF('Rekap Nilai'!C11<=2,3,IF('Rekap Nilai'!C11<=3,4,IF('Rekap Nilai'!C11<=4,5,5)))),MIN(100,'Rekap Nilai'!C11+5))*$A$7+IF('Rekap Nilai'!D11<=5,IF('Rekap Nilai'!D11<=1,2,IF('Rekap Nilai'!D11<=2,3,IF('Rekap Nilai'!D11<=3,4,IF('Rekap Nilai'!D11<=4,5,5)))),MIN(100,'Rekap Nilai'!D11+5))*$B$7+IF('Rekap Nilai'!E11<=5,IF('Rekap Nilai'!E11<=1,2,IF('Rekap Nilai'!E11<=2,3,IF('Rekap Nilai'!E11<=3,4,IF('Rekap Nilai'!E11<=4,5,5)))),MIN(100,'Rekap Nilai'!E11+5))*$C$7+IF('Rekap Nilai'!F11<=5,IF('Rekap Nilai'!F11<=1,2,IF('Rekap Nilai'!F11<=2,3,IF('Rekap Nilai'!F11<=3,4,IF('Rekap Nilai'!F11<=4,5,5)))),MIN(100,'Rekap Nilai'!F11+5))*$D$7+IF('Rekap Nilai'!G11<=5,IF('Rekap Nilai'!G11<=1,2,IF('Rekap Nilai'!G11<=2,3,IF('Rekap Nilai'!G11<=3,4,IF('Rekap Nilai'!G11<=4,5,5)))),MIN(100,'Rekap Nilai'!G11+5))*$E$7+IF('Rekap Nilai'!H11<=5,IF('Rekap Nilai'!H11<=1,2,IF('Rekap Nilai'!H11<=2,3,IF('Rekap Nilai'!H11<=3,4,IF('Rekap Nilai'!H11<=4,5,5)))),MIN(100,'Rekap Nilai'!H11+5))*$F$7 | F18: =(C18+D18+E18)/3 | G18: =IF(B18="","",RANK(F18,$F$11:$F$20,0))
A19: 9 | B19: ='Input'!B22 | C19: =IF('Rekap Nilai'!C12<=5,IF('Rekap Nilai'!C12<=1,1,IF('Rekap Nilai'!C12<=2,1,IF('Rekap Nilai'!C12<=3,2,IF('Rekap Nilai'!C12<=4,3,4)))),MAX(0,'Rekap Nilai'!C12-5))*$A$7+IF('Rekap Nilai'!D12<=5,IF('Rekap Nilai'!D12<=1,1,IF('Rekap Nilai'!D12<=2,1,IF('Rekap Nilai'!D12<=3,2,IF('Rekap Nilai'!D12<=4,3,4)))),MAX(0,'Rekap Nilai'!D12-5))*$B$7+IF('Rekap Nilai'!E12<=5,IF('Rekap Nilai'!E12<=1,1,IF('Rekap Nilai'!E12<=2,1,IF('Rekap Nilai'!E12<=3,2,IF('Rekap Nilai'!E12<=4,3,4)))),MAX(0,'Rekap Nilai'!E12-5))*$C$7+IF('Rekap Nilai'!F12<=5,IF('Rekap Nilai'!F12<=1,1,IF('Rekap Nilai'!F12<=2,1,IF('Rekap Nilai'!F12<=3,2,IF('Rekap Nilai'!F12<=4,3,4)))),MAX(0,'Rekap Nilai'!F12-5))*$D$7+IF('Rekap Nilai'!G12<=5,IF('Rekap Nilai'!G12<=1,1,IF('Rekap Nilai'!G12<=2,1,IF('Rekap Nilai'!G12<=3,2,IF('Rekap Nilai'!G12<=4,3,4)))),MAX(0,'Rekap Nilai'!G12-5))*$E$7+IF('Rekap Nilai'!H12<=5,IF('Rekap Nilai'!H12<=1,1,IF('Rekap Nilai'!H12<=2,1,IF('Rekap Nilai'!H12<=3,2,IF('Rekap Nilai'!H12<=4,3,4)))),MAX(0,'Rekap Nilai'!H12-5))*$F$7 | D19: =IF('Rekap Nilai'!C12<=5,'Rekap Nilai'!C12,'Rekap Nilai'!C12)*$A$7+IF('Rekap Nilai'!D12<=5,'Rekap Nilai'!D12,'Rekap Nilai'!D12)*$B$7+IF('Rekap Nilai'!E12<=5,'Rekap Nilai'!E12,'Rekap Nilai'!E12)*$C$7+IF('Rekap Nilai'!F12<=5,'Rekap Nilai'!F12,'Rekap Nilai'!F12)*$D$7+IF('Rekap Nilai'!G12<=5,'Rekap Nilai'!G12,'Rekap Nilai'!G12)*$E$7+IF('Rekap Nilai'!H12<=5,'Rekap Nilai'!H12,'Rekap Nilai'!H12)*$F$7 | E19: =IF('Rekap Nilai'!C12<=5,IF('Rekap Nilai'!C12<=1,2,IF('Rekap Nilai'!C12<=2,3,IF('Rekap Nilai'!C12<=3,4,IF('Rekap Nilai'!C12<=4,5,5)))),MIN(100,'Rekap Nilai'!C12+5))*$A$7+IF('Rekap Nilai'!D12<=5,IF('Rekap Nilai'!D12<=1,2,IF('Rekap Nilai'!D12<=2,3,IF('Rekap Nilai'!D12<=3,4,IF('Rekap Nilai'!D12<=4,5,5)))),MIN(100,'Rekap Nilai'!D12+5))*$B$7+IF('Rekap Nilai'!E12<=5,IF('Rekap Nilai'!E12<=1,2,IF('Rekap Nilai'!E12<=2,3,IF('Rekap Nilai'!E12<=3,4,IF('Rekap Nilai'!E12<=4,5,5)))),MIN(100,'Rekap Nilai'!E12+5))*$C$7+IF('Rekap Nilai'!F12<=5,IF('Rekap Nilai'!F12<=1,2,IF('Rekap Nilai'!F12<=2,3,IF('Rekap Nilai'!F12<=3,4,IF('Rekap Nilai'!F12<=4,5,5)))),MIN(100,'Rekap Nilai'!F12+5))*$D$7+IF('Rekap Nilai'!G12<=5,IF('Rekap Nilai'!G12<=1,2,IF('Rekap Nilai'!G12<=2,3,IF('Rekap Nilai'!G12<=3,4,IF('Rekap Nilai'!G12<=4,5,5)))),MIN(100,'Rekap Nilai'!G12+5))*$E$7+IF('Rekap Nilai'!H12<=5,IF('Rekap Nilai'!H12<=1,2,IF('Rekap Nilai'!H12<=2,3,IF('Rekap Nilai'!H12<=3,4,IF('Rekap Nilai'!H12<=4,5,5)))),MIN(100,'Rekap Nilai'!H12+5))*$F$7 | F19: =(C19+D19+E19)/3 | G19: =IF(B19="","",RANK(F19,$F$11:$F$20,0))
A20: 10 | B20: ='Input'!B23 | C20: =IF('Rekap Nilai'!C13<=5,IF('Rekap Nilai'!C13<=1,1,IF('Rekap Nilai'!C13<=2,1,IF('Rekap Nilai'!C13<=3,2,IF('Rekap Nilai'!C13<=4,3,4)))),MAX(0,'Rekap Nilai'!C13-5))*$A$7+IF('Rekap Nilai'!D13<=5,IF('Rekap Nilai'!D13<=1,1,IF('Rekap Nilai'!D13<=2,1,IF('Rekap Nilai'!D13<=3,2,IF('Rekap Nilai'!D13<=4,3,4)))),MAX(0,'Rekap Nilai'!D13-5))*$B$7+IF('Rekap Nilai'!E13<=5,IF('Rekap Nilai'!E13<=1,1,IF('Rekap Nilai'!E13<=2,1,IF('Rekap Nilai'!E13<=3,2,IF('Rekap Nilai'!E13<=4,3,4)))),MAX(0,'Rekap Nilai'!E13-5))*$C$7+IF('Rekap Nilai'!F13<=5,IF('Rekap Nilai'!F13<=1,1,IF('Rekap Nilai'!F13<=2,1,IF('Rekap Nilai'!F13<=3,2,IF('Rekap Nilai'!F13<=4,3,4)))),MAX(0,'Rekap Nilai'!F13-5))*$D$7+IF('Rekap Nilai'!G13<=5,IF('Rekap Nilai'!G13<=1,1,IF('Rekap Nilai'!G13<=2,1,IF('Rekap Nilai'!G13<=3,2,IF('Rekap Nilai'!G13<=4,3,4)))),MAX(0,'Rekap Nilai'!G13-5))*$E$7+IF('Rekap Nilai'!H13<=5,IF('Rekap Nilai'!H13<=1,1,IF('Rekap Nilai'!H13<=2,1,IF('Rekap Nilai'!H13<=3,2,IF('Rekap Nilai'!H13<=4,3,4)))),MAX(0,'Rekap Nilai'!H13-5))*$F$7 | D20: =IF('Rekap Nilai'!C13<=5,'Rekap Nilai'!C13,'Rekap Nilai'!C13)*$A$7+IF('Rekap Nilai'!D13<=5,'Rekap Nilai'!D13,'Rekap Nilai'!D13)*$B$7+IF('Rekap Nilai'!E13<=5,'Rekap Nilai'!E13,'Rekap Nilai'!E13)*$C$7+IF('Rekap Nilai'!F13<=5,'Rekap Nilai'!F13,'Rekap Nilai'!F13)*$D$7+IF('Rekap Nilai'!G13<=5,'Rekap Nilai'!G13,'Rekap Nilai'!G13)*$E$7+IF('Rekap Nilai'!H13<=5,'Rekap Nilai'!H13,'Rekap Nilai'!H13)*$F$7 | E20: =IF('Rekap Nilai'!C13<=5,IF('Rekap Nilai'!C13<=1,2,IF('Rekap Nilai'!C13<=2,3,IF('Rekap Nilai'!C13<=3,4,IF('Rekap Nilai'!C13<=4,5,5)))),MIN(100,'Rekap Nilai'!C13+5))*$A$7+IF('Rekap Nilai'!D13<=5,IF('Rekap Nilai'!D13<=1,2,IF('Rekap Nilai'!D13<=2,3,IF('Rekap Nilai'!D13<=3,4,IF('Rekap Nilai'!D13<=4,5,5)))),MIN(100,'Rekap Nilai'!D13+5))*$B$7+IF('Rekap Nilai'!E13<=5,IF('Rekap Nilai'!E13<=1,2,IF('Rekap Nilai'!E13<=2,3,IF('Rekap Nilai'!E13<=3,4,IF('Rekap Nilai'!E13<=4,5,5)))),MIN(100,'Rekap Nilai'!E13+5))*$C$7+IF('Rekap Nilai'!F13<=5,IF('Rekap Nilai'!F13<=1,2,IF('Rekap Nilai'!F13<=2,3,IF('Rekap Nilai'!F13<=3,4,IF('Rekap Nilai'!F13<=4,5,5)))),MIN(100,'Rekap Nilai'!F13+5))*$D$7+IF('Rekap Nilai'!G13<=5,IF('Rekap Nilai'!G13<=1,2,IF('Rekap Nilai'!G13<=2,3,IF('Rekap Nilai'!G13<=3,4,IF('Rekap Nilai'!G13<=4,5,5)))),MIN(100,'Rekap Nilai'!G13+5))*$E$7+IF('Rekap Nilai'!H13<=5,IF('Rekap Nilai'!H13<=1,2,IF('Rekap Nilai'!H13<=2,3,IF('Rekap Nilai'!H13<=3,4,IF('Rekap Nilai'!H13<=4,5,5)))),MIN(100,'Rekap Nilai'!H13+5))*$F$7 | F20: =(C20+D20+E20)/3 | G20: =IF(B20="","",RANK(F20,$F$11:$F$20,0))
