Workbook

Sheet Input
A1: FUZZY AHP - 3 PENILAI
A3: BOBOT KRITERIA
A4: Kode | B4: Kriteria | C4: Bobot
A5: K1 | B5: Status Keaktifan | C5: 1
A6: K2 | B6: Pencapaian SKU | C6: 2
A7: K3 | B7: Pencapaian SPG | C7: 2
A8: K4 | B8: Kesehatan Jasmani | C8: 3
A9: K5 | B9: Tes Wawancara | C9: 4
A10: K6 | B10: Tes Pilihan Ganda | C10: 5
A12: PESERTA
A13: No | B13: Nama
A14: 1 | B14: David Kulian
A15: 2 | B15: Siti Aminah
A16: 3 | B16: Budi Santoso
A17: 4 | B17: Dewi Lestari
A18: 5 | B18: Ahmad Fauzi
A19: 6 | B19: Rina Wati
A20: 7 | B20: Joko Susilo
A21: 8 | B21: Maya Sari
A22: 9 | B22: Andi Pratama
A23: 10 | B23: Lina Marlina

Sheet Penilai 1
A1: INPUT NILAI PENILAI 1 (K1, K2)
A3: No | B3: Nama | C3: K1 | D3: K2
A4: 1 | B4: ='Input'!B14 | C4: 85 | D4: 78
A5: 2 | B5: ='Input'!B15 | C5: 78 | D5: 82
A6: 3 | B6: ='Input'!B16 | C6: 92 | D6: 88
A7: 4 | B7: ='Input'!B17 | C7: 80 | D7: 85
A8: 5 | B8: ='Input'!B18 | C8: 88 | D8: 90
A9: 6 | B9: ='Input'!B19 | C9: 75 | D9: 80
A10: 7 | B10: ='Input'!B20 | C10: 82 | D10: 78
A11: 8 | B11: ='Input'!B21 | C11: 90 | D11: 85
A12: 9 | B12: ='Input'!B22 | C12: 85 | D12: 82
A13: 10 | B13: ='Input'!B23 | C13: 78 | D13: 80

Sheet Penilai 2
A1: INPUT NILAI PENILAI 2 (K3, K4)
A3: No | B3: Nama | C3: K3 | D3: K4
A4: 1 | B4: ='Input'!B14 | C4: 88 | D4: 92
A5: 2 | B5: ='Input'!B15 | C5: 82 | D5: 88
A6: 3 | B6: ='Input'!B16 | C6: 90 | D6: 85
A7: 4 | B7: ='Input'!B17 | C7: 85 | D7: 90
A8: 5 | B8: ='Input'!B18 | C8: 87 | D8: 80
A9: 6 | B9: ='Input'!B19 | C9: 80 | D9: 85
A10: 7 | B10: ='Input'!B20 | C10: 88 | D10: 82
A11: 8 | B11: ='Input'!B21 | C11: 85 | D11: 88
A12: 9 | B12: ='Input'!B22 | C12: 82 | D12: 85
A13: 10 | B13: ='Input'!B23 | C13: 85 | D13: 90

Sheet Penilai 3
A1: INPUT NILAI PENILAI 3 (K5, K6)
A3: No | B3: Nama | C3: K5 | D3: K6
A4: 1 | B4: ='Input'!B14 | C4: 87 | D4: 85
A5: 2 | B5: ='Input'!B15 | C5: 80 | D5: 78
A6: 3 | B6: ='Input'!B16 | C6: 88 | D6: 90
A7: 4 | B7: ='Input'!B17 | C7: 82 | D7: 80
A8: 5 | B8: ='Input'!B18 | C8: 90 | D8: 88
A9: 6 | B9: ='Input'!B19 | C9: 85 | D9: 82
A10: 7 | B10: ='Input'!B20 | C10: 80 | D10: 85
A11: 8 | B11: ='Input'!B21 | C11: 88 | D11: 92
A12: 9 | B12: ='Input'!B22 | C12: 85 | D12: 80
A13: 10 | B13: ='Input'!B23 | C13: 82 | D13: 85

Sheet Rekap Nilai
A1: REKAP NILAI DARI 3 PENILAI
A3: No | B3: Nama | C3: K1 | D3: K2 | E3: K3 | F3: K4 | G3: K5 | H3: K6
A4: 1 | B4: ='Input'!B14 | C4: ='Penilai 1'!C4 | D4: ='Penilai 1'!D4 | E4: ='Penilai 2'!C4 | F4: ='Penilai 2'!D4 | G4: ='Penilai 3'!C4 | H4: ='Penilai 3'!D4
A5: 2 | B5: ='Input'!B15 | C5: ='Penilai 1'!C5 | D5: ='Penilai 1'!D5 | E5: ='Penilai 2'!C5 | F5: ='Penilai 2'!D5 | G5: ='Penilai 3'!C5 | H5: ='Penilai 3'!D5
A6: 3 | B6: ='Input'!B16 | C6: ='Penilai 1'!C6 | D6: ='Penilai 1'!D6 | E6: ='Penilai 2'!C6 | F6: ='Penilai 2'!D6 | G6: ='Penilai 3'!C6 | H6: ='Penilai 3'!D6
A7: 4 | B7: ='Input'!B17 | C7: ='Penilai 1'!C7 | D7: ='Penilai 1'!D7 | E7: ='Penilai 2'!C7 | F7: ='Penilai 2'!D7 | G7: ='Penilai 3'!C7 | H7: ='Penilai 3'!D7
A8: 5 | B8: ='Input'!B18 | C8: ='Penilai 1'!C8 | D8: ='Penilai 1'!D8 | E8: ='Penilai 2'!C8 | F8: ='Penilai 2'!D8 | G8: ='Penilai 3'!C8 | H8: ='Penilai 3'!D8
A9: 6 | B9: ='Input'!B19 | C9: ='Penilai 1'!C9 | D9: ='Penilai 1'!D9 | E9: ='Penilai 2'!C9 | F9: ='Penilai 2'!D9 | G9: ='Penilai 3'!C9 | H9: ='Penilai 3'!D9
A10: 7 | B10: ='Input'!B20 | C10: ='Penilai 1'!C10 | D10: ='Penilai 1'!D10 | E10: ='Penilai 2'!C10 | F10: ='Penilai 2'!D10 | G10: ='Penilai 3'!C10 | H10: ='Penilai 3'!D10
A11: 8 | B11: ='Input'!B21 | C11: ='Penilai 1'!C11 | D11: ='Penilai 1'!D11 | E11: ='Penilai 2'!C11 | F11: ='Penilai 2'!D11 | G11: ='Penilai 3'!C11 | H11: ='Penilai 3'!D11
A12: 9 | B12: ='Input'!B22 | C12: ='Penilai 1'!C12 | D12: ='Penilai 1'!D12 | E12: ='Penilai 2'!C12 | F12: ='Penilai 2'!D12 | G12: ='Penilai 3'!C12 | H12: ='Penilai 3'!D12
A13: 10 | B13: ='Input'!B23 | C13: ='Penilai 1'!C13 | D13: ='Penilai 1'!D13 | E13: ='Penilai 2'!C13 | F13: ='Penilai 2'!D13 | G13: ='Penilai 3'!C13 | H13: ='Penilai 3'!D13

Sheet Fuzzy AHP
A1: PERHITUNGAN FUZZY AHP LENGKAP
A3: LANGKAH 1: MATRIKS CRISP
B4: K1 | C4: K2 | D4: K3 | E4: K4 | F4: K5 | G4: K6
A5: K1 | B5: 1 | C5: =IF('Input'!$C$5/'Input'!$C$6>=1,MIN(9,MAX(1,'Input'!$C$5/'Input'!$C$6)),MAX(1/9,'Input'!$C$5/'Input'!$C$6)) | D5: =IF('Input'!$C$5/'Input'!$C$7>=1,MIN(9,MAX(1,'Input'!$C$5/'Input'!$C$7)),MAX(1/9,'Input'!$C$5/'Input'!$C$7)) | E5: =IF('Input'!$C$5/'Input'!$C$8>=1,MIN(9,MAX(1,'Input'!$C$5/'Input'!$C$8)),MAX(1/9,'Input'!$C$5/'Input'!$C$8)) | F5: =IF('Input'!$C$5/'Input'!$C$9>=1,MIN(9,MAX(1,'Input'!$C$5/'Input'!$C$9)),MAX(1/9,'Input'!$C$5/'Input'!$C$9)) | G5: =IF('Input'!$C$5/'Input'!$C$10>=1,MIN(9,MAX(1,'Input'!$C$5/'Input'!$C$10)),MAX(1/9,'Input'!$C$5/'Input'!$C$10))
A6: K2 | B6: =IF('Input'!$C$6/'Input'!$C$5>=1,MIN(9,MAX(1,'Input'!$C$6/'Input'!$C$5)),MAX(1/9,'Input'!$C$6/'Input'!$C$5)) | C6: 1 | D6: =IF('Input'!$C$6/'Input'!$C$7>=1,MIN(9,MAX(1,'Input'!$C$6/'Input'!$C$7)),MAX(1/9,'Input'!$C$6/'Input'!$C$7)) | E6: =IF('Input'!$C$6/'Input'!$C$8>=1,MIN(9,MAX(1,'Input'!$C$6/'Input'!$C$8)),MAX(1/9,'Input'!$C$6/'Input'!$C$8)) | F6: =IF('Input'!$C$6/'Input'!$C$9>=1,MIN(9,MAX(1,'Input'!$C$6/'Input'!$C$9)),MAX(1/9,'Input'!$C$6/'Input'!$C$9)) | G6: =IF('Input'!$C$6/'Input'!$C$10>=1,MIN(9,MAX(1,'Input'!$C$6/'Input'!$C$10)),MAX(1/9,'Input'!$C$6/'Input'!$C$10))
A7: K3 | B7: =IF('Input'!$C$7/'Input'!$C$5>=1,MIN(9,MAX(1,'Input'!$C$7/'Input'!$C$5)),MAX(1/9,'Input'!$C$7/'Input'!$C$5)) | C7: =IF('Input'!$C$7/'Input'!$C$6>=1,MIN(9,MAX(1,'Input'!$C$7/'Input'!$C$6)),MAX(1/9,'Input'!$C$7/'Input'!$C$6)) | D7: 1 | E7: =IF('Input'!$C$7/'Input'!$C$8>=1,MIN(9,MAX(1,'Input'!$C$7/'Input'!$C$8)),MAX(1/9,'Input'!$C$7/'Input'!$C$8)) | F7: =IF('Input'!$C$7/'Input'!$C$9>=1,MIN(9,MAX(1,'Input'!$C$7/'Input'!$C$9)),MAX(1/9,'Input'!$C$7/'Input'!$C$9)) | G7: =IF('Input'!$C$7/'Input'!$C$10>=1,MIN(9,MAX(1,'Input'!$C$7/'Input'!$C$10)),MAX(1/9,'Input'!$C$7/'Input'!$C$10))
A8: K4 | B8: =IF('Input'!$C$8/'Input'!$C$5>=1,MIN(9,MAX(1,'Input'!$C$8/'Input'!$C$5)),MAX(1/9,'Input'!$C$8/'Input'!$C$5)) | C8: =IF('Input'!$C$8/'Input'!$C$6>=1,MIN(9,MAX(1,'Input'!$C$8/'Input'!$C$6)),MAX(1/9,'Input'!$C$8/'Input'!$C$6)) | D8: =IF('Input'!$C$8/'Input'!$C$7>=1,MIN(9,MAX(1,'Input'!$C$8/'Input'!$C$7)),MAX(1/9,'Input'!$C$8/'Input'!$C$7)) | E8: 1 | F8: =IF('Input'!$C$8/'Input'!$C$9>=1,MIN(9,MAX(1,'Input'!$C$8/'Input'!$C$9)),MAX(1/9,'Input'!$C$8/'Input'!$C$9)) | G8: =IF('Input'!$C$8/'Input'!$C$10>=1,MIN(9,MAX(1,'Input'!$C$8/'Input'!$C$10)),MAX(1/9,'Input'!$C$8/'Input'!$C$10))
A9: K5 | B9: =IF('Input'!$C$9/'Input'!$C$5>=1,MIN(9,MAX(1,'Input'!$C$9/'Input'!$C$5)),MAX(1/9,'Input'!$C$9/'Input'!$C$5)) | C9: =IF('Input'!$C$9/'Input'!$C$6>=1,MIN(9,MAX(1,'Input'!$C$9/'Input'!$C$6)),MAX(1/9,'Input'!$C$9/'Input'!$C$6)) | D9: =IF('Input'!$C$9/'Input'!$C$7>=1,MIN(9,MAX(1,'Input'!$C$9/'Input'!$C$7)),MAX(1/9,'Input'!$C$9/'Input'!$C$7)) | E9: =IF('Input'!$C$9/'Input'!$C$8>=1,MIN(9,MAX(1,'Input'!$C$9/'Input'!$C$8)),MAX(1/9,'Input'!$C$9/'Input'!$C$8)) | F9: 1 | G9: =IF('Input'!$C$9/'Input'!$C$10>=1,MIN(9,MAX(1,'Input'!$C$9/'Input'!$C$10)),MAX(1/9,'Input'!$C$9/'Input'!$C$10))
A10: K6 | B10: =IF('Input'!$C$10/'Input'!$C$5>=1,MIN(9,MAX(1,'Input'!$C$10/'Input'!$C$5)),MAX(1/9,'Input'!$C$10/'Input'!$C$5)) | C10: =IF('Input'!$C$10/'Input'!$C$6>=1,MIN(9,MAX(1,'Input'!$C$10/'Input'!$C$6)),MAX(1/9,'Input'!$C$10/'Input'!$C$6)) | D10: =IF('Input'!$C$10/'Input'!$C$7>=1,MIN(9,MAX(1,'Input'!$C$10/'Input'!$C$7)),MAX(1/9,'Input'!$C$10/'Input'!$C$7)) | E10: =IF('Input'!$C$10/'Input'!$C$8>=1,MIN(9,MAX(1,'Input'!$C$10/'Input'!$C$8)),MAX(1/9,'Input'!$C$10/'Input'!$C$8)) | F10: =IF('Input'!$C$10/'Input'!$C$9>=1,MIN(9,MAX(1,'Input'!$C$10/'Input'!$C$9)),MAX(1/9,'Input'!$C$10/'Input'!$C$9)) | G10: 1
A12: LANGKAH 4: MATRIKS FUZZY TFN
A13: Konversi crisp ke TFN: 1=(1,1,1), 2=(0.5,1,1.5), 3=(1,1.5,2), dst
B14: K1 | E14: K2 | H14: K3 | K14: K4 | N14: K5 | Q14: K6
B15: l | C15: m | D15: u | E15: l | F15: m | G15: u | H15: l | I15: m | J15: u | K15: l | L15: m | M15: u | N15: l | O15: m | P15: u | Q15: l | R15: m | S15: u
A16: K1 | B16: 1 | C16: 1 | D16: 1 | E16: 0.5 | F16: 0.67 | G16: 1 | H16: 0.5 | I16: 0.67 | J16: 1 | K16: 0.33 | L16: 0.4 | M16: 0.5 | N16: 0.25 | O16: 0.29 | P16: 0.33 | Q16: 0.22 | R16: 0.22 | S16: 0.25
A17: K2 | B17: 1 | C17: 1.5 | D17: 2 | E17: 1 | F17: 1 | G17: 1 | H17: 1 | I17: 1 | J17: 1 | K17: 0.5 | L17: 0.67 | M17: 1 | N17: 0.5 | O17: 0.67 | P17: 1 | Q17: 0.33 | R17: 0.4 | S17: 0.5
A18: K3 | B18: 1 | C18: 1.5 | D18: 2 | E18: 1 | F18: 1 | G18: 1 | H18: 1 | I18: 1 | J18: 1 | K18: 0.5 | L18: 0.67 | M18: 1 | N18: 0.5 | O18: 0.67 | P18: 1 | Q18: 0.33 | R18: 0.4 | S18: 0.5
A19: K4 | B19: 2 | C19: 2.5 | D19: 3 | E19: 1 | F19: 1.5 | G19: 2 | H19: 1 | I19: 1.5 | J19: 2 | K19: 1 | L19: 1 | M19: 1 | N19: 0.5 | O19: 0.67 | P19: 1 | Q19: 0.5 | R19: 0.67 | S19: 1
A20: K5 | B20: 3 | C20: 3.5 | D20: 4 | E20: 1 | F20: 1.5 | G20: 2 | H20: 1 | I20: 1.5 | J20: 2 | K20: 1 | L20: 1.5 | M20: 2 | N20: 1 | O20: 1 | P20: 1 | Q20: 0.5 | R20: 0.67 | S20: 1
A21: K6 | B21: 4 | C21: 4.5 | D21: 4.5 | E21: 2 | F21: 2.5 | G21: 3 | H21: 2 | I21: 2.5 | J21: 3 | K21: 1 | L21: 1.5 | M21: 2 | N21: 1 | O21: 1.5 | P21: 2 | Q21: 1 | R21: 1 | S21: 1
A23: LANGKAH 5: FUZZY SYNTHETIC EXTENT
A24: Kriteria | B24: Σl | C24: Σm | D24: Σu
A25: Status Keaktifan | B25: =B16+E16+H16+K16+N16+Q16 | C25: =C16+F16+I16+L16+O16+R16 | D25: =D16+G16+J16+M16+P16+S16
A26: Pencapaian SKU | B26: =B17+E17+H17+K17+N17+Q17 | C26: =C17+F17+I17+L17+O17+R17 | D26: =D17+G17+J17+M17+P17+S17
A27: Pencapaian SPG | B27: =B18+E18+H18+K18+N18+Q18 | C27: =C18+F18+I18+L18+O18+R18 | D27: =D18+G18+J18+M18+P18+S18
A28: Kesehatan Jasmani | B28: =B19+E19+H19+K19+N19+Q19 | C28: =C19+F19+I19+L19+O19+R19 | D28: =D19+G19+J19+M19+P19+S19
A29: Tes Wawancara | B29: =B20+E20+H20+K20+N20+Q20 | C29: =C20+F20+I20+L20+O20+R20 | D29: =D20+G20+J20+M20+P20+S20
A30: Tes Pilihan Ganda | B30: =B21+E21+H21+K21+N21+Q21 | C30: =C21+F21+I21+L21+O21+R21 | D30: =D21+G21+J21+M21+P21+S21
A31: Total | B31: =SUM(B25:B30) | C31: =SUM(C25:C30) | D31: =SUM(D25:D30)
A33: Synthetic Extent Si
A34: Kriteria | B34: Si(l) | C34: Si(m) | D34: Si(u)
A35: Status Keaktifan | B35: =B25/$D$31 | C35: =C25/$C$31 | D35: =D25/$B$31
A36: Pencapaian SKU | B36: =B26/$D$31 | C36: =C26/$C$31 | D36: =D26/$B$31
A37: Pencapaian SPG | B37: =B27/$D$31 | C37: =C27/$C$31 | D37: =D27/$B$31
A38: Kesehatan Jasmani | B38: =B28/$D$31 | C38: =C28/$C$31 | D38: =D28/$B$31
A39: Tes Wawancara | B39: =B29/$D$31 | C39: =C29/$C$31 | D39: =D29/$B$31
A40: Tes Pilihan Ganda | B40: =B30/$D$31 | C40: =C30/$C$31 | D40: =D30/$B$31
A42: LANGKAH 6: BOBOT GLOBAL (d'(Ai) & Normalisasi)
A43: d'(Ai)=MIN(V(Si>=Sk)), Wi=d'(Ai)/Σd'
A44: Kriteria | B44: d'(Ai) | C44: Wi | D44: %
A45: Status Keaktifan | B45: =(B35+C35+D35)/3 | C45: =B45/$B$51 | D45: =C45*100
...

Sheet Hasil & Ranking
A1: SKOR AKHIR DENGAN DEFUZZIFIKASI
A2: Skor = (ΣL×w + ΣM×w + ΣU×w) / 3
A4: BOBOT (Wi)
A5: K1 | B5: K2 | C5: K3 | D5: K4 | E5: K5 | F5: K6
A6: ='Fuzzy AHP'!C45 | B6: ='Fuzzy AHP'!C46 | C6: ='Fuzzy AHP'!C47 | D6: ='Fuzzy AHP'!C48 | E6: ='Fuzzy AHP'!C49 | F6: ='Fuzzy AHP'!C50
A8: PERHITUNGAN SKOR (dengan Defuzzifikasi)
A9: No | B9: Nama | C9: ΣL×w | D9: ΣM×w | E9: ΣU×w | F9: Skor | G9: Rank
A10: 1 | B10: ='Input'!B14 | C10: =MAX(0,'Rekap Nilai'!C4-5)*$A$6+MAX(0,'Rekap Nilai'!D4-5)*$B$6+MAX(0,'Rekap Nilai'!E4-5)*$C$6+MAX(0,'Rekap Nilai'!F4-5)*$D$6+MAX(0,'Rekap Nilai'!G4-5)*$E$6+MAX(0,'Rekap Nilai'!H4-5)*$F$6 | D10: ='Rekap Nilai'!C4*$A$6+'Rekap Nilai'!D4*$B$6+'Rekap Nilai'!E4*$C$6+'Rekap Nilai'!F4*$D$6+'Rekap Nilai'!G4*$E$6+'Rekap Nilai'!H4*$F$6 | E10: =MIN(100,'Rekap Nilai'!C4+5)*$A$6+MIN(100,'Rekap Nilai'!D4+5)*$B$6+MIN(100,'Rekap Nilai'!E4+5)*$C$6+MIN(100,'Rekap Nilai'!F4+5)*$D$6+MIN(100,'Rekap Nilai'!G4+5)*$E$6+MIN(100,'Rekap Nilai'!H4+5)*$F$6 | F10: =(C10+D10+E10)/3 | G10: =IF(B10="","",RANK(F10,$F$10:$F$19,0))
A11: 2 | B11: ='Input'!B15 | C11: =MAX(0,'Rekap Nilai'!C5-5)*$A$6+MAX(0,'Rekap Nilai'!D5-5)*$B$6+MAX(0,'Rekap Nilai'!E5-5)*$C$6+MAX(0,'Rekap Nilai'!F5-5)*$D$6+MAX(0,'Rekap Nilai'!G5-5)*$E$6+MAX(0,'Rekap Nilai'!H5-5)*$F$6 | D11: ='Rekap Nilai'!C5*$A$6+'Rekap Nilai'!D5*$B$6+'Rekap Nilai'!E5*$C$6+'Rekap Nilai'!F5*$D$6+'Rekap Nilai'!G5*$E$6+'Rekap Nilai'!H5*$F$6 | E11: =MIN(100,'Rekap Nilai'!C5+5)*$A$6+MIN(100,'Rekap Nilai'!D5+5)*$B$6+MIN(100,'Rekap Nilai'!E5+5)*$C$6+MIN(100,'Rekap Nilai'!F5+5)*$D$6+MIN(100,'Rekap Nilai'!G5+5)*$E$6+MIN(100,'Rekap Nilai'!H5+5)*$F$6 | F11: =(C11+D11+E11)/3 | G11: =IF(B11="","",RANK(F11,$F$10:$F$19,0))
A12: 3 | B12: ='Input'!B16 | C12: =MAX(0,'Rekap Nilai'!C6-5)*$A$6+MAX(0,'Rekap Nilai'!D6-5)*$B$6+MAX(0,'Rekap Nilai'!E6-5)*$C$6+MAX(0,'Rekap Nilai'!F6-5)*$D$6+MAX(0,'Rekap Nilai'!G6-5)*$E$6+MAX(0,'Rekap Nilai'!H6-5)*$F$6 | D12: ='Rekap Nilai'!C6*$A$6+'Rekap Nilai'!D6*$B$6+'Rekap Nilai'!E6*$C$6+'Rekap Nilai'!F6*$D$6+'Rekap Nilai'!G6*$E$6+'Rekap Nilai'!H6*$F$6 | E12: =MIN(100,'Rekap Nilai'!C6+5)*$A$6+MIN(100,'Rekap Nilai'!D6+5)*$B$6+MIN(100,'Rekap Nilai'!E6+5)*$C$6+MIN(100,'Rekap Nilai'!F6+5)*$D$6+MIN(100,'Rekap Nilai'!G6+5)*$E$6+MIN(100,'Rekap Nilai'!H6+5)*$F$6 | F12: =(C12+D12+E12)/3 | G12: =IF(B12="","",RANK(F12,$F$10:$F$19,0))
A13: 4 | B13: ='Input'!B17 | C13: =MAX(0,'Rekap Nilai'!C7-5)*$A$6+MAX(0,'Rekap Nilai'!D7-5)*$B$6+MAX(0,'Rekap Nilai'!E7-5)*$C$6+MAX(0,'Rekap Nilai'!F7-5)*$D$6+MAX(0,'Rekap Nilai'!G7-5)*$E$6+MAX(0,'Rekap Nilai'!H7-5)*$F$6 | D13: ='Rekap Nilai'!C7*$A$6+'Rekap Nilai'!D7*$B$6+'Rekap Nilai'!E7*$C$6+'Rekap Nilai'!F7*$D$6+'Rekap Nilai'!G7*$E$6+'Rekap Nilai'!H7*$F$6 | E13: =MIN(100,'Rekap Nilai'!C7+5)*$A$6+MIN(100,'Rekap Nilai'!D7+5)*$B$6+MIN(100,'Rekap Nilai'!E7+5)*$C$6+MIN(100,'Rekap Nilai'!F7+5)*$D$6+MIN(100,'Rekap Nilai'!G7+5)*$E$6+MIN(100,'Rekap Nilai'!H7+5)*$F$6 | F13: =(C13+D13+E13)/3 | G13: =IF(B13="","",RANK(F13,$F$10:$F$19,0))
A14: 5 | B14: ='Input'!B18 | C14: =MAX(0,'Rekap Nilai'!C8-5)*$A$6+MAX(0,'Rekap Nilai'!D8-5)*$B$6+MAX(0,'Rekap Nilai'!E8-5)*$C$6+MAX(0,'Rekap Nilai'!F8-5)*$D$6+MAX(0,'Rekap Nilai'!G8-5)*$E$6+MAX(0,'Rekap Nilai'!H8-5)*$F$6 | D14: ='Rekap Nilai'!C8*$A$6+'Rekap Nilai'!D8*$B$6+'Rekap Nilai'!E8*$C$6+'Rekap Nilai'!F8*$D$6+'Rekap Nilai'!G8*$E$6+'Rekap Nilai'!H8*$F$6 | E14: =MIN(100,'Rekap Nilai'!C8+5)*$A$6+MIN(100,'Rekap Nilai'!D8+5)*$B$6+MIN(100,'Rekap Nilai'!E8+5)*$C$6+MIN(100,'Rekap Nilai'!F8+5)*$D$6+MIN(100,'Rekap Nilai'!G8+5)*$E$6+MIN(100,'Rekap Nilai'!H8+5)*$F$6 | F14: =(C14+D14+E14)/3 | G14: =IF(B14="","",RANK(F14,$F$10:$F$19,0))
A15: 6 | B15: ='Input'!B19 | C15: =MAX(0,'Rekap Nilai'!C9-5)*$A$6+MAX(0,'Rekap Nilai'!D9-5)*$B$6+MAX(0,'Rekap Nilai'!E9-5)*$C$6+MAX(0,'Rekap Nilai'!F9-5)*$D$6+MAX(0,'Rekap Nilai'!G9-5)*$E$6+MAX(0,'Rekap Nilai'!H9-5)*$F$6 | D15: ='Rekap Nilai'!C9*$A$6+'Rekap Nilai'!D9*$B$6+'Rekap Nilai'!E9*$C$6+'Rekap Nilai'!F9*$D$6+'Rekap Nilai'!G9*$E$6+'Rekap Nilai'!H9*$F$6 | E15: =MIN(100,'Rekap Nilai'!C9+5)*$A$6+MIN(100,'Rekap Nilai'!D9+5)*$B$6+MIN(100,'Rekap Nilai'!E9+5)*$C$6+MIN(100,'Rekap Nilai'!F9+5)*$D$6+MIN(100,'Rekap Nilai'!G9+5)*$E$6+MIN(100,'Rekap Nilai'!H9+5)*$F$6 | F15: =(C15+D15+E15)/3 | G15: =IF(B15="","",RANK(F15,$F$10:$F$19,0))
A16: 7 | B16: ='Input'!B20 | C16: =MAX(0,'Rekap Nilai'!C10-5)*$A$6+MAX(0,'Rekap Nilai'!D10-5)*$B$6+MAX(0,'Rekap Nilai'!E10-5)*$C$6+MAX(0,'Rekap Nilai'!F10-5)*$D$6+MAX(0,'Rekap Nilai'!G10-5)*$E$6+MAX(0,'Rekap Nilai'!H10-5)*$F$6 | D16: ='Rekap Nilai'!C10*$A$6+'Rekap Nilai'!D10*$B$6+'Rekap Nilai'!E10*$C$6+'Rekap Nilai'!F10*$D$6+'Rekap Nilai'!G10*$E$6+'Rekap Nilai'!H10*$F$6 | E16: =MIN(100,'Rekap Nilai'!C10+5)*$A$6+MIN(100,'Rekap Nilai'!D10+5)*$B$6+MIN(100,'Rekap Nilai'!E10+5)*$C$6+MIN(100,'Rekap Nilai'!F10+5)*$D$6+MIN(100,'Rekap Nilai'!G10+5)*$E$6+MIN(100,'Rekap Nilai'!H10+5)*$F$6 | F16: =(C16+D16+E16)/3 | G16: =IF(B16="","",RANK(F16,$F$10:$F$19,0))
A17: 8 | B17: ='Input'!B21 | C17: =MAX(0,'Rekap Nilai'!C11-5)*$A$6+MAX(0,'Rekap Nilai'!D11-5)*$B$6+MAX(0,'Rekap Nilai'!E11-5)*$C$6+MAX(0,'Rekap Nilai'!F11-5)*$D$6+MAX(0,'Rekap Nilai'!G11-5)*$E$6+MAX(0,'Rekap Nilai'!H11-5)*$F$6 | D17: ='Rekap Nilai'!C11*$A$6+'Rekap Nilai'!D11*$B$6+'Rekap Nilai'!E11*$C$6+'Rekap Nilai'!F11*$D$6+'Rekap Nilai'!G11*$E$6+'Rekap Nilai'!H11*$F$6 | E17: =MIN(100,'Rekap Nilai'!C11+5)*$A$6+MIN(100,'Rekap Nilai'!D11+5)*$B$6+MIN(100,'Rekap Nilai'!E11+5)*$C$6+MIN(100,'Rekap Nilai'!F11+5)*$D$6+MIN(100,'Rekap Nilai'!G11+5)*$E$6+MIN(100,'Rekap Nilai'!H11+5)*$F$6 | F17: =(C17+D17+E17)/3 | G17: =IF(B17="","",RANK(F17,$F$10:$F$19,0))
A18: 9 | B18: ='Input'!B22 | C18: =MAX(0,'Rekap Nilai'!C12-5)*$A$6+MAX(0,'Rekap Nilai'!D12-5)*$B$6+MAX(0,'Rekap Nilai'!E12-5)*$C$6+MAX(0,'Rekap Nilai'!F12-5)*$D$6+MAX(0,'Rekap Nilai'!G12-5)*$E$6+MAX(0,'Rekap Nilai'!H12-5)*$F$6 | D18: ='Rekap Nilai'!C12*$A$6+'Rekap Nilai'!D12*$B$6+'Rekap Nilai'!E12*$C$6+'Rekap Nilai'!F12*$D$6+'Rekap Nilai'!G12*$E$6+'Rekap Nilai'!H12*$F$6 | E18: =MIN(100,'Rekap Nilai'!C12+5)*$A$6+MIN(100,'Rekap Nilai'!D12+5)*$B$6+MIN(100,'Rekap Nilai'!E12+5)*$C$6+MIN(100,'Rekap Nilai'!F12+5)*$D$6+MIN(100,'Rekap Nilai'!G12+5)*$E$6+MIN(100,'Rekap Nilai'!H12+5)*$F$6 | F18: =(C18+D18+E18)/3 | G18: =IF(B18="","",RANK(F18,$F$10:$F$19,0))
A19: 10 | B19: ='Input'!B23 | C19: =MAX(0,'Rekap Nilai'!C13-5)*$A$6+MAX(0,'Rekap Nilai'!D13-5)*$B$6+MAX(0,'Rekap Nilai'!E13-5)*$C$6+MAX(0,'Rekap Nilai'!F13-5)*$D$6+MAX(0,'Rekap Nilai'!G13-5)*$E$6+MAX(0,'Rekap Nilai'!H13-5)*$F$6 | D19: ='Rekap Nilai'!C13*$A$6+'Rekap Nilai'!D13*$B$6+'Rekap Nilai'!E13*$C$6+'Rekap Nilai'!F13*$D$6+'Rekap Nilai'!G13*$E$6+'Rekap Nilai'!H13*$F$6 | E19: =MIN(100,'Rekap Nilai'!C13+5)*$A$6+MIN(100,'Rekap Nilai'!D13+5)*$B$6+MIN(100,'Rekap Nilai'!E13+5)*$C$6+MIN(100,'Rekap Nilai'!F13+5)*$D$6+MIN(100,'Rekap Nilai'!G13+5)*$E$6+MIN(100,'Rekap Nilai'!H13+5)*$F$6 | F19: =(C19+D19+E19)/3 | G19: =IF(B19="","",RANK(F19,$F$10:$F$19,0))
